Workbook

Sheet Summary
A1: *自2025/1起調整為最小單位(發/點/支) | BA1: Actual:填入買賣大表"耗療數量"
A2: 料件編號 新 | B2: 凱惠料號 | C2: 品名 | D2: 盒入數 | E2: 庫存 單位 | F2: 46173 | K2: 44531 | L2: 44562 | M2: 44593 | N2: 44621 | O2: 44652 | P2: 44682 | Q2: 44713 | R2: 44743 | S2: 44774 | T2: 44805 | U2: 44835 | V2: 44866 | W2: 44896 | X2: 44927 | Y2: 44958 | Z2: 44986 | AA2: 45017 | AB2: 45047 | AC2: 45078 | AD2: 45108 | AE2: 45139 | AF2: 45170 | AG2: 45200 | AH2: 45231 | AI2: 45261 | AJ2: 45292 | AK2: 45323 | AL2: 45352 | AM2: 45383 | AN2: 45413 | AO2: 45444 | AP2: 45474 | AQ2: 45505 | AR2: 45536 | AS2: 45566 | AT2: 45597 | AU2: 45627 | AV2: 2024 總銷量 (盒裝) | AW2: 2024 月均銷 (盒裝) | AX2: 45658 | AY2: 45689 | AZ2: 45717 | BA2: 45748 | BB2: 45778 | BC2: 2025/06 | BD2: 站前4樓 | BE2: 站前11樓 | BF2: 忠孝7樓 | BG2: 忠孝國際醫學3樓 | BH2: 2025/07 | BI2: 站前4樓 | BJ2: 站前11樓 | BK2: 忠孝7樓 | BL2: 忠孝國際醫學3樓 | BM2: 2025/08 | BN2: 站前4樓 | BO2: 站前11樓 | BP2: 忠孝7樓 | BQ2: 忠孝國際醫學3樓 | BR2: 2025/09 | BS2: 站前4樓 | BT2: 站前11樓 | BU2: 忠孝7樓 | BV2: 忠孝國際醫學3樓 | BW2: 2025/10 | BX2: 站前4樓 | BY2: 站前11樓 | BZ2: 忠孝7樓 | CA2: 忠孝國際醫學3樓 | CB2: 2025/11 | CC2: 站前4樓 | CD2: 站前11樓 | CE2: 忠孝7樓 | CF2: 忠孝國際醫學3樓 | CG2: 2025/12 | CH2: 站前4樓 | CI2: 站前11樓 | CJ2: 忠孝7樓 | CK2: 忠孝國際醫學3樓 | CL2: 2025 總銷量 (單支/條/點) | CM2: 2025 月均銷 (單支/條/點) | CN2: 2026/01 | CO2: 站前4樓 | CP2: 站前11樓 | CQ2: 忠孝7樓 | CR2: 忠孝國際醫學3樓 | CS2: 2026/02 | CT2: 站前4樓 | CU2: 站前11樓 | CV2: 忠孝7樓 | CW2: 忠孝國際醫學3樓 | CX2: 忠孝健康7樓 | CY2: 2026/03 | CZ2: 站前4樓 | DA2: 站前11樓 | DB2: 忠孝7樓 | DC2: 忠孝國際醫學3樓 | DD2: 忠孝健康7樓 | DE2: 2026/04 | DF2: 站前4樓 | DG2: 站前11樓 | DH2: 忠孝7樓 | DI2: 忠孝國際醫學3樓 | DJ2: 忠孝健康7樓 | DK2: 2026/05 | DL2: 站前4樓 | DM2: 站前11樓 | DN2: 忠孝7樓 | DO2: 忠孝國際醫學3樓 | DP2: 忠孝健康7樓 | DQ2: 2026 總銷量 (單支/條/點) | DR2: 2026 月均銷 (單支/條/點) | DS2: 2026/05 | DT2: 站前4樓 | DU2: 站前11樓 | DV2: 忠孝7樓 | DW2: 忠孝國際醫學3樓 | DX2: 安庫 | DY2: 已簽約 寄庫數量 | DZ2: 10/17在途 | EB2: 備註 | ED2: 站前4樓 | EE2: 站前11樓 | EF2: 忠孝7樓 | EG2: 忠孝國際醫學3樓
F3: 站前4樓 庫存 | G3: 站前11樓 庫存 | H3: 忠孝7樓 庫存 | I3: 忠孝國際 醫學3樓 庫存 | J3: 忠孝健康7樓 庫存 | K3: Actual | L3: Actual | M3: Actual | N3: Actual | O3: Actual | P3: Actual | Q3: Actual | R3: Actual | S3: Actual | T3: Actual | U3: Actual | V3: Actual | W3: Actual | X3: Actual | Y3: Actual | Z3: Actual | AA3: Actual | AB3: Actual | AC3: Actual | AD3: Actual | AE3: Actual | AF3: Actual | AG3: Actual | AH3: Actual | AI3: Actual | AJ3: Actual | AK3: Actual | AL3: Actual | AM3: Actual | AN3: Actual | AO3: Actual | AP3: Actual | AQ3: Actual | AR3: Actual | AS3: Actual | AT3: Actual | AU3: Actual | AX3: Actual | AY3: Actual | AZ3: Actual | BA3: Actual | BB3: Actual | BC3: Actual | BD3: Actual | BE3: Actual | BF3: Actual | BG3: Actual | BH3: Actual | BI3: Actual | BJ3: Actual | BK3: Actual | BL3: Actual | BM3: Actual | BN3: Actual | BO3: Actual | BP3: Actual | BQ3: Actual | BR3: Actual | BS3: Actual | BT3: Actual | BU3: Actual | BV3: Actual | BW3: Actual | BX3: Actual | BY3: Actual | BZ3: Actual | CA3: Actual | CB3: Actual | CC3: Actual | CD3: Actual | CE3: Actual | CF3: Actual | CG3: Actual | CH3: Actual | CI3: Actual | CJ3: Actual | CK3: Actual | CN3: Actual | CO3: Actual | CP3: Actual | CQ3: Actual | CR3: Actual | CS3: Actual | CT3: Actual | CU3: Actual | CV3: Actual | CW3: Actual | CX3: Actual | CY3: Actual | CZ3: Actual | DA3: Actual | DB3: Actual | DC3: Actual | DD3: Actual | DE3: Actual | DF3: Actual | DG3: Actual | DH3: Actual | DI3: Actual | DJ3: Actual | DK3: Actual | DL3: Actual | DM3: Actual | DN3: Actual | DO3: Actual | DP3: Actual | DS3: Forecast | DT3: Forecast | DU3: Forecast | DV3: Forecast | DW3: Forecast | DZ3: 站前診所 | EA3: 忠孝診所 | ED3: Forecast | EE3: Forecast | EF3: Forecast | EG3: Forecast
A4: MP1MA020019A | B4: 6150001 | C4: 喬雅登豐麗緹玻尿酸植入物Voluma 1ml/ syringe(1支) | D4: 2 | E4: PCS | F4: =SUMIF(站前4樓!B:B,B4,站前4樓!F:F) -> 100 | G4: =SUMIF(站前11樓!B:B,B4,站前11樓!F:F) -> 0 | H4: =SUMIF(忠孝7樓!B:B,B4,忠孝7樓!G:G) -> 44 | I4: =SUMIF(忠孝國際醫學3樓!B:B,B4,忠孝國際醫學3樓!G:G) -> 0 | J4: =SUMIF(忠孝健康7樓!B:B,B4,忠孝健康7樓!G:G) -> 15 | K4: 3 | L4: 3 | M4: 2 | N4: 5 | O4: 4 | P4: 6 | Q4: 0 | R4: 0 | S4: 14 | T4: 0 | U4: 6 | V4: 6 | W4: 20 | X4: 4 | Y4: 3 | Z4: 0 | AA4: 2 | AB4: 1 | AC4: 9 | AD4: 16 | AE4: 2 | AF4: 3 | AG4: 3 | AH4: 2 | AI4: 6 | AJ4: 7.5 | AK4: 6.5 | AL4: 11 | AM4: 11.5 | AN4: 11.5 | AO4: 21 | AP4: 9.5 | AQ4: 11 | AR4: 17 | AS4: 8.5 | AT4: 19.5 | AU4: 18 | AV4: =SUM(AJ4:AU4) -> 152.5 | AW4: =AV4/12 -> 12.708333 | AX4: 64 | AY4: 29 | AZ4: 54 | BA4: 60 | BB4: 75 | BC4: =SUMIFS(領用表!$L:$L,領用表!$A:$A,BC$2,領用表!$E:$E,B4) -> 47 | BD4: =SUMIFS(領用表!$L:$L,領用表!$E:$E,$B4,領用表!$B:$B,BC$2&BD$2) -> 47 | BE4: =SUMIFS(領用表!$L:$L,領用表!$E:$E,$B4,領用表!$B:$B,$BC$2&BE$2) -> 0 | BF4: =SUMIFS(領用表!$L:$L,領用表!$E:$E,$B4,領用表!$B:$B,$BC$2&BF$2) -> 0 | BG4: =SUMIFS(領用表!$L:$L,領用表!$E:$E,$B4,領用表!$B:$B,$BC$2&BG$2) -> 0 | BH4: =SUMIFS(領用表!$L:$L,領用表!$A:$A,BH$2,領用表!$E:$E,B4) -> 74 | BI4: =SUMIFS(領用表!$L:$L,領用表!$E:$E,$B4,領用表!$B:$B,BH$2&BI$2) -> 63 | BJ4: =SUMIFS(領用表!$L:$L,領用表!$E:$E,$B4,領用表!$B:$B,$BH$2&BJ$2) -> 0 | BK4: =SUMIFS(領用表!$L:$L,領用表!$E:$E,$B4,領用表!$B:$B,$BH$2&BK$2) -> 11 | BL4: =SUMIFS(領用表!$L:$L,領用表!$E:$E,$B4,領用表!$B:$B,$BH$2&BL$2) -> 0 | BM4: =SUMIFS(領用表!$L:$L,領用表!$A:$A,BM$2,領用表!$E:$E,B4) -> 140 | BN4: =SUMIFS(領用表!$L:$L,領用表!$E:$E,$B4,領用表!$B:$B,BM$2&BN$2) -> 64 | BO4: =SUMIFS(領用表!$L:$L,領用表!$E:$E,$B4,領用表!$B:$B,$BM$2&BO$2) -> 0 | BP4: =SUMIFS(領用表!$L:$L,領用表!$E:$E,$B4,領用表!$B:$B,$BM$2&BP$2) -> 76 | BQ4: =SUMIFS(領用表!$L:$L,領用表!$E:$E,$B4,領用表!$B:$B,$BM$2&BQ$2) -> 0 | BR4: =SUMIFS(領用表!$L:$L,領用表!$A:$A,BR$2,領用表!$E:$E,B4) -> 115 | BS4: =SUMIFS(領用表!$L:$L,領用表!$E:$E,$B4,領用表!$B:$B,BR$2&BS$2) -> 64 | BT4: =SUMIFS(領用表!$L:$L,領用表!$E:$E,$B4,領用表!$B:$B,$BR$2&BT$2) -> 0 | BU4: =SUMIFS(領用表!$L:$L,領用表!$E:$E,$B4,領用表!$B:$B,$BR$2&BU$2) -> 51 | BV4: =SUMIFS(領用表!$L:$L,領用表!$E:$E,$B4,領用表!$B:$B,$BR$2&BV$2) -> 0 | BW4: =SUMIFS(領用表!$L:$L,領用表!$A:$A,BW$2,領用表!$E:$E,B4) -> 141 | BX4: =SUMIFS(領用表!$L:$L,領用表!$E:$E,$B4,領用表!$B:$B,BW$2&BX$2) -> 68 | BY4: =SUMIFS(領用表!$L:$L,領用表!$E:$E,$B4,領用表!$B:$B,$BW$2&BY$2) -> 0 | BZ4: =SUMIFS(領用表!$L:$L,領用表!$E:$E,$B4,領用表!$B:$B,$BW$2&BZ$2) -> 73 | CA4: =SUMIFS(領用表!$L:$L,領用表!$E:$E,$B4,領用表!$B:$B,$BW$2&CA$2) -> 0 | CB4: =SUMIFS(領用表!$L:$L,領用表!$A:$A,CB$2,領用表!$E:$E,B4) -> 148 | CC4: =SUMIFS(領用表!$L:$L,領用表!$E:$E,$B4,領用表!$B:$B,CB$2&CC$2) -> 87 | CD4: =SUMIFS(領用表!$L:$L,領用表!$E:$E,$B4,領用表!$B:$B,$CB$2&CD$2) -> 0 | CE4: =SUMIFS(領用表!$L:$L,領用表!$E:$E,$B4,領用表!$B:$B,$CB$2&CE$2) -> 61 | CF4: =SUMIFS(領用表!$L:$L,領用表!$E:$E,$B4,領用表!$B:$B,$CB$2&CF$2) -> 0 | CG4: =SUMIFS(領用表!$L:$L,領用表!$A:$A,CG$2,領用表!$E:$E,B4) -> 209 | CH4: =SUMIFS(領用表!$L:$L,領用表!$E:$E,$B4,領用表!$B:$B,CG$2&CH$2) -> 116 | CI4: =SUMIFS(領用表!$L:$L,領用表!$E:$E,$B4,領用表!$B:$B,CG$2&CI$2) -> 0 | CJ4: =SUMIFS(領用表!$L:$L,領用表!$E:$E,$B4,領用表!$B:$B,CG$2&CJ$2) -> 93 | CK4: =SUMIFS(領用表!$L:$L,領用表!$E:$E,$B4,領用表!$B:$B,$CG$2&CK$2) -> 0 | CL4: =SUM(AX4,AY4,AZ4,BA4,BB4,BC4,BH4,BM4,BR4,BW4,CB4,CG4) -> 1156 | CM4: =AVERAGE(AX4,AY4,AZ4,BA4,BB4,BC4,BH4,BM4,BR4,BW4,CB4,CG4) -> 96.333333 | CN4: =SUMIFS(領用表!$L:$L,領用表!$A:$A,CN$2,領用表!$E:$E,B4) -> 258 | CO4: =SUMIFS(領用表!$L:$L,領用表!$E:$E,$B4,領用表!$B:$B,CN$2&CO$2) -> 150 | CP4: =SUMIFS(領用表!$L:$L,領用表!$E:$E,$B4,領用表!$B:$B,$CN$2&CP$2) -> 0 | CQ4: =SUMIFS(領用表!$L:$L,領用表!$E:$E,$B4,領用表!$B:$B,$CN$2&CQ$2) -> 108 | CR4: =SUMIFS(領用表!$L:$L,領用表!$E:$E,$B4,領用表!$B:$B,$CN$2&CR$2) -> 0 | CS4: =SUMIFS(領用表!$L:$L,領用表!$A:$A,CS$2,領用表!$E:$E,B4) -> 330 | CT4: =SUMIFS(領用表!$L:$L,領用表!$E:$E,$B4,領用表!$B:$B,CS$2&CT$2) -> 220 | CU4: =SUMIFS(領用表!$L:$L,領用表!$E:$E,$B4,領用表!$B:$B,$CS$2&CU$2) -> 0 | CV4: =SUMIFS(領用表!$L:$L,領用表!$E:$E,$B4,領用表!$B:$B,$CS$2&CV$2) -> 96 | CW4: =SUMIFS(領用表!$L:$L,領用表!$E:$E,$B4,領用表!$B:$B,$CS$2&CW$2) -> 0 | CX4: =SUMIFS(領用表!$L:$L,領用表!$E:$E,$B4,領用表!$B:$B,$CS$2&CX$2) -> 14 | CY4: =SUMIFS(領用表!$L:$L,領用表!$A:$A,CY$2,領用表!$E:$E,B4) -> 282 | CZ4: =SUMIFS(領用表!$L:$L,領用表!$E:$E,$B4,領用表!$B:$B,CY$2&CZ$2) -> 176 | DA4: =SUMIFS(領用表!$L:$L,領用表!$E:$E,$B4,領用表!$B:$B,$CY$2&DA$2) -> 0 | DB4: =SUMIFS(領用表!$L:$L,領用表!$E:$E,$B4,領用表!$B:$B,$CY$2&DB$2) -> 83 | DC4: =SUMIFS(領用表!$L:$L,領用表!$E:$E,$B4,領用表!$B:$B,$CY$2&DC$2) -> 0 | DD4: =SUMIFS(領用表!$L:$L,領用表!$E:$E,$B4,領用表!$B:$B,$CY$2&DD$2) -> 23 | DE4: =SUMIFS(領用表!$L:$L,領用表!$A:$A,DE$2,領用表!$E:$E,B4) -> 304 | DF4: =SUMIFS(領用表!$L:$L,領用表!$E:$E,$B4,領用表!$B:$B,DE$2&DF$2) -> 150 | DG4: =SUMIFS(領用表!$L:$L,領用表!$E:$E,$B4,領用表!$B:$B,$DE$2&DG$2) -> 0 | DH4: =SUMIFS(領用表!$L:$L,領用表!$E:$E,$B4,領用表!$B:$B,$DE$2&DH$2) -> 118 | DI4: =SUMIFS(領用表!$L:$L,領用表!$E:$E,$B4,領用表!$B:$B,$DE$2&DI$2) -> 0 | DJ4: =SUMIFS(領用表!$L:$L,領用表!$E:$E,$B4,領用表!$B:$B,$DE$2&DJ$2) -> 36 | DK4: =SUMIFS(領用表!$L:$L,領用表!$A:$A,DK$2,領用表!$E:$E,$B4) -> 326 | DL4: =SUMIFS(領用表!$L:$L,領用表!$E:$E,$B4,領用表!$B:$B,DK$2&DL$2) -> 183 | DM4: =SUMIFS(領用表!$L:$L,領用表!$E:$E,$B4,領用表!$B:$B,$DK$2&DM$2) -> 0 | DN4: =SUMIFS(領用表!$L:$L,領用表!$E:$E,$B4,領用表!$B:$B,$DK$2&DN$2) -> 120 | DO4: =SUMIFS(領用表!$L:$L,領用表!$E:$E,$B4,領用表!$B:$B,$DK$2&DO$2) -> 0 | DP4: =SUMIFS(領用表!$L:$L,領用表!$E:$E,$B4,領用表!$B:$B,$DK$2&DP$2) -> 23 | DQ4: =SUM(CN4,CS4,CY4,DE4,DK4) -> 1500 | DR4: =AVERAGEA(CN4,CS4,CY4,DE4,DK4) -> 300 | DS4: =SUM(DT4:DW4) -> 240 | DT4: 120 | DU4: 0 | DV4: 120 | DW4: 0 | DX4: 50 | DY4: 0 | DZ4: 40盒(10/21) | EA4: 10盒(10/21) | ED4: =IFERROR(VLOOKUP(A4,站前4樓!A:BF,57,0),0) -> 87 | EE4: =IFERROR(VLOOKUP(A4,站前11樓!A:BE,57,0),0) -> 0 | EF4: =IFERROR(VLOOKUP(A4,忠孝7樓!A:N,57,0),0) -> 0 | EG4: =IFERROR(VLOOKUP(A4,忠孝國際醫學3樓!A:L,57,0),0) -> 0 | EH4: =SUM(ED4:EG4) -> 87 | EJ4: 61 | EK4: 85
A5: MP1MA020020A | B5: 6150002 | C5: 喬雅登夢蓓菈玻尿酸植入物Volbella 1ml/ syringe(1支) | D5: 2 | E5: PCS | F5: =SUMIF(站前4樓!B:B,B5,站前4樓!F:F) -> 4 | G5: =SUMIF(站前11樓!B:B,B5,站前11樓!F:F) -> 0 | H5: =SUMIF(忠孝7樓!B:B,B5,忠孝7樓!G:G) -> 22 | I5: =SUMIF(忠孝國際醫學3樓!B:B,B5,忠孝國際醫學3樓!G:G) -> 0 | J5: =SUMIF(忠孝健康7樓!B:B,B5,忠孝健康7樓!G:G) -> 9 | K5: 0 | L5: 3 | M5: 0 | N5: 3 | O5: 0 | P5: 0 | Q5: 0 | R5: 0 | S5: 3 | T5: 0 | U5: 2 | V5: 0 | W5: 2 | X5: 5 | Y5: 0 | Z5: 0 | AA5: 0 | AB5: 1 | AC5: 0 | AD5: 4 | AE5: 0 | AF5: 1 | AG5: 1 | AH5: 3 | AI5: 19 | AJ5: 4.5 | AK5: 0.5 | AL5: 3.5 | AM5: 0.5 | AN5: 3 | AO5: 5.5 | AP5: 4.5 | AQ5: 3.5 | AR5: 1 | AS5: 1 | AT5: 3 | AU5: 6 | AV5: =SUM(AJ5:AU5) -> 36.5 | AW5: =AV5/12 -> 3.0416667 | AX5: 11 | AY5: 2 | AZ5: 1 | BA5: 9 | BB5: 3 | BC5: =SUMIFS(領用表!$L:$L,領用表!$A:$A,BC$2,領用表!$E:$E,B5) -> 3 | BD5: =SUMIFS(領用表!$L:$L,領用表!$E:$E,$B5,領用表!$B:$B,BC$2&BD$2) -> 3 | BE5: =SUMIFS(領用表!$L:$L,領用表!$E:$E,$B5,領用表!$B:$B,$BC$2&BE$2) -> 0 | BF5: =SUMIFS(領用表!$L:$L,領用表!$E:$E,$B5,領用表!$B:$B,$BC$2&BF$2) -> 0 | BG5: =SUMIFS(領用表!$L:$L,領用表!$E:$E,$B5,領用表!$B:$B,$BC$2&BG$2) -> 0 | BH5: =SUMIFS(領用表!$L:$L,領用表!$A:$A,BH$2,領用表!$E:$E,B5) -> 16 | BI5: =SUMIFS(領用表!$L:$L,領用表!$E:$E,$B5,領用表!$B:$B,BH$2&BI$2) -> 10 | BJ5: =SUMIFS(領用表!$L:$L,領用表!$E:$E,$B5,領用表!$B:$B,$BH$2&BJ$2) -> 0 | BK5: =SUMIFS(領用表!$L:$L,領用表!$E:$E,$B5,領用表!$B:$B,$BH$2&BK$2) -> 6 | BL5: =SUMIFS(領用表!$L:$L,領用表!$E:$E,$B5,領用表!$B:$B,$BH$2&BL$2) -> 0 | BM5: =SUMIFS(領用表!$L:$L,領用表!$A:$A,BM$2,領用表!$E:$E,B5) -> 6 | BN5: =SUMIFS(領用表!$L:$L,領用表!$E:$E,$B5,領用表!$B:$B,BM$2&BN$2) -> 3 | BO5: =SUMIFS(領用表!$L:$L,領用表!$E:$E,$B5,領用表!$B:$B,$BM$2&BO$2) -> 0 | BP5: =SUMIFS(領用表!$L:$L,領用表!$E:$E,$B5,領用表!$B:$B,$BM$2&BP$2) -> 3 | BQ5: =SUMIFS(領用表!$L:$L,領用表!$E:$E,$B5,領用表!$B:$B,$BM$2&BQ$2) -> 0 | BR5: =SUMIFS(領用表!$L:$L,領用表!$A:$A,BR$2,領用表!$E:$E,B5) -> 11 | BS5: =SUMIFS(領用表!$L:$L,領用表!$E:$E,$B5,領用表!$B:$B,BR$2&BS$2) -> 9 | BT5: =SUMIFS(領用表!$L:$L,領用表!$E:$E,$B5,領用表!$B:$B,$BR$2&BT$2) -> 0 | BU5: =SUMIFS(領用表!$L:$L,領用表!$E:$E,$B5,領用表!$B:$B,$BR$2&BU$2) -> 2 | BV5: =SUMIFS(領用表!$L:$L,領用表!$E:$E,$B5,領用表!$B:$B,$BR$2&BV$2) -> 0 | BW5: =SUMIFS(領用表!$L:$L,領用表!$A:$A,BW$2,領用表!$E:$E,B5) -> 10 | BX5: =SUMIFS(領用表!$L:$L,領用表!$E:$E,$B5,領用表!$B:$B,BW$2&BX$2) -> 5 | BY5: =SUMIFS(領用表!$L:$L,領用表!$E:$E,$B5,領用表!$B:$B,$BW$2&BY$2) -> 0 | BZ5: =SUMIFS(領用表!$L:$L,領用表!$E:$E,$B5,領用表!$B:$B,$BW$2&BZ$2) -> 5 | CA5: =SUMIFS(領用表!$L:$L,領用表!$E:$E,$B5,領用表!$B:$B,$BW$2&CA$2) -> 0 | CB5: =SUMIFS(領用表!$L:$L,領用表!$A:$A,CB$2,領用表!$E:$E,B5) -> 12 | CC5: =SUMIFS(領用表!$L:$L,領用表!$E:$E,$B5,領用表!$B:$B,CB$2&CC$2) -> 2 | CD5: =SUMIFS(領用表!$L:$L,領用表!$E:$E,$B5,領用表!$B:$B,$CB$2&CD$2) -> 0 | CE5: =SUMIFS(領用表!$L:$L,領用表!$E:$E,$B5,領用表!$B:$B,$CB$2&CE$2) -> 10 | CF5: =SUMIFS(領用表!$L:$L,領用表!$E:$E,$B5,領用表!$B:$B,$CB$2&CF$2) -> 0 | CG5: =SUMIFS(領用表!$L:$L,領用表!$A:$A,CG$2,領用表!$E:$E,B5) -> 27 | CH5: =SUMIFS(領用表!$L:$L,領用表!$E:$E,$B5,領用表!$B:$B,CG$2&CH$2) -> 3 | CI5: =SUMIFS(領用表!$L:$L,領用表!$E:$E,$B5,領用表!$B:$B,CG$2&CI$2) -> 0 | CJ5: =SUMIFS(領用表!$L:$L,領用表!$E:$E,$B5,領用表!$B:$B,CG$2&CJ$2) -> 24 | CK5: =SUMIFS(領用表!$L:$L,領用表!$E:$E,$B5,領用表!$B:$B,$CG$2&CK$2) -> 0 | CL5: =SUM(AX5,AY5,AZ5,BA5,BB5,BC5,BH5,BM5,BR5,BW5,CB5,CG5) -> 111 | CM5: =AVERAGE(AX5,AY5,AZ5,BA5,BB5,BC5,BH5,BM5,BR5,BW5,CB5,CG5) -> 9.25 | CN5: =SUMIFS(領用表!$L:$L,領用表!$A:$A,CN$2,領用表!$E:$E,B5) -> 31 | CO5: =SUMIFS(領用表!$L:$L,領用表!$E:$E,$B5,領用表!$B:$B,CN$2&CO$2) -> 6 | CP5: =SUMIFS(領用表!$L:$L,領用表!$E:$E,$B5,領用表!$B:$B,$CN$2&CP$2) -> 0 | CQ5: =SUMIFS(領用表!$L:$L,領用表!$E:$E,$B5,領用表!$B:$B,$CN$2&CQ$2) -> 25 | CR5: =SUMIFS(領用表!$L:$L,領用表!$E:$E,$B5,領用表!$B:$B,$CN$2&CR$2) -> 0 | CS5: =SUMIFS(領用表!$L:$L,領用表!$A:$A,CS$2,領用表!$E:$E,B5) -> 27 | CT5: =SUMIFS(領用表!$L:$L,領用表!$E:$E,$B5,領用表!$B:$B,CS$2&CT$2) -> 7 | CU5: =SUMIFS(領用表!$L:$L,領用表!$E:$E,$B5,領用表!$B:$B,$CS$2&CU$2) -> 0 | CV5: =SUMIFS(領用表!$L:$L,領用表!$E:$E,$B5,領用表!$B:$B,$CS$2&CV$2) -> 20 | CW5: =SUMIFS(領用表!$L:$L,領用表!$E:$E,$B5,領用表!$B:$B,$CS$2&CW$2) -> 0 | CX5: =SUMIFS(領用表!$L:$L,領用表!$E:$E,$B5,領用表!$B:$B,$CS$2&CX$2) -> 0 | CY5: =SUMIFS(領用表!$L:$L,領用表!$A:$A,CY$2,領用表!$E:$E,B5) -> 30 | CZ5: =SUMIFS(領用表!$L:$L,領用表!$E:$E,$B5,領用表!$B:$B,CY$2&CZ$2) -> 11 | DA5: =SUMIFS(領用表!$L:$L,領用表!$E:$E,$B5,領用表!$B:$B,$CY$2&DA$2) -> 0 | DB5: =SUMIFS(領用表!$L:$L,領用表!$E:$E,$B5,領用表!$B:$B,$CY$2&DB$2) -> 16 | DC5: =SUMIFS(領用表!$L:$L,領用表!$E:$E,$B5,領用表!$B:$B,$CY$2&DC$2) -> 0 | DD5: =SUMIFS(領用表!$L:$L,領用表!$E:$E,$B5,領用表!$B:$B,$CY$2&DD$2) -> 3 | DE5: =SUMIFS(領用表!$L:$L,領用表!$A:$A,DE$2,領用表!$E:$E,B5) -> 31 | DF5: =SUMIFS(領用表!$L:$L,領用表!$E:$E,$B5,領用表!$B:$B,DE$2&DF$2) -> 7 | DG5: =SUMIFS(領用表!$L:$L,領用表!$E:$E,$B5,領用表!$B:$B,$DE$2&DG$2) -> 0 | DH5: =SUMIFS(領用表!$L:$L,領用表!$E:$E,$B5,領用表!$B:$B,$DE$2&DH$2) -> 21 | DI5: =SUMIFS(領用表!$L:$L,領用表!$E:$E,$B5,領用表!$B:$B,$DE$2&DI$2) -> 0 | DJ5: =SUMIFS(領用表!$L:$L,領用表!$E:$E,$B5,領用表!$B:$B,$DE$2&DJ$2) -> 3 | DK5: =SUMIFS(領用表!$L:$L,領用表!$A:$A,DK$2,領用表!$E:$E,$B5) -> 31 | DL5: =SUMIFS(領用表!$L:$L,領用表!$E:$E,$B5,領用表!$B:$B,DK$2&DL$2) -> 6 | DM5: =SUMIFS(領用表!$L:$L,領用表!$E:$E,$B5,領用表!$B:$B,$DK$2&DM$2) -> 0 | DN5: =SUMIFS(領用表!$L:$L,領用表!$E:$E,$B5,領用表!$B:$B,$DK$2&DN$2) -> 18 | DO5: =SUMIFS(領用表!$L:$L,領用表!$E:$E,$B5,領用表!$B:$B,$DK$2&DO$2) -> 0 | DP5: =SUMIFS(領用表!$L:$L,領用表!$E:$E,$B5,領用表!$B:$B,$DK$2&DP$2) -> 7 | DQ5: =SUM(CN5,CS5,CY5,DE5,DK5) -> 150 | DR5: =AVERAGEA(CN5,CS5,CY5,DE5,DK5) -> 30 | DS5: =SUM(DT5:DW5) -> 33 | DT5: 8 | DU5: 0 | DV5: 25 | DW5: 0 | DX5: 10 | DY5: 0 | EA5: 10盒(10/21) | ED5: =IFERROR(VLOOKUP(A5,站前4樓!A:BF,57,0),0) -> 2 | EE5: =IFERROR(VLOOKUP(A5,站前11樓!A:BE,57,0),0) -> 0 | EF5: =IFERROR(VLOOKUP(A5,忠孝7樓!A:N,57,0),0) -> 0 | EG5: =IFERROR(VLOOKUP(A5,忠孝國際醫學3樓!A:L,57,0),0) -> 0 | EH5: =SUM(ED5:EG5) -> 2 | EJ5: 19 | EK5: 8
A6: MP1MA020021A | B6: 6150003 | C6: 喬雅登豐麗緹玻尿酸植入物Volift 1ml/ syringe(1支) | D6: 2 | E6: PCS | F6: =SUMIF(站前4樓!B:B,B6,站前4樓!F:F) -> 4 | G6: =SUMIF(站前11樓!B:B,B6,站前11樓!F:F) -> 0 | H6: =SUMIF(忠孝7樓!B:B,B6,忠孝7樓!G:G) -> 4 | I6: =SUMIF(忠孝國際醫學3樓!B:B,B6,忠孝國際醫學3樓!G:G) -> 0 | J6: =SUMIF(忠孝健康7樓!B:B,B6,忠孝健康7樓!G:G) -> 10 | K6: 1 | L6: 1 | M6: 0 | N6: 0 | O6: 2 | P6: 1 | Q6: 0 | R6: 0 | S6: 2 | T6: 0 | U6: 0 | V6: 1 | W6: 6 | X6: 3 | Y6: 0 | Z6: 0 | AA6: 0 | AB6: 2 | AC6: 1 | AD6: 3 | AE6: 0 | AF6: 0 | AG6: 0 | AH6: 2 | AI6: 10 | AJ6: 1 | AK6: 0 | AL6: 0.5 | AM6: 0.5 | AN6: 0 | AO6: 2.5 | AP6: 0.5 | AQ6: 0.5 | AR6: 7 | AS6: 10 | AT6: 0.5 | AU6: 0 | AV6: =SUM(AJ6:AU6) -> 23 | AW6: =AV6/12 -> 1.9166667 | AX6: 1 | AY6: 0 | AZ6: 0 | BA6: 1 | BB6: 6 | BC6: =SUMIFS(領用表!$L:$L,領用表!$A:$A,BC$2,領用表!$E:$E,B6) -> 3 | BD6: =SUMIFS(領用表!$L:$L,領用表!$E:$E,$B6,領用表!$B:$B,BC$2&BD$2) -> 3 | BE6: =SUMIFS(領用表!$L:$L,領用表!$E:$E,$B6,領用表!$B:$B,$BC$2&BE$2) -> 0 | BF6: =SUMIFS(領用表!$L:$L,領用表!$E:$E,$B6,領用表!$B:$B,$BC$2&BF$2) -> 0 | BG6: =SUMIFS(領用表!$L:$L,領用表!$E:$E,$B6,領用表!$B:$B,$BC$2&BG$2) -> 0 | BH6: =SUMIFS(領用表!$L:$L,領用表!$A:$A,BH$2,領用表!$E:$E,B6) -> 6 | BI6: =SUMIFS(領用表!$L:$L,領用表!$E:$E,$B6,領用表!$B:$B,BH$2&BI$2) -> 6 | BJ6: =SUMIFS(領用表!$L:$L,領用表!$E:$E,$B6,領用表!$B:$B,$BH$2&BJ$2) -> 0 | BK6: =SUMIFS(領用表!$L:$L,領用表!$E:$E,$B6,領用表!$B:$B,$BH$2&BK$2) -> 0 | BL6: =SUMIFS(領用表!$L:$L,領用表!$E:$E,$B6,領用表!$B:$B,$BH$2&BL$2) -> 0 | BM6: =SUMIFS(領用表!$L:$L,領用表!$A:$A,BM$2,領用表!$E:$E,B6) -> 8 | BN6: =SUMIFS(領用表!$L:$L,領用表!$E:$E,$B6,領用表!$B:$B,BM$2&BN$2) -> 7 | BO6: =SUMIFS(領用表!$L:$L,領用表!$E:$E,$B6,領用表!$B:$B,$BM$2&BO$2) -> 0 | BP6: =SUMIFS(領用表!$L:$L,領用表!$E:$E,$B6,領用表!$B:$B,$BM$2&BP$2) -> 1 | BQ6: =SUMIFS(領用表!$L:$L,領用表!$E:$E,$B6,領用表!$B:$B,$BM$2&BQ$2) -> 0 | BR6: =SUMIFS(領用表!$L:$L,領用表!$A:$A,BR$2,領用表!$E:$E,B6) -> 1 | BS6: =SUMIFS(領用表!$L:$L,領用表!$E:$E,$B6,領用表!$B:$B,BR$2&BS$2) -> 0 | BT6: =SUMIFS(領用表!$L:$L,領用表!$E:$E,$B6,領用表!$B:$B,$BR$2&BT$2) -> 0 | BU6: =SUMIFS(領用表!$L:$L,領用表!$E:$E,$B6,領用表!$B:$B,$BR$2&BU$2) -> 1 | BV6: =SUMIFS(領用表!$L:$L,領用表!$E:$E,$B6,領用表!$B:$B,$BR$2&BV$2) -> 0 | BW6: =SUMIFS(領用表!$L:$L,領用表!$A:$A,BW$2,領用表!$E:$E,B6) -> 5 | BX6: =SUMIFS(領用表!$L:$L,領用表!$E:$E,$B6,領用表!$B:$B,BW$2&BX$2) -> 1 | BY6: =SUMIFS(領用表!$L:$L,領用表!$E:$E,$B6,領用表!$B:$B,$BW$2&BY$2) -> 0 | BZ6: =SUMIFS(領用表!$L:$L,領用表!$E:$E,$B6,領用表!$B:$B,$BW$2&BZ$2) -> 4 | CA6: =SUMIFS(領用表!$L:$L,領用表!$E:$E,$B6,領用表!$B:$B,$BW$2&CA$2) -> 0 | CB6: =SUMIFS(領用表!$L:$L,領用表!$A:$A,CB$2,領用表!$E:$E,B6) -> 3 | CC6: =SUMIFS(領用表!$L:$L,領用表!$E:$E,$B6,領用表!$B:$B,CB$2&CC$2) -> 3 | CD6: =SUMIFS(領用表!$L:$L,領用表!$E:$E,$B6,領用表!$B:$B,$CB$2&CD$2) -> 0 | CE6: =SUMIFS(領用表!$L:$L,領用表!$E:$E,$B6,領用表!$B:$B,$CB$2&CE$2) -> 0 | CF6: =SUMIFS(領用表!$L:$L,領用表!$E:$E,$B6,領用表!$B:$B,$CB$2&CF$2) -> 0 | CG6: =SUMIFS(領用表!$L:$L,領用表!$A:$A,CG$2,領用表!$E:$E,B6) -> 5 | CH6: =SUMIFS(領用表!$L:$L,領用表!$E:$E,$B6,領用表!$B:$B,CG$2&CH$2) -> 4 | CI6: =SUMIFS(領用表!$L:$L,領用表!$E:$E,$B6,領用表!$B:$B,CG$2&CI$2) -> 0 | CJ6: =SUMIFS(領用表!$L:$L,領用表!$E:$E,$B6,領用表!$B:$B,CG$2&CJ$2) -> 1 | CK6: =SUMIFS(領用表!$L:$L,領用表!$E:$E,$B6,領用表!$B:$B,$CG$2&CK$2) -> 0 | CL6: =SUM(AX6,AY6,AZ6,BA6,BB6,BC6,BH6,BM6,BR6,BW6,CB6,CG6) -> 39 | CM6: =AVERAGE(AX6,AY6,AZ6,BA6,BB6,BC6,BH6,BM6,BR6,BW6,CB6,CG6) -> 3.25 | CN6: =SUMIFS(領用表!$L:$L,領用表!$A:$A,CN$2,領用表!$E:$E,B6) -> 23 | CO6: =SUMIFS(領用表!$L:$L,領用表!$E:$E,$B6,領用表!$B:$B,CN$2&CO$2) -> 10 | CP6: =SUMIFS(領用表!$L:$L,領用表!$E:$E,$B6,領用表!$B:$B,$CN$2&CP$2) -> 0 | CQ6: =SUMIFS(領用表!$L:$L,領用表!$E:$E,$B6,領用表!$B:$B,$CN$2&CQ$2) -> 13 | CR6: =SUMIFS(領用表!$L:$L,領用表!$E:$E,$B6,領用表!$B:$B,$CN$2&CR$2) -> 0 | CS6: =SUMIFS(領用表!$L:$L,領用表!$A:$A,CS$2,領用表!$E:$E,B6) -> 10 | CT6: =SUMIFS(領用表!$L:$L,領用表!$E:$E,$B6,領用表!$B:$B,CS$2&CT$2) -> 6 | CU6: =SUMIFS(領用表!$L:$L,領用表!$E:$E,$B6,領用表!$B:$B,$CS$2&CU$2) -> 0 | CV6: =SUMIFS(領用表!$L:$L,領用表!$E:$E,$B6,領用表!$B:$B,$CS$2&CV$2) -> 4 | CW6: =SUMIFS(領用表!$L:$L,領用表!$E:$E,$B6,領用表!$B:$B,$CS$2&CW$2) -> 0 | CX6: =SUMIFS(領用表!$L:$L,領用表!$E:$E,$B6,領用表!$B:$B,$CS$2&CX$2) -> 0 | CY6: =SUMIFS(領用表!$L:$L,領用表!$A:$A,CY$2,領用表!$E:$E,B6) -> 5 | CZ6: =SUMIFS(領用表!$L:$L,領用表!$E:$E,$B6,領用表!$B:$B,CY$2&CZ$2) -> 4 | DA6: =SUMIFS(領用表!$L:$L,領用表!$E:$E,$B6,領用表!$B:$B,$CY$2&DA$2) -> 0 | DB6: =SUMIFS(領用表!$L:$L,領用表!$E:$E,$B6,領用表!$B:$B,$CY$2&DB$2) -> 1 | DC6: =SUMIFS(領用表!$L:$L,領用表!$E:$E,$B6,領用表!$B:$B,$CY$2&DC$2) -> 0 | DD6: =SUMIFS(領用表!$L:$L,領用表!$E:$E,$B6,領用表!$B:$B,$CY$2&DD$2) -> 0 | DE6: =SUMIFS(領用表!$L:$L,領用表!$A:$A,DE$2,領用表!$E:$E,B6) -> 7 | DF6: =SUMIFS(領用表!$L:$L,領用表!$E:$E,$B6,領用表!$B:$B,DE$2&DF$2) -> 3 | DG6: =SUMIFS(領用表!$L:$L,領用表!$E:$E,$B6,領用表!$B:$B,$DE$2&DG$2) -> 0 | DH6: =SUMIFS(領用表!$L:$L,領用表!$E:$E,$B6,領用表!$B:$B,$DE$2&DH$2) -> 4 | DI6: =SUMIFS(領用表!$L:$L,領用表!$E:$E,$B6,領用表!$B:$B,$DE$2&DI$2) -> 0 | DJ6: =SUMIFS(領用表!$L:$L,領用表!$E:$E,$B6,領用表!$B:$B,$DE$2&DJ$2) -> 0 | DK6: =SUMIFS(領用表!$L:$L,領用表!$A:$A,DK$2,領用表!$E:$E,$B6) -> 12 | DL6: =SUMIFS(領用表!$L:$L,領用表!$E:$E,$B6,領用表!$B:$B,DK$2&DL$2) -> 2 | DM6: =SUMIFS(領用表!$L:$L,領用表!$E:$E,$B6,領用表!$B:$B,$DK$2&DM$2) -> 0 | DN6: =SUMIFS(領用表!$L:$L,領用表!$E:$E,$B6,領用表!$B:$B,$DK$2&DN$2) -> 10 | DO6: =SUMIFS(領用表!$L:$L,領用表!$E:$E,$B6,領用表!$B:$B,$DK$2&DO$2) -> 0 | DP6: =SUMIFS(領用表!$L:$L,領用表!$E:$E,$B6,領用表!$B:$B,$DK$2&DP$2) -> 0 | DQ6: =SUM(CN6,CS6,CY6,DE6,DK6) -> 57 | DR6: =AVERAGEA(CN6,CS6,CY6,DE6,DK6) -> 11.4 | DS6: =SUM(DT6:DW6) -> 20 | DT6: 10 | DU6: 0 | DV6: 10 | DW6: 0 | DX6: 10 | DY6: 0 | ED6: =IFERROR(VLOOKUP(A6,站前4樓!A:BF,57,0),0) -> 3 | EE6: =IFERROR(VLOOKUP(A6,站前11樓!A:BE,57,0),0) -> 0 | EF6: =IFERROR(VLOOKUP(A6,忠孝7樓!A:N,57,0),0) -> 0 | EG6: =IFERROR(VLOOKUP(A6,忠孝國際醫學3樓!A:L,57,0),0) -> 0 | EH6: =SUM(ED6:EG6) -> 3 | EJ6: 23 | EK6: 31
A7: MP1MA020022A | B7: 6150004 | C7: 喬雅登豐塑玻尿酸植入物Volux 1ml/ syringe(1支) | D7: 2 | E7: PCS | F7: =SUMIF(站前4樓!B:B,B7,站前4樓!F:F) -> 10 | G7: =SUMIF(站前11樓!B:B,B7,站前11樓!F:F) -> 0 | H7: =SUMIF(忠孝7樓!B:B,B7,忠孝7樓!G:G) -> 3 | I7: =SUMIF(忠孝國際醫學3樓!B:B,B7,忠孝國際醫學3樓!G:G) -> 0 | J7: =SUMIF(忠孝健康7樓!B:B,B7,忠孝健康7樓!G:G) -> 3 | K7: 2 | L7: 2 | M7: 0 | N7: 2 | O7: 2 | P7: 2 | Q7: 0 | R7: 0 | S7: 2 | T7: 3 | U7: 0 | V7: 3 | W7: 1 | X7: 3 | Y7: 4 | Z7: 4 | AA7: 5 | AB7: 1 | AC7: 4 | AD7: 8 | AE7: 1 | AF7: 2 | AG7: 5 | AH7: 1 | AI7: 3 | AJ7: 2 | AK7: 0.5 | AL7: 1.5 | AM7: 0.5 | AN7: 2.5 | AO7: 1.5 | AP7: 2.5 | AQ7: 5.5 | AR7: 6 | AS7: 4 | AT7: 2.5 | AU7: 1 | AV7: =SUM(AJ7:AU7) -> 30 | AW7: =AV7/12 -> 2.5 | AX7: 6 | AY7: 5 | AZ7: 16 | BA7: 26 | BB7: 19 | BC7: =SUMIFS(領用表!$L:$L,領用表!$A:$A,BC$2,領用表!$E:$E,B7) -> 14 | BD7: =SUMIFS(領用表!$L:$L,領用表!$E:$E,$B7,領用表!$B:$B,BC$2&BD$2) -> 14 | BE7: =SUMIFS(領用表!$L:$L,領用表!$E:$E,$B7,領用表!$B:$B,$BC$2&BE$2) -> 0 | BF7: =SUMIFS(領用表!$L:$L,領用表!$E:$E,$B7,領用表!$B:$B,$BC$2&BF$2) -> 0 | BG7: =SUMIFS(領用表!$L:$L,領用表!$E:$E,$B7,領用表!$B:$B,$BC$2&BG$2) -> 0 | BH7: =SUMIFS(領用表!$L:$L,領用表!$A:$A,BH$2,領用表!$E:$E,B7) -> 24 | BI7: =SUMIFS(領用表!$L:$L,領用表!$E:$E,$B7,領用表!$B:$B,BH$2&BI$2) -> 13 | BJ7: =SUMIFS(領用表!$L:$L,領用表!$E:$E,$B7,領用表!$B:$B,$BH$2&BJ$2) -> 0 | BK7: =SUMIFS(領用表!$L:$L,領用表!$E:$E,$B7,領用表!$B:$B,$BH$2&BK$2) -> 11 | BL7: =SUMIFS(領用表!$L:$L,領用表!$E:$E,$B7,領用表!$B:$B,$BH$2&BL$2) -> 0 | BM7: =SUMIFS(領用表!$L:$L,領用表!$A:$A,BM$2,領用表!$E:$E,B7) -> 49 | BN7: =SUMIFS(領用表!$L:$L,領用表!$E:$E,$B7,領用表!$B:$B,BM$2&BN$2) -> 10 | BO7: =SUMIFS(領用表!$L:$L,領用表!$E:$E,$B7,領用表!$B:$B,$BM$2&BO$2) -> 0 | BP7: =SUMIFS(領用表!$L:$L,領用表!$E:$E,$B7,領用表!$B:$B,$BM$2&BP$2) -> 39 | BQ7: =SUMIFS(領用表!$L:$L,領用表!$E:$E,$B7,領用表!$B:$B,$BM$2&BQ$2) -> 0 | BR7: =SUMIFS(領用表!$L:$L,領用表!$A:$A,BR$2,領用表!$E:$E,B7) -> 35 | BS7: =SUMIFS(領用表!$L:$L,領用表!$E:$E,$B7,領用表!$B:$B,BR$2&BS$2) -> 10 | BT7: =SUMIFS(領用表!$L:$L,領用表!$E:$E,$B7,領用表!$B:$B,$BR$2&BT$2) -> 0 | BU7: =SUMIFS(領用表!$L:$L,領用表!$E:$E,$B7,領用表!$B:$B,$BR$2&BU$2) -> 25 | BV7: =SUMIFS(領用表!$L:$L,領用表!$E:$E,$B7,領用表!$B:$B,$BR$2&BV$2) -> 0 | BW7: =SUMIFS(領用表!$L:$L,領用表!$A:$A,BW$2,領用表!$E:$E,B7) -> 33 | BX7: =SUMIFS(領用表!$L:$L,領用表!$E:$E,$B7,領用表!$B:$B,BW$2&BX$2) -> 12 | BY7: =SUMIFS(領用表!$L:$L,領用表!$E:$E,$B7,領用表!$B:$B,$BW$2&BY$2) -> 0 | BZ7: =SUMIFS(領用表!$L:$L,領用表!$E:$E,$B7,領用表!$B:$B,$BW$2&BZ$2) -> 21 | CA7: =SUMIFS(領用表!$L:$L,領用表!$E:$E,$B7,領用表!$B:$B,$BW$2&CA$2) -> 0 | CB7: =SUMIFS(領用表!$L:$L,領用表!$A:$A,CB$2,領用表!$E:$E,B7) -> 23 | CC7: =SUMIFS(領用表!$L:$L,領用表!$E:$E,$B7,領用表!$B:$B,CB$2&CC$2) -> 8 | CD7: =SUMIFS(領用表!$L:$L,領用表!$E:$E,$B7,領用表!$B:$B,$CB$2&CD$2) -> 0 | CE7: =SUMIFS(領用表!$L:$L,領用表!$E:$E,$B7,領用表!$B:$B,$CB$2&CE$2) -> 15 | CF7: =SUMIFS(領用表!$L:$L,領用表!$E:$E,$B7,領用表!$B:$B,$CB$2&CF$2) -> 0 | CG7: =SUMIFS(領用表!$L:$L,領用表!$A:$A,CG$2,領用表!$E:$E,B7) -> 31 | CH7: =SUMIFS(領用表!$L:$L,領用表!$E:$E,$B7,領用表!$B:$B,CG$2&CH$2) -> 13 | CI7: =SUMIFS(領用表!$L:$L,領用表!$E:$E,$B7,領用表!$B:$B,CG$2&CI$2) -> 0 | CJ7: =SUMIFS(領用表!$L:$L,領用表!$E:$E,$B7,領用表!$B:$B,CG$2&CJ$2) -> 18 | CK7: =SUMIFS(領用表!$L:$L,領用表!$E:$E,$B7,領用表!$B:$B,$CG$2&CK$2) -> 0 | CL7: =SUM(AX7,AY7,AZ7,BA7,BB7,BC7,BH7,BM7,BR7,BW7,CB7,CG7) -> 281 | CM7: =AVERAGE(AX7,AY7,AZ7,BA7,BB7,BC7,BH7,BM7,BR7,BW7,CB7,CG7) -> 23.416667 | CN7: =SUMIFS(領用表!$L:$L,領用表!$A:$A,CN$2,領用表!$E:$E,B7) -> 26 | CO7: =SUMIFS(領用表!$L:$L,領用表!$E:$E,$B7,領用表!$B:$B,CN$2&CO$2) -> 12 | CP7: =SUMIFS(領用表!$L:$L,領用表!$E:$E,$B7,領用表!$B:$B,$CN$2&CP$2) -> 0 | CQ7: =SUMIFS(領用表!$L:$L,領用表!$E:$E,$B7,領用表!$B:$B,$CN$2&CQ$2) -> 14 | CR7: =SUMIFS(領用表!$L:$L,領用表!$E:$E,$B7,領用表!$B:$B,$CN$2&CR$2) -> 0 | CS7: =SUMIFS(領用表!$L:$L,領用表!$A:$A,CS$2,領用表!$E:$E,B7) -> 35 | CT7: =SUMIFS(領用表!$L:$L,領用表!$E:$E,$B7,領用表!$B:$B,CS$2&CT$2) -> 14 | CU7: =SUMIFS(領用表!$L:$L,領用表!$E:$E,$B7,領用表!$B:$B,$CS$2&CU$2) -> 0 | CV7: =SUMIFS(領用表!$L:$L,領用表!$E:$E,$B7,領用表!$B:$B,$CS$2&CV$2) -> 19 | CW7: =SUMIFS(領用表!$L:$L,領用表!$E:$E,$B7,領用表!$B:$B,$CS$2&CW$2) -> 0 | CX7: =SUMIFS(領用表!$L:$L,領用表!$E:$E,$B7,領用表!$B:$B,$CS$2&CX$2) -> 2 | CY7: =SUMIFS(領用表!$L:$L,領用表!$A:$A,CY$2,領用表!$E:$E,B7) -> 29 | CZ7: =SUMIFS(領用表!$L:$L,領用表!$E:$E,$B7,領用表!$B:$B,CY$2&CZ$2) -> 14 | DA7: =SUMIFS(領用表!$L:$L,領用表!$E:$E,$B7,領用表!$B:$B,$CY$2&DA$2) -> 0 | DB7: =SUMIFS(領用表!$L:$L,領用表!$E:$E,$B7,領用表!$B:$B,$CY$2&DB$2) -> 10 | DC7: =SUMIFS(領用表!$L:$L,領用表!$E:$E,$B7,領用表!$B:$B,$CY$2&DC$2) -> 0 | DD7: =SUMIFS(領用表!$L:$L,領用表!$E:$E,$B7,領用表!$B:$B,$CY$2&DD$2) -> 5 | DE7: =SUMIFS(領用表!$L:$L,領用表!$A:$A,DE$2,領用表!$E:$E,B7) -> 32 | DF7: =SUMIFS(領用表!$L:$L,領用表!$E:$E,$B7,領用表!$B:$B,DE$2&DF$2) -> 14 | DG7: =SUMIFS(領用表!$L:$L,領用表!$E:$E,$B7,領用表!$B:$B,$DE$2&DG$2) -> 0 | DH7: =SUMIFS(領用表!$L:$L,領用表!$E:$E,$B7,領用表!$B:$B,$DE$2&DH$2) -> 10 | DI7: =SUMIFS(領用表!$L:$L,領用表!$E:$E,$B7,領用表!$B:$B,$DE$2&DI$2) -> 0 | DJ7: =SUMIFS(領用表!$L:$L,領用表!$E:$E,$B7,領用表!$B:$B,$DE$2&DJ$2) -> 8 | DK7: =SUMIFS(領用表!$L:$L,領用表!$A:$A,DK$2,領用表!$E:$E,$B7) -> 40 | DL7: =SUMIFS(領用表!$L:$L,領用表!$E:$E,$B7,領用表!$B:$B,DK$2&DL$2) -> 9 | DM7: =SUMIFS(領用表!$L:$L,領用表!$E:$E,$B7,領用表!$B:$B,$DK$2&DM$2) -> 0 | DN7: =SUMIFS(領用表!$L:$L,領用表!$E:$E,$B7,領用表!$B:$B,$DK$2&DN$2) -> 26 | DO7: =SUMIFS(領用表!$L:$L,領用表!$E:$E,$B7,領用表!$B:$B,$DK$2&DO$2) -> 0 | DP7: =SUMIFS(領用表!$L:$L,領用表!$E:$E,$B7,領用表!$B:$B,$DK$2&DP$2) -> 5 | DQ7: =SUM(CN7,CS7,CY7,DE7,DK7) -> 162 | DR7: =AVERAGEA(CN7,CS7,CY7,DE7,DK7) -> 32.4 | DS7: =SUM(DT7:DW7) -> 30 | DT7: 15 | DU7: 0 | DV7: 15 | DW7: 0 | DX7: 20 | DY7: 0 | EA7: 15盒(10/21) | ED7: =IFERROR(VLOOKUP(A7,站前4樓!A:BF,57,0),0) -> 8 | EE7: =IFERROR(VLOOKUP(A7,站前11樓!A:BE,57,0),0) -> 0 | EF7: =IFERROR(VLOOKUP(A7,忠孝7樓!A:N,57,0),0) -> 0 | EG7: =IFERROR(VLOOKUP(A7,忠孝國際醫學3樓!A:L,57,0),0) -> 0 | EH7: =SUM(ED7:EG7) -> 8 | EJ7: 38 | EK7: 32
A8: MP1MA020023A | B8: 6150005 | C8: 喬雅登芙潤玻尿酸植入物Volite 1ml/ Syringe(1支) | D8: 2 | E8: PCS | F8: =SUMIF(站前4樓!B:B,B8,站前4樓!F:F) -> 0 | G8: =SUMIF(站前11樓!B:B,B8,站前11樓!F:F) -> 0 | H8: =SUMIF(忠孝7樓!B:B,B8,忠孝7樓!G:G) -> 0 | I8: =SUMIF(忠孝國際醫學3樓!B:B,B8,忠孝國際醫學3樓!G:G) -> 0 | J8: =SUMIF(忠孝健康7樓!B:B,B8,忠孝健康7樓!G:G) -> 0 | K8: 0 | L8: 0 | M8: 0 | N8: 0 | O8: 0 | P8: 0 | Q8: 3 | R8: 0 | S8: 0 | T8: 0 | U8: 3 | V8: 2 | W8: 2 | X8: 1 | Y8: 1 | Z8: 0 | AA8: 0 | AB8: 0 | AC8: 0 | AD8: 0 | AE8: 0 | AF8: 0 | AG8: 5 | AH8: 0 | AI8: 0 | AJ8: 0.5 | AK8: 1.5 | AL8: 2 | AM8: 2.5 | AN8: 2 | AO8: 5.5 | AP8: 2.5 | AQ8: 7 | AR8: 2 | AS8: 1 | AT8: 0.5 | AU8: 4 | AV8: =SUM(AJ8:AU8) -> 31 | AW8: =AV8/12 -> 2.5833333 | AX8: 2 | AY8: 3 | AZ8: 6 | BA8: 2 | BB8: 3 | BC8: =SUMIFS(領用表!$L:$L,領用表!$A:$A,BC$2,領用表!$E:$E,B8) -> 0 | BD8: =SUMIFS(領用表!$L:$L,領用表!$E:$E,$B8,領用表!$B:$B,BC$2&BD$2) -> 0 | BE8: =SUMIFS(領用表!$L:$L,領用表!$E:$E,$B8,領用表!$B:$B,$BC$2&BE$2) -> 0 | BF8: =SUMIFS(領用表!$L:$L,領用表!$E:$E,$B8,領用表!$B:$B,$BC$2&BF$2) -> 0 | BG8: =SUMIFS(領用表!$L:$L,領用表!$E:$E,$B8,領用表!$B:$B,$BC$2&BG$2) -> 0 | BH8: =SUMIFS(領用表!$L:$L,領用表!$A:$A,BH$2,領用表!$E:$E,B8) -> 2 | BI8: =SUMIFS(領用表!$L:$L,領用表!$E:$E,$B8,領用表!$B:$B,BH$2&BI$2) -> 2 | BJ8: =SUMIFS(領用表!$L:$L,領用表!$E:$E,$B8,領用表!$B:$B,$BH$2&BJ$2) -> 0 | BK8: =SUMIFS(領用表!$L:$L,領用表!$E:$E,$B8,領用表!$B:$B,$BH$2&BK$2) -> 0 | BL8: =SUMIFS(領用表!$L:$L,領用表!$E:$E,$B8,領用表!$B:$B,$BH$2&BL$2) -> 0 | BM8: =SUMIFS(領用表!$L:$L,領用表!$A:$A,BM$2,領用表!$E:$E,B8) -> 9 | BN8: =SUMIFS(領用表!$L:$L,領用表!$E:$E,$B8,領用表!$B:$B,BM$2&BN$2) -> 5 | BO8: =SUMIFS(領用表!$L:$L,領用表!$E:$E,$B8,領用表!$B:$B,$BM$2&BO$2) -> 0 | BP8: =SUMIFS(領用表!$L:$L,領用表!$E:$E,$B8,領用表!$B:$B,$BM$2&BP$2) -> 4 | BQ8: =SUMIFS(領用表!$L:$L,領用表!$E:$E,$B8,領用表!$B:$B,$BM$2&BQ$2) -> 0 | BR8: =SUMIFS(領用表!$L:$L,領用表!$A:$A,BR$2,領用表!$E:$E,B8) -> 5 | BS8: =SUMIFS(領用表!$L:$L,領用表!$E:$E,$B8,領用表!$B:$B,BR$2&BS$2) -> 2 | BT8: =SUMIFS(領用表!$L:$L,領用表!$E:$E,$B8,領用表!$B:$B,$BR$2&BT$2) -> 0 | BU8: =SUMIFS(領用表!$L:$L,領用表!$E:$E,$B8,領用表!$B:$B,$BR$2&BU$2) -> 3 | BV8: =SUMIFS(領用表!$L:$L,領用表!$E:$E,$B8,領用表!$B:$B,$BR$2&BV$2) -> 0 | BW8: =SUMIFS(領用表!$L:$L,領用表!$A:$A,BW$2,領用表!$E:$E,B8) -> 2 | BX8: =SUMIFS(領用表!$L:$L,領用表!$E:$E,$B8,領用表!$B:$B,BW$2&BX$2) -> 1 | BY8: =SUMIFS(領用表!$L:$L,領用表!$E:$E,$B8,領用表!$B:$B,$BW$2&BY$2) -> 0 | BZ8: =SUMIFS(領用表!$L:$L,領用表!$E:$E,$B8,領用表!$B:$B,$BW$2&BZ$2) -> 1 | CA8: =SUMIFS(領用表!$L:$L,領用表!$E:$E,$B8,領用表!$B:$B,$BW$2&CA$2) -> 0 | CB8: =SUMIFS(領用表!$L:$L,領用表!$A:$A,CB$2,領用表!$E:$E,B8) -> 4 | CC8: =SUMIFS(領用表!$L:$L,領用表!$E:$E,$B8,領用表!$B:$B,CB$2&CC$2) -> 3 | CD8: =SUMIFS(領用表!$L:$L,領用表!$E:$E,$B8,領用表!$B:$B,$CB$2&CD$2) -> 0 | CE8: =SUMIFS(領用表!$L:$L,領用表!$E:$E,$B8,領用表!$B:$B,$CB$2&CE$2) -> 1 | CF8: =SUMIFS(領用表!$L:$L,領用表!$E:$E,$B8,領用表!$B:$B,$CB$2&CF$2) -> 0 | CG8: =SUMIFS(領用表!$L:$L,領用表!$A:$A,CG$2,領用表!$E:$E,B8) -> 6 | CH8: =SUMIFS(領用表!$L:$L,領用表!$E:$E,$B8,領用表!$B:$B,CG$2&CH$2) -> 4 | CI8: =SUMIFS(領用表!$L:$L,領用表!$E:$E,$B8,領用表!$B:$B,CG$2&CI$2) -> 0 | CJ8: =SUMIFS(領用表!$L:$L,領用表!$E:$E,$B8,領用表!$B:$B,CG$2&CJ$2) -> 2 | CK8: =SUMIFS(領用表!$L:$L,領用表!$E:$E,$B8,領用表!$B:$B,$CG$2&CK$2) -> 0 | CL8: =SUM(AX8,AY8,AZ8,BA8,BB8,BC8,BH8,BM8,BR8,BW8,CB8,CG8) -> 44 | CM8: =AVERAGE(AX8,AY8,AZ8,BA8,BB8,BC8,BH8,BM8,BR8,BW8,CB8,CG8) -> 3.6666667 | CN8: =SUMIFS(領用表!$L:$L,領用表!$A:$A,CN$2,領用表!$E:$E,B8) -> 9 | CO8: =SUMIFS(領用表!$L:$L,領用表!$E:$E,$B8,領用表!$B:$B,CN$2&CO$2) -> 3 | CP8: =SUMIFS(領用表!$L:$L,領用表!$E:$E,$B8,領用表!$B:$B,$CN$2&CP$2) -> 0 | CQ8: =SUMIFS(領用表!$L:$L,領用表!$E:$E,$B8,領用表!$B:$B,$CN$2&CQ$2) -> 6 | CR8: =SUMIFS(領用表!$L:$L,領用表!$E:$E,$B8,領用表!$B:$B,$CN$2&CR$2) -> 0 | CS8: =SUMIFS(領用表!$L:$L,領用表!$A:$A,CS$2,領用表!$E:$E,B8) -> 11 | CT8: =SUMIFS(領用表!$L:$L,領用表!$E:$E,$B8,領用表!$B:$B,CS$2&CT$2) -> 4 | CU8: =SUMIFS(領用表!$L:$L,領用表!$E:$E,$B8,領用表!$B:$B,$CS$2&CU$2) -> 0 | CV8: =SUMIFS(領用表!$L:$L,領用表!$E:$E,$B8,領用表!$B:$B,$CS$2&CV$2) -> 7 | CW8: =SUMIFS(領用表!$L:$L,領用表!$E:$E,$B8,領用表!$B:$B,$CS$2&CW$2) -> 0 | CX8: =SUMIFS(領用表!$L:$L,領用表!$E:$E,$B8,領用表!$B:$B,$CS$2&CX$2) -> 0 | CY8: =SUMIFS(領用表!$L:$L,領用表!$A:$A,CY$2,領用表!$E:$E,B8) -> 5 | CZ8: =SUMIFS(領用表!$L:$L,領用表!$E:$E,$B8,領用表!$B:$B,CY$2&CZ$2) -> 3 | DA8: =SUMIFS(領用表!$L:$L,領用表!$E:$E,$B8,領用表!$B:$B,$CY$2&DA$2) -> 0 | DB8: =SUMIFS(領用表!$L:$L,領用表!$E:$E,$B8,領用表!$B:$B,$CY$2&DB$2) -> 1 | DC8: =SUMIFS(領用表!$L:$L,領用表!$E:$E,$B8,領用表!$B:$B,$CY$2&DC$2) -> 0 | DD8: =SUMIFS(領用表!$L:$L,領用表!$E:$E,$B8,領用表!$B:$B,$CY$2&DD$2) -> 1 | DE8: =SUMIFS(領用表!$L:$L,領用表!$A:$A,DE$2,領用表!$E:$E,B8) -> 2 | DF8: =SUMIFS(領用表!$L:$L,領用表!$E:$E,$B8,領用表!$B:$B,DE$2&DF$2) -> 1 | DG8: =SUMIFS(領用表!$L:$L,領用表!$E:$E,$B8,領用表!$B:$B,$DE$2&DG$2) -> 0 | DH8: =SUMIFS(領用表!$L:$L,領用表!$E:$E,$B8,領用表!$B:$B,$DE$2&DH$2) -> 1 | DI8: =SUMIFS(領用表!$L:$L,領用表!$E:$E,$B8,領用表!$B:$B,$DE$2&DI$2) -> 0 | DJ8: =SUMIFS(領用表!$L:$L,領用表!$E:$E,$B8,領用表!$B:$B,$DE$2&DJ$2) -> 0 | DK8: =SUMIFS(領用表!$L:$L,領用表!$A:$A,DK$2,領用表!$E:$E,$B8) -> 4 | DL8: =SUMIFS(領用表!$L:$L,領用表!$E:$E,$B8,領用表!$B:$B,DK$2&DL$2) -> 4 | DM8: =SUMIFS(領用表!$L:$L,領用表!$E:$E,$B8,領用表!$B:$B,$DK$2&DM$2) -> 0 | DN8: =SUMIFS(領用表!$L:$L,領用表!$E:$E,$B8,領用表!$B:$B,$DK$2&DN$2) -> 0 | DO8: =SUMIFS(領用表!$L:$L,領用表!$E:$E,$B8,領用表!$B:$B,$DK$2&DO$2) -> 0 | DP8: =SUMIFS(領用表!$L:$L,領用表!$E:$E,$B8,領用表!$B:$B,$DK$2&DP$2) -> 0 | DQ8: =SUM(CN8,CS8,CY8,DE8,DK8) -> 31 | DR8: =AVERAGEA(CN8,CS8,CY8,DE8,DK8) -> 6.2 | DS8: =SUM(DT8:DW8) -> 10 | DT8: 5 | DU8: 0 | DV8: 5 | DW8: 0 | DX8: 6 | DY8: 0 | ED8: =IFERROR(VLOOKUP(A8,站前4樓!A:BF,57,0),0) -> 3 | EE8: =IFERROR(VLOOKUP(A8,站前11樓!A:BE,57,0),0) -> 0 | EF8: =IFERROR(VLOOKUP(A8,忠孝7樓!A:N,57,0),0) -> 0 | EG8: =IFERROR(VLOOKUP(A8,忠孝國際醫學3樓!A:L,57,0),0) -> 0 | EH8: =SUM(ED8:EG8) -> 3 | EJ8: 26 | EK8: 7
B9: 6150015 | C9: 喬雅登絲漾膚玻尿酸植入物Skinvive 1ml/支 | D9: 2 | E9: PCS | F9: =SUMIF(站前4樓!B:B,B9,站前4樓!F:F) -> 2 | G9: =SUMIF(站前11樓!B:B,B9,站前11樓!F:F) -> 0 | H9: =SUMIF(忠孝7樓!B:B,B9,忠孝7樓!G:G) -> 5 | I9: =SUMIF(忠孝國際醫學3樓!B:B,B9,忠孝國際醫學3樓!G:G) -> 0 | J9: =SUMIF(忠孝健康7樓!B:B,B9,忠孝健康7樓!G:G) -> 1 | CL9: =SUM(AX9,AY9,AZ9,BA9,BB9,BC9,BH9,BM9,BR9,BW9,CB9,CG9) -> 0 | CM9: =IFERROR(AVERAGE(AX9,AY9,AZ9,BA9,BB9,BC9,BH9,BM9,BR9,BW9,CB9,CG9),0) -> 0 | CN9: =SUMIFS(領用表!$L:$L,領用表!$A:$A,CN$2,領用表!$E:$E,B9) -> 0 | CO9: =SUMIFS(領用表!$L:$L,領用表!$E:$E,$B9,領用表!$B:$B,CN$2&CO$2) -> 0 | CP9: =SUMIFS(領用表!$L:$L,領用表!$E:$E,$B9,領用表!$B:$B,$CN$2&CP$2) -> 0 | CQ9: =SUMIFS(領用表!$L:$L,領用表!$E:$E,$B9,領用表!$B:$B,$CN$2&CQ$2) -> 0 | CR9: =SUMIFS(領用表!$L:$L,領用表!$E:$E,$B9,領用表!$B:$B,$CN$2&CR$2) -> 0 | CS9: =SUMIFS(領用表!$L:$L,領用表!$A:$A,CS$2,領用表!$E:$E,B9) -> 0 | CT9: =SUMIFS(領用表!$L:$L,領用表!$E:$E,$B9,領用表!$B:$B,CS$2&CT$2) -> 0 | CU9: =SUMIFS(領用表!$L:$L,領用表!$E:$E,$B9,領用表!$B:$B,$CS$2&CU$2) -> 0 | CV9: =SUMIFS(領用表!$L:$L,領用表!$E:$E,$B9,領用表!$B:$B,$CS$2&CV$2) -> 0 | CW9: =SUMIFS(領用表!$L:$L,領用表!$E:$E,$B9,領用表!$B:$B,$CS$2&CW$2) -> 0 | CX9: =SUMIFS(領用表!$L:$L,領用表!$E:$E,$B9,領用表!$B:$B,$CS$2&CX$2) -> 0 | CY9: =SUMIFS(領用表!$L:$L,領用表!$A:$A,CY$2,領用表!$E:$E,B9) -> 0 | CZ9: =SUMIFS(領用表!$L:$L,領用表!$E:$E,$B9,領用表!$B:$B,CY$2&CZ$2) -> 0 | DA9: =SUMIFS(領用表!$L:$L,領用表!$E:$E,$B9,領用表!$B:$B,$CY$2&DA$2) -> 0 | DB9: =SUMIFS(領用表!$L:$L,領用表!$E:$E,$B9,領用表!$B:$B,$CY$2&DB$2) -> 0 | DC9: =SUMIFS(領用表!$L:$L,領用表!$E:$E,$B9,領用表!$B:$B,$CY$2&DC$2) -> 0 | DD9: =SUMIFS(領用表!$L:$L,領用表!$E:$E,$B9,領用表!$B:$B,$CY$2&DD$2) -> 0 | DE9: =SUMIFS(領用表!$L:$L,領用表!$A:$A,DE$2,領用表!$E:$E,B9) -> 2 | DF9: =SUMIFS(領用表!$L:$L,領用表!$E:$E,$B9,領用表!$B:$B,DE$2&DF$2) -> 2 | DG9: =SUMIFS(領用表!$L:$L,領用表!$E:$E,$B9,領用表!$B:$B,$DE$2&DG$2) -> 0 | DH9: =SUMIFS(領用表!$L:$L,領用表!$E:$E,$B9,領用表!$B:$B,$DE$2&DH$2) -> 0 | DI9: =SUMIFS(領用表!$L:$L,領用表!$E:$E,$B9,領用表!$B:$B,$DE$2&DI$2) -> 0 | DJ9: =SUMIFS(領用表!$L:$L,領用表!$E:$E,$B9,領用表!$B:$B,$DE$2&DJ$2) -> 0 | DK9: =SUMIFS(領用表!$L:$L,領用表!$A:$A,DK$2,領用表!$E:$E,$B9) -> 13 | DL9: =SUMIFS(領用表!$L:$L,領用表!$E:$E,$B9,領用表!$B:$B,DK$2&DL$2) -> 8 | DM9: =SUMIFS(領用表!$L:$L,領用表!$E:$E,$B9,領用表!$B:$B,$DK$2&DM$2) -> 0 | DN9: =SUMIFS(領用表!$L:$L,領用表!$E:$E,$B9,領用表!$B:$B,$DK$2&DN$2) -> 3 | DO9: =SUMIFS(領用表!$L:$L,領用表!$E:$E,$B9,領用表!$B:$B,$DK$2&DO$2) -> 0 | DP9: =SUMIFS(領用表!$L:$L,領用表!$E:$E,$B9,領用表!$B:$B,$DK$2&DP$2) -> 2 | DQ9: =SUM(CN9,CS9,CY9,DE9,DK9) -> 15 | DR9: =AVERAGEA(CN9,CS9,CY9,DE9,DK9) -> 3 | DS9: =SUM(DT9:DW9) -> 0
B10: 6150016 | C10: 彈力針(1支/盒) | D10: 1 | E10: PCS | F10: =SUMIF(站前4樓!B:B,B10,站前4樓!F:F) -> 10 | G10: =SUMIF(站前11樓!B:B,B10,站前11樓!F:F) -> 0 | H10: =SUMIF(忠孝7樓!B:B,B10,忠孝7樓!G:G) -> 14 | I10: =SUMIF(忠孝國際醫學3樓!B:B,B10,忠孝國際醫學3樓!G:G) -> 0 | J10: =SUMIF(忠孝健康7樓!B:B,B10,忠孝健康7樓!G:G) -> 3 | DK10: =SUMIFS(領用表!$L:$L,領用表!$A:$A,DK$2,領用表!$E:$E,$B10) -> 0 | DL10: =SUMIFS(領用表!$L:$L,領用表!$E:$E,$B10,領用表!$B:$B,DK$2&DL$2) -> 0 | DM10: =SUMIFS(領用表!$L:$L,領用表!$E:$E,$B10,領用表!$B:$B,$DK$2&DM$2) -> 0 | DN10: =SUMIFS(領用表!$L:$L,領用表!$E:$E,$B10,領用表!$B:$B,$DK$2&DN$2) -> 0 | DO10: =SUMIFS(領用表!$L:$L,領用表!$E:$E,$B10,領用表!$B:$B,$DK$2&DO$2) -> 0 | DP10: =SUMIFS(領用表!$L:$L,領用表!$E:$E,$B10,領用表!$B:$B,$DK$2&DP$2) -> 0 | DQ10: =SUM(CN10,CS10,CY10,DE10,DK10) -> 0 | DR10: =AVERAGEA(CN10,CS10,CY10,DE10,DK10) -> 0 | DS10: =SUM(DT10:DW10) -> 0
A11: MP1MA010011A | B11: 6180015 | C11: MINT秘特拉提線EASY 42.4CM(1支) | D11: 2 | E11: PCS | F11: =SUMIF(站前4樓!B:B,B11,站前4樓!F:F) -> 2 | G11: =SUMIF(站前11樓!B:B,B11,站前11樓!F:F) -> 0 | H11: =SUMIF(忠孝7樓!B:B,B11,忠孝7樓!G:G) -> 2 | I11: =SUMIF(忠孝國際醫學3樓!B:B,B11,忠孝國際醫學3樓!G:G) -> 0 | J11: =SUMIF(忠孝健康7樓!B:B,B11,忠孝健康7樓!G:G) -> 0 | K11: 0 | L11: 0 | M11: 0 | N11: 0 | O11: 0 | P11: 0 | Q11: 0 | R11: 0 | S11: 0 | T11: 0 | U11: 0 | V11: 0 | W11: 0 | X11: 0 | Y11: 0 | Z11: 0 | AA11: 0 | AB11: 0 | AC11: 0 | AD11: 0 | AE11: 0 | AF11: 0 | AG11: 0 | AH11: 0 | AI11: 0 | AJ11: 0 | AK11: 0 | AL11: 0 | AM11: 2 | AN11: 0 | AO11: 0 | AP11: 0 | AQ11: 0 | AR11: 1 | AS11: 0 | AT11: 0 | AU11: 0 | AV11: =SUM(AJ11:AU11) -> 3 | AW11: =AV11/12 -> 0.25 | AX11: 0 | AY11: 0 | AZ11: 2 | BA11: 0 | BB11: 2 | BC11: =SUMIFS(領用表!$L:$L,領用表!$A:$A,BC$2,領用表!$E:$E,B11) -> 0 | BD11: =SUMIFS(領用表!$L:$L,領用表!$E:$E,$B11,領用表!$B:$B,BC$2&BD$2) -> 0 | BE11: =SUMIFS(領用表!$L:$L,領用表!$E:$E,$B11,領用表!$B:$B,$BC$2&BE$2) -> 0 | BF11: =SUMIFS(領用表!$L:$L,領用表!$E:$E,$B11,領用表!$B:$B,$BC$2&BF$2) -> 0 | BG11: =SUMIFS(領用表!$L:$L,領用表!$E:$E,$B11,領用表!$B:$B,$BC$2&BG$2) -> 0 | BH11: =SUMIFS(領用表!$L:$L,領用表!$A:$A,BH$2,領用表!$E:$E,B11) -> 0 | BI11: =SUMIFS(領用表!$L:$L,領用表!$E:$E,$B11,領用表!$B:$B,BH$2&BI$2) -> 0 | BJ11: =SUMIFS(領用表!$L:$L,領用表!$E:$E,$B11,領用表!$B:$B,$BH$2&BJ$2) -> 0 | BK11: =SUMIFS(領用表!$L:$L,領用表!$E:$E,$B11,領用表!$B:$B,$BH$2&BK$2) -> 0 | BL11: =SUMIFS(領用表!$L:$L,領用表!$E:$E,$B11,領用表!$B:$B,$BH$2&BL$2) -> 0 | BM11: =SUMIFS(領用表!$L:$L,領用表!$A:$A,BM$2,領用表!$E:$E,B11) -> 0 | BN11: =SUMIFS(領用表!$L:$L,領用表!$E:$E,$B11,領用表!$B:$B,BM$2&BN$2) -> 0 | BO11: =SUMIFS(領用表!$L:$L,領用表!$E:$E,$B11,領用表!$B:$B,$BM$2&BO$2) -> 0 | BP11: =SUMIFS(領用表!$L:$L,領用表!$E:$E,$B11,領用表!$B:$B,$BM$2&BP$2) -> 0 | BQ11: =SUMIFS(領用表!$L:$L,領用表!$E:$E,$B11,領用表!$B:$B,$BM$2&BQ$2) -> 0 | BR11: =SUMIFS(領用表!$L:$L,領用表!$A:$A,BR$2,領用表!$E:$E,B11) -> 0 | BS11: =SUMIFS(領用表!$L:$L,領用表!$E:$E,$B11,領用表!$B:$B,BR$2&BS$2) -> 0 | BT11: =SUMIFS(領用表!$L:$L,領用表!$E:$E,$B11,領用表!$B:$B,$BR$2&BT$2) -> 0 | BU11: =SUMIFS(領用表!$L:$L,領用表!$E:$E,$B11,領用表!$B:$B,$BR$2&BU$2) -> 0 | BV11: =SUMIFS(領用表!$L:$L,領用表!$E:$E,$B11,領用表!$B:$B,$BR$2&BV$2) -> 0 | BW11: =SUMIFS(領用表!$L:$L,領用表!$A:$A,BW$2,領用表!$E:$E,B11) -> 0 | BX11: =SUMIFS(領用表!$L:$L,領用表!$E:$E,$B11,領用表!$B:$B,BW$2&BX$2) -> 0 | BY11: =SUMIFS(領用表!$L:$L,領用表!$E:$E,$B11,領用表!$B:$B,$BW$2&BY$2) -> 0 | BZ11: =SUMIFS(領用表!$L:$L,領用表!$E:$E,$B11,領用表!$B:$B,$BW$2&BZ$2) -> 0 | CA11: =SUMIFS(領用表!$L:$L,領用表!$E:$E,$B11,領用表!$B:$B,$BW$2&CA$2) -> 0 | CB11: =SUMIFS(領用表!$L:$L,領用表!$A:$A,CB$2,領用表!$E:$E,B11) -> 0 | CC11: =SUMIFS(領用表!$L:$L,領用表!$E:$E,$B11,領用表!$B:$B,CB$2&CC$2) -> 0 | CD11: =SUMIFS(領用表!$L:$L,領用表!$E:$E,$B11,領用表!$B:$B,$CB$2&CD$2) -> 0 | CE11: =SUMIFS(領用表!$L:$L,領用表!$E:$E,$B11,領用表!$B:$B,$CB$2&CE$2) -> 0 | CF11: =SUMIFS(領用表!$L:$L,領用表!$E:$E,$B11,領用表!$B:$B,$CB$2&CF$2) -> 0 | CG11: =SUMIFS(領用表!$L:$L,領用表!$A:$A,CG$2,領用表!$E:$E,B11) -> 0 | CH11: =SUMIFS(領用表!$L:$L,領用表!$E:$E,$B11,領用表!$B:$B,CG$2&CH$2) -> 0 | CI11: =SUMIFS(領用表!$L:$L,領用表!$E:$E,$B11,領用表!$B:$B,CG$2&CI$2) -> 0 | CJ11: =SUMIFS(領用表!$L:$L,領用表!$E:$E,$B11,領用表!$B:$B,CG$2&CJ$2) -> 0 | CK11: =SUMIFS(領用表!$L:$L,領用表!$E:$E,$B11,領用表!$B:$B,$CG$2&CK$2) -> 0 | CL11: =SUM(AX11,AY11,AZ11,BA11,BB11,BC11,BH11,BM11,BR11,BW11,CB11,CG11) -> 4 | CM11: =AVERAGE(AX11,AY11,AZ11,BA11,BB11,BC11,BH11,BM11,BR11,BW11,CB11,CG11) -> 0.33333333 | CN11: =SUMIFS(領用表!$L:$L,領用表!$A:$A,CN$2,領用表!$E:$E,B11) -> 0 | CO11: =SUMIFS(領用表!$L:$L,領用表!$E:$E,$B11,領用表!$B:$B,CN$2&CO$2) -> 0 | CP11: =SUMIFS(領用表!$L:$L,領用表!$E:$E,$B11,領用表!$B:$B,$CN$2&CP$2) -> 0 | CQ11: =SUMIFS(領用表!$L:$L,領用表!$E:$E,$B11,領用表!$B:$B,$CN$2&CQ$2) -> 0 | CR11: =SUMIFS(領用表!$L:$L,領用表!$E:$E,$B11,領用表!$B:$B,$CN$2&CR$2) -> 0 | CS11: =SUMIFS(領用表!$L:$L,領用表!$A:$A,CS$2,領用表!$E:$E,B11) -> 0 | CT11: =SUMIFS(領用表!$L:$L,領用表!$E:$E,$B11,領用表!$B:$B,CS$2&CT$2) -> 0 | CU11: =SUMIFS(領用表!$L:$L,領用表!$E:$E,$B11,領用表!$B:$B,$CS$2&CU$2) -> 0 | CV11: =SUMIFS(領用表!$L:$L,領用表!$E:$E,$B11,領用表!$B:$B,$CS$2&CV$2) -> 0 | CW11: =SUMIFS(領用表!$L:$L,領用表!$E:$E,$B11,領用表!$B:$B,$CS$2&CW$2) -> 0 | CX11: =SUMIFS(領用表!$L:$L,領用表!$E:$E,$B11,領用表!$B:$B,$CS$2&CX$2) -> 0 | CY11: =SUMIFS(領用表!$L:$L,領用表!$A:$A,CY$2,領用表!$E:$E,B11) -> 0 | CZ11: =SUMIFS(領用表!$L:$L,領用表!$E:$E,$B11,領用表!$B:$B,CY$2&CZ$2) -> 0 | DA11: =SUMIFS(領用表!$L:$L,領用表!$E:$E,$B11,領用表!$B:$B,$CY$2&DA$2) -> 0 | DB11: =SUMIFS(領用表!$L:$L,領用表!$E:$E,$B11,領用表!$B:$B,$CY$2&DB$2) -> 0 | DC11: =SUMIFS(領用表!$L:$L,領用表!$E:$E,$B11,領用表!$B:$B,$CY$2&DC$2) -> 0 | DD11: =SUMIFS(領用表!$L:$L,領用表!$E:$E,$B11,領用表!$B:$B,$CY$2&DD$2) -> 0 | DE11: =SUMIFS(領用表!$L:$L,領用表!$A:$A,DE$2,領用表!$E:$E,B11) -> 0 | DF11: =SUMIFS(領用表!$L:$L,領用表!$E:$E,$B11,領用表!$B:$B,DE$2&DF$2) -> 0 | DG11: =SUMIFS(領用表!$L:$L,領用表!$E:$E,$B11,領用表!$B:$B,$DE$2&DG$2) -> 0 | DH11: =SUMIFS(領用表!$L:$L,領用表!$E:$E,$B11,領用表!$B:$B,$DE$2&DH$2) -> 0 | DI11: =SUMIFS(領用表!$L:$L,領用表!$E:$E,$B11,領用表!$B:$B,$DE$2&DI$2) -> 0 | DJ11: =SUMIFS(領用表!$L:$L,領用表!$E:$E,$B11,領用表!$B:$B,$DE$2&DJ$2) -> 0 | DK11: =SUMIFS(領用表!$L:$L,領用表!$A:$A,DK$2,領用表!$E:$E,$B11) -> 0 | DL11: =SUMIFS(領用表!$L:$L,領用表!$E:$E,$B11,領用表!$B:$B,DK$2&DL$2) -> 0 | DM11: =SUMIFS(領用表!$L:$L,領用表!$E:$E,$B11,領用表!$B:$B,$DK$2&DM$2) -> 0 | DN11: =SUMIFS(領用表!$L:$L,領用表!$E:$E,$B11,領用表!$B:$B,$DK$2&DN$2) -> 0 | DO11: =SUMIFS(領用表!$L:$L,領用表!$E:$E,$B11,領用表!$B:$B,$DK$2&DO$2) -> 0 | DP11: =SUMIFS(領用表!$L:$L,領用表!$E:$E,$B11,領用表!$B:$B,$DK$2&DP$2) -> 0 | DQ11: =SUM(CN11,CS11,CY11,DE11,DK11) -> 0 | DR11: =AVERAGEA(CN11,CS11,CY11,DE11,DK11) -> 0 | DS11: =SUM(DT11:DW11) -> 2 | DT11: 1 | DU11: 0 | DV11: 1 | DW11: 0 | DX11: 1 | ED11: =IFERROR(VLOOKUP(A11,站前4樓!A:BF,57,0),0) -> 0 | EE11: =IFERROR(VLOOKUP(A11,站前11樓!A:BE,57,0),0) -> 0 | EF11: =IFERROR(VLOOKUP(A11,忠孝7樓!A:N,57,0),0) -> 0 | EG11: =IFERROR(VLOOKUP(A11,忠孝國際醫學3樓!A:L,57,0),0) -> 0 | EH11: =SUM(ED11:EG11) -> 0 | EJ11: 6 | EK11: 4
A12: MP1MA010012A | B12: 6180005 | C12: MINT秘特拉提線FINE 18CM(1支) | D12: 20 | E12: PCS | F12: =SUMIF(站前4樓!B:B,B12,站前4樓!F:F) -> 0 | G12: =SUMIF(站前11樓!B:B,B12,站前11樓!F:F) -> 0 | H12: =SUMIF(忠孝7樓!B:B,B12,忠孝7樓!G:G) -> 28 | I12: =SUMIF(忠孝國際醫學3樓!B:B,B12,忠孝國際醫學3樓!G:G) -> 0 | J12: =SUMIF(忠孝健康7樓!B:B,B12,忠孝健康7樓!G:G) -> 4 | K12: 0 | L12: 0 | M12: 0 | N12: 0 | O12: 0 | P12: 0 | Q12: 0 | R12: 0 | S12: 0 | T12: 0 | U12: 0 | V12: 0 | W12: 0 | X12: 0 | Y12: 0 | Z12: 0 | AA12: 0 | AB12: 0 | AC12: 0 | AD12: 0 | AE12: 0 | AF12: 0 | AG12: 0 | AH12: 0 | AI12: 32 | AJ12: 1.2 | AK12: 2.2 | AL12: 2.2 | AM12: 1.6 | AN12: 3.4 | AO12: 2.2 | AP12: 0.4 | AQ12: 0.6 | AR12: 0.4 | AS12: 0.2 | AT12: 0.4 | AU12: 28 | AV12: =SUM(AJ12:AU12) -> 42.8 | AW12: =AV12/12 -> 3.5666667 | AX12: 0 | AY12: 8 | AZ12: 0 | BA12: 0 | BB12: 0 | BC12: =SUMIFS(領用表!$L:$L,領用表!$A:$A,BC$2,領用表!$E:$E,B12) -> 12 | BD12: =SUMIFS(領用表!$L:$L,領用表!$E:$E,$B12,領用表!$B:$B,BC$2&BD$2) -> 12 | BE12: =SUMIFS(領用表!$L:$L,領用表!$E:$E,$B12,領用表!$B:$B,$BC$2&BE$2) -> 0 | BF12: =SUMIFS(領用表!$L:$L,領用表!$E:$E,$B12,領用表!$B:$B,$BC$2&BF$2) -> 0 | BG12: =SUMIFS(領用表!$L:$L,領用表!$E:$E,$B12,領用表!$B:$B,$BC$2&BG$2) -> 0 | BH12: =SUMIFS(領用表!$L:$L,領用表!$A:$A,BH$2,領用表!$E:$E,B12) -> 4 | BI12: =SUMIFS(領用表!$L:$L,領用表!$E:$E,$B12,領用表!$B:$B,BH$2&BI$2) -> 4 | BJ12: =SUMIFS(領用表!$L:$L,領用表!$E:$E,$B12,領用表!$B:$B,$BH$2&BJ$2) -> 0 | BK12: =SUMIFS(領用表!$L:$L,領用表!$E:$E,$B12,領用表!$B:$B,$BH$2&BK$2) -> 0 | BL12: =SUMIFS(領用表!$L:$L,領用表!$E:$E,$B12,領用表!$B:$B,$BH$2&BL$2) -> 0 | BM12: =SUMIFS(領用表!$L:$L,領用表!$A:$A,BM$2,領用表!$E:$E,B12) -> 0 | BN12: =SUMIFS(領用表!$L:$L,領用表!$E:$E,$B12,領用表!$B:$B,BM$2&BN$2) -> 0 | BO12: =SUMIFS(領用表!$L:$L,領用表!$E:$E,$B12,領用表!$B:$B,$BM$2&BO$2) -> 0 | BP12: =SUMIFS(領用表!$L:$L,領用表!$E:$E,$B12,領用表!$B:$B,$BM$2&BP$2) -> 0 | BQ12: =SUMIFS(領用表!$L:$L,領用表!$E:$E,$B12,領用表!$B:$B,$BM$2&BQ$2) -> 0 | BR12: =SUMIFS(領用表!$L:$L,領用表!$A:$A,BR$2,領用表!$E:$E,B12) -> 0 | BS12: =SUMIFS(領用表!$L:$L,領用表!$E:$E,$B12,領用表!$B:$B,BR$2&BS$2) -> 0 | BT12: =SUMIFS(領用表!$L:$L,領用表!$E:$E,$B12,領用表!$B:$B,$BR$2&BT$2) -> 0 | BU12: =SUMIFS(領用表!$L:$L,領用表!$E:$E,$B12,領用表!$B:$B,$BR$2&BU$2) -> 0 | BV12: =SUMIFS(領用表!$L:$L,領用表!$E:$E,$B12,領用表!$B:$B,$BR$2&BV$2) -> 0 | BW12: =SUMIFS(領用表!$L:$L,領用表!$A:$A,BW$2,領用表!$E:$E,B12) -> 8 | BX12: =SUMIFS(領用表!$L:$L,領用表!$E:$E,$B12,領用表!$B:$B,BW$2&BX$2) -> 8 | BY12: =SUMIFS(領用表!$L:$L,領用表!$E:$E,$B12,領用表!$B:$B,$BW$2&BY$2) -> 0 | BZ12: =SUMIFS(領用表!$L:$L,領用表!$E:$E,$B12,領用表!$B:$B,$BW$2&BZ$2) -> 0 | CA12: =SUMIFS(領用表!$L:$L,領用表!$E:$E,$B12,領用表!$B:$B,$BW$2&CA$2) -> 0 | CB12: =SUMIFS(領用表!$L:$L,領用表!$A:$A,CB$2,領用表!$E:$E,B12) -> 16 | CC12: =SUMIFS(領用表!$L:$L,領用表!$E:$E,$B12,領用表!$B:$B,CB$2&CC$2) -> 0 | CD12: =SUMIFS(領用表!$L:$L,領用表!$E:$E,$B12,領用表!$B:$B,$CB$2&CD$2) -> 0 | CE12: =SUMIFS(領用表!$L:$L,領用表!$E:$E,$B12,領用表!$B:$B,$CB$2&CE$2) -> 16 | CF12: =SUMIFS(領用表!$L:$L,領用表!$E:$E,$B12,領用表!$B:$B,$CB$2&CF$2) -> 0 | CG12: =SUMIFS(領用表!$L:$L,領用表!$A:$A,CG$2,領用表!$E:$E,B12) -> 28 | CH12: =SUMIFS(領用表!$L:$L,領用表!$E:$E,$B12,領用表!$B:$B,CG$2&CH$2) -> 8 | CI12: =SUMIFS(領用表!$L:$L,領用表!$E:$E,$B12,領用表!$B:$B,CG$2&CI$2) -> 0 | CJ12: =SUMIFS(領用表!$L:$L,領用表!$E:$E,$B12,領用表!$B:$B,CG$2&CJ$2) -> 20 | CK12: =SUMIFS(領用表!$L:$L,領用表!$E:$E,$B12,領用表!$B:$B,$CG$2&CK$2) -> 0 | CL12: =SUM(AX12,AY12,AZ12,BA12,BB12,BC12,BH12,BM12,BR12,BW12,CB12,CG12) -> 76 | CM12: =AVERAGE(AX12,AY12,AZ12,BA12,BB12,BC12,BH12,BM12,BR12,BW12,CB12,CG12) -> 6.3333333 | CN12: =SUMIFS(領用表!$L:$L,領用表!$A:$A,CN$2,領用表!$E:$E,B12) -> 0 | CO12: =SUMIFS(領用表!$L:$L,領用表!$E:$E,$B12,領用表!$B:$B,CN$2&CO$2) -> 0 | CP12: =SUMIFS(領用表!$L:$L,領用表!$E:$E,$B12,領用表!$B:$B,$CN$2&CP$2) -> 0 | CQ12: =SUMIFS(領用表!$L:$L,領用表!$E:$E,$B12,領用表!$B:$B,$CN$2&CQ$2) -> 0 | CR12: =SUMIFS(領用表!$L:$L,領用表!$E:$E,$B12,領用表!$B:$B,$CN$2&CR$2) -> 0 | CS12: =SUMIFS(領用表!$L:$L,領用表!$A:$A,CS$2,領用表!$E:$E,B12) -> 24 | CT12: =SUMIFS(領用表!$L:$L,領用表!$E:$E,$B12,領用表!$B:$B,CS$2&CT$2) -> 12 | CU12: =SUMIFS(領用表!$L:$L,領用表!$E:$E,$B12,領用表!$B:$B,$CS$2&CU$2) -> 0 | CV12: =SUMIFS(領用表!$L:$L,領用表!$E:$E,$B12,領用表!$B:$B,$CS$2&CV$2) -> 12 | CW12: =SUMIFS(領用表!$L:$L,領用表!$E:$E,$B12,領用表!$B:$B,$CS$2&CW$2) -> 0 | CX12: =SUMIFS(領用表!$L:$L,領用表!$E:$E,$B12,領用表!$B:$B,$CS$2&CX$2) -> 0 | CY12: =SUMIFS(領用表!$L:$L,領用表!$A:$A,CY$2,領用表!$E:$E,B12) -> 12 | CZ12: =SUMIFS(領用表!$L:$L,領用表!$E:$E,$B12,領用表!$B:$B,CY$2&CZ$2) -> 12 | DA12: =SUMIFS(領用表!$L:$L,領用表!$E:$E,$B12,領用表!$B:$B,$CY$2&DA$2) -> 0 | DB12: =SUMIFS(領用表!$L:$L,領用表!$E:$E,$B12,領用表!$B:$B,$CY$2&DB$2) -> 0 | DC12: =SUMIFS(領用表!$L:$L,領用表!$E:$E,$B12,領用表!$B:$B,$CY$2&DC$2) -> 0 | DD12: =SUMIFS(領用表!$L:$L,領用表!$E:$E,$B12,領用表!$B:$B,$CY$2&DD$2) -> 0 | DE12: =SUMIFS(領用表!$L:$L,領用表!$A:$A,DE$2,領用表!$E:$E,B12) -> 4 | DF12: =SUMIFS(領用表!$L:$L,領用表!$E:$E,$B12,領用表!$B:$B,DE$2&DF$2) -> 4 | DG12: =SUMIFS(領用表!$L:$L,領用表!$E:$E,$B12,領用表!$B:$B,$DE$2&DG$2) -> 0 | DH12: =SUMIFS(領用表!$L:$L,領用表!$E:$E,$B12,領用表!$B:$B,$DE$2&DH$2) -> 0 | DI12: =SUMIFS(領用表!$L:$L,領用表!$E:$E,$B12,領用表!$B:$B,$DE$2&DI$2) -> 0 | DJ12: =SUMIFS(領用表!$L:$L,領用表!$E:$E,$B12,領用表!$B:$B,$DE$2&DJ$2) -> 0 | DK12: =SUMIFS(領用表!$L:$L,領用表!$A:$A,DK$2,領用表!$E:$E,$B12) -> 16 | DL12: =SUMIFS(領用表!$L:$L,領用表!$E:$E,$B12,領用表!$B:$B,DK$2&DL$2) -> 16 | DM12: =SUMIFS(領用表!$L:$L,領用表!$E:$E,$B12,領用表!$B:$B,$DK$2&DM$2) -> 0 | DN12: =SUMIFS(領用表!$L:$L,領用表!$E:$E,$B12,領用表!$B:$B,$DK$2&DN$2) -> 0 | DO12: =SUMIFS(領用表!$L:$L,領用表!$E:$E,$B12,領用表!$B:$B,$DK$2&DO$2) -> 0 | DP12: =SUMIFS(領用表!$L:$L,領用表!$E:$E,$B12,領用表!$B:$B,$DK$2&DP$2) -> 0 | DQ12: =SUM(CN12,CS12,CY12,DE12,DK12) -> 56 | DR12: =AVERAGEA(CN12,CS12,CY12,DE12,DK12) -> 11.2 | DS12: =SUM(DT12:DW12) -> 14 | DT12: 4 | DU12: 0 | DV12: 10 | DW12: 0 | DX12: 20 | ED12: =IFERROR(VLOOKUP(A12,站前4樓!A:BF,57,0),0) -> 0 | EE12: =IFERROR(VLOOKUP(A12,站前11樓!A:BE,57,0),0) -> 0 | EF12: =IFERROR(VLOOKUP(A12,忠孝7樓!A:N,57,0),0) -> 0 | EG12: =IFERROR(VLOOKUP(A12,忠孝國際醫學3樓!A:L,57,0),0) -> 0 | EH12: =SUM(ED12:EG12) -> 0 | EJ12: 48 | EK12: 8
A13: MP1MA010013A | B13: 6180013 | C13: MINT秘特拉提線FIX 18CM(1支) | D13: 20 | E13: PCS | F13: =SUMIF(站前4樓!B:B,B13,站前4樓!F:F) -> 24 | G13: =SUMIF(站前11樓!B:B,B13,站前11樓!F:F) -> 0 | H13: =SUMIF(忠孝7樓!B:B,B13,忠孝7樓!G:G) -> 12 | I13: =SUMIF(忠孝國際醫學3樓!B:B,B13,忠孝國際醫學3樓!G:G) -> 0 | J13: =SUMIF(忠孝健康7樓!B:B,B13,忠孝健康7樓!G:G) -> 0 | K13: 0 | L13: 0 | M13: 0 | N13: 0 | O13: 0 | P13: 0 | Q13: 0 | R13: 0 | S13: 0 | T13: 0 | U13: 0 | V13: 0 | W13: 0 | X13: 0 | Y13: 0 | Z13: 0 | AA13: 0 | AB13: 0 | AC13: 0 | AD13: 0 | AE13: 0 | AF13: 0 | AG13: 0 | AH13: 0 | AI13: 0 | AJ13: 0 | AK13: 0 | AL13: 0 | AM13: 0.4 | AN13: 0 | AO13: 0.4 | AP13: 0.2 | AQ13: 0.8 | AR13: 0.2 | AS13: 0.6 | AT13: 0 | AU13: 0 | AV13: =SUM(AJ13:AU13) -> 2.6 | AW13: =AV13/12 -> 0.21666667 | AX13: 23 | AY13: 0 | AZ13: 0 | BA13: 0 | BB13: 8 | BC13: =SUMIFS(領用表!$L:$L,領用表!$A:$A,BC$2,領用表!$E:$E,B13) -> 4 | BD13: =SUMIFS(領用表!$L:$L,領用表!$E:$E,$B13,領用表!$B:$B,BC$2&BD$2) -> 4 | BE13: =SUMIFS(領用表!$L:$L,領用表!$E:$E,$B13,領用表!$B:$B,$BC$2&BE$2) -> 0 | BF13: =SUMIFS(領用表!$L:$L,領用表!$E:$E,$B13,領用表!$B:$B,$BC$2&BF$2) -> 0 | BG13: =SUMIFS(領用表!$L:$L,領用表!$E:$E,$B13,領用表!$B:$B,$BC$2&BG$2) -> 0 | BH13: =SUMIFS(領用表!$L:$L,領用表!$A:$A,BH$2,領用表!$E:$E,B13) -> 8 | BI13: =SUMIFS(領用表!$L:$L,領用表!$E:$E,$B13,領用表!$B:$B,BH$2&BI$2) -> 8 | BJ13: =SUMIFS(領用表!$L:$L,領用表!$E:$E,$B13,領用表!$B:$B,$BH$2&BJ$2) -> 0 | BK13: =SUMIFS(領用表!$L:$L,領用表!$E:$E,$B13,領用表!$B:$B,$BH$2&BK$2) -> 0 | BL13: =SUMIFS(領用表!$L:$L,領用表!$E:$E,$B13,領用表!$B:$B,$BH$2&BL$2) -> 0 | BM13: =SUMIFS(領用表!$L:$L,領用表!$A:$A,BM$2,領用表!$E:$E,B13) -> 0 | BN13: =SUMIFS(領用表!$L:$L,領用表!$E:$E,$B13,領用表!$B:$B,BM$2&BN$2) -> 0 | BO13: =SUMIFS(領用表!$L:$L,領用表!$E:$E,$B13,領用表!$B:$B,$BM$2&BO$2) -> 0 | BP13: =SUMIFS(領用表!$L:$L,領用表!$E:$E,$B13,領用表!$B:$B,$BM$2&BP$2) -> 0 | BQ13: =SUMIFS(領用表!$L:$L,領用表!$E:$E,$B13,領用表!$B:$B,$BM$2&BQ$2) -> 0 | BR13: =SUMIFS(領用表!$L:$L,領用表!$A:$A,BR$2,領用表!$E:$E,B13) -> 0 | BS13: =SUMIFS(領用表!$L:$L,領用表!$E:$E,$B13,領用表!$B:$B,BR$2&BS$2) -> 0 | BT13: =SUMIFS(領用表!$L:$L,領用表!$E:$E,$B13,領用表!$B:$B,$BR$2&BT$2) -> 0 | BU13: =SUMIFS(領用表!$L:$L,領用表!$E:$E,$B13,領用表!$B:$B,$BR$2&BU$2) -> 0 | BV13: =SUMIFS(領用表!$L:$L,領用表!$E:$E,$B13,領用表!$B:$B,$BR$2&BV$2) -> 0 | BW13: =SUMIFS(領用表!$L:$L,領用表!$A:$A,BW$2,領用表!$E:$E,B13) -> 8 | BX13: =SUMIFS(領用表!$L:$L,領用表!$E:$E,$B13,領用表!$B:$B,BW$2&BX$2) -> 0 | BY13: =SUMIFS(領用表!$L:$L,領用表!$E:$E,$B13,領用表!$B:$B,$BW$2&BY$2) -> 0 | BZ13: =SUMIFS(領用表!$L:$L,領用表!$E:$E,$B13,領用表!$B:$B,$BW$2&BZ$2) -> 8 | CA13: =SUMIFS(領用表!$L:$L,領用表!$E:$E,$B13,領用表!$B:$B,$BW$2&CA$2) -> 0 | CB13: =SUMIFS(領用表!$L:$L,領用表!$A:$A,CB$2,領用表!$E:$E,B13) -> 8 | CC13: =SUMIFS(領用表!$L:$L,領用表!$E:$E,$B13,領用表!$B:$B,CB$2&CC$2) -> 0 | CD13: =SUMIFS(領用表!$L:$L,領用表!$E:$E,$B13,領用表!$B:$B,$CB$2&CD$2) -> 0 | CE13: =SUMIFS(領用表!$L:$L,領用表!$E:$E,$B13,領用表!$B:$B,$CB$2&CE$2) -> 8 | CF13: =SUMIFS(領用表!$L:$L,領用表!$E:$E,$B13,領用表!$B:$B,$CB$2&CF$2) -> 0 | CG13: =SUMIFS(領用表!$L:$L,領用表!$A:$A,CG$2,領用表!$E:$E,B13) -> 4 | CH13: =SUMIFS(領用表!$L:$L,領用表!$E:$E,$B13,領用表!$B:$B,CG$2&CH$2) -> 0 | CI13: =SUMIFS(領用表!$L:$L,領用表!$E:$E,$B13,領用表!$B:$B,CG$2&CI$2) -> 0 | CJ13: =SUMIFS(領用表!$L:$L,領用表!$E:$E,$B13,領用表!$B:$B,CG$2&CJ$2) -> 4 | CK13: =SUMIFS(領用表!$L:$L,領用表!$E:$E,$B13,領用表!$B:$B,$CG$2&CK$2) -> 0 | CL13: =SUM(AX13,AY13,AZ13,BA13,BB13,BC13,BH13,BM13,BR13,BW13,CB13,CG13) -> 63 | CM13: =AVERAGE(AX13,AY13,AZ13,BA13,BB13,BC13,BH13,BM13,BR13,BW13,CB13,CG13) -> 5.25 | CN13: =SUMIFS(領用表!$L:$L,領用表!$A:$A,CN$2,領用表!$E:$E,B13) -> 4 | CO13: =SUMIFS(領用表!$L:$L,領用表!$E:$E,$B13,領用表!$B:$B,CN$2&CO$2) -> 0 | CP13: =SUMIFS(領用表!$L:$L,領用表!$E:$E,$B13,領用表!$B:$B,$CN$2&CP$2) -> 0 | CQ13: =SUMIFS(領用表!$L:$L,領用表!$E:$E,$B13,領用表!$B:$B,$CN$2&CQ$2) -> 4 | CR13: =SUMIFS(領用表!$L:$L,領用表!$E:$E,$B13,領用表!$B:$B,$CN$2&CR$2) -> 0 | CS13: =SUMIFS(領用表!$L:$L,領用表!$A:$A,CS$2,領用表!$E:$E,B13) -> 0 | CT13: =SUMIFS(領用表!$L:$L,領用表!$E:$E,$B13,領用表!$B:$B,CS$2&CT$2) -> 0 | CU13: =SUMIFS(領用表!$L:$L,領用表!$E:$E,$B13,領用表!$B:$B,$CS$2&CU$2) -> 0 | CV13: =SUMIFS(領用表!$L:$L,領用表!$E:$E,$B13,領用表!$B:$B,$CS$2&CV$2) -> 0 | CW13: =SUMIFS(領用表!$L:$L,領用表!$E:$E,$B13,領用表!$B:$B,$CS$2&CW$2) -> 0 | CX13: =SUMIFS(領用表!$L:$L,領用表!$E:$E,$B13,領用表!$B:$B,$CS$2&CX$2) -> 0 | CY13: =SUMIFS(領用表!$L:$L,領用表!$A:$A,CY$2,領用表!$E:$E,B13) -> 12 | CZ13: =SUMIFS(領用表!$L:$L,領用表!$E:$E,$B13,領用表!$B:$B,CY$2&CZ$2) -> 0 | DA13: =SUMIFS(領用表!$L:$L,領用表!$E:$E,$B13,領用表!$B:$B,$CY$2&DA$2) -> 0 | DB13: =SUMIFS(領用表!$L:$L,領用表!$E:$E,$B13,領用表!$B:$B,$CY$2&DB$2) -> 0 | DC13: =SUMIFS(領用表!$L:$L,領用表!$E:$E,$B13,領用表!$B:$B,$CY$2&DC$2) -> 0 | DD13: =SUMIFS(領用表!$L:$L,領用表!$E:$E,$B13,領用表!$B:$B,$CY$2&DD$2) -> 12 | DE13: =SUMIFS(領用表!$L:$L,領用表!$A:$A,DE$2,領用表!$E:$E,B13) -> 8 | DF13: =SUMIFS(領用表!$L:$L,領用表!$E:$E,$B13,領用表!$B:$B,DE$2&DF$2) -> 0 | DG13: =SUMIFS(領用表!$L:$L,領用表!$E:$E,$B13,領用表!$B:$B,$DE$2&DG$2) -> 0 | DH13: =SUMIFS(領用表!$L:$L,領用表!$E:$E,$B13,領用表!$B:$B,$DE$2&DH$2) -> 8 | DI13: =SUMIFS(領用表!$L:$L,領用表!$E:$E,$B13,領用表!$B:$B,$DE$2&DI$2) -> 0 | DJ13: =SUMIFS(領用表!$L:$L,領用表!$E:$E,$B13,領用表!$B:$B,$DE$2&DJ$2) -> 0 | DK13: =SUMIFS(領用表!$L:$L,領用表!$A:$A,DK$2,領用表!$E:$E,$B13) -> 4 | DL13: =SUMIFS(領用表!$L:$L,領用表!$E:$E,$B13,領用表!$B:$B,DK$2&DL$2) -> 4 | DM13: =SUMIFS(領用表!$L:$L,領用表!$E:$E,$B13,領用表!$B:$B,$DK$2&DM$2) -> 0 | DN13: =SUMIFS(領用表!$L:$L,領用表!$E:$E,$B13,領用表!$B:$B,$DK$2&DN$2) -> 0 | DO13: =SUMIFS(領用表!$L:$L,領用表!$E:$E,$B13,領用表!$B:$B,$DK$2&DO$2) -> 0 | DP13: =SUMIFS(領用表!$L:$L,領用表!$E:$E,$B13,領用表!$B:$B,$DK$2&DP$2) -> 0 | DQ13: =SUM(CN13,CS13,CY13,DE13,DK13) -> 28 | DR13: =AVERAGEA(CN13,CS13,CY13,DE13,DK13) -> 5.6 | DS13: =SUM(DT13:DW13) -> 6 | DT13: 1 | DU13: 0 | DV13: 5 | DW13: 0 | DX13: 20 | ED13: =IFERROR(VLOOKUP(A13,站前4樓!A:BF,57,0),0) -> 0 | EE13: =IFERROR(VLOOKUP(A13,站前11樓!A:BE,57,0),0) -> 0 | EF13: =IFERROR(VLOOKUP(A13,忠孝7樓!A:N,57,0),0) -> 0 | EG13: =IFERROR(VLOOKUP(A13,忠孝國際醫學3樓!A:L,57,0),0) -> 0 | EH13: =SUM(ED13:EG13) -> 0 | EJ13: 40 | EK13: 24
A14: MP1MA010014A | B14: 6180007 | C14: MINT秘特拉提線PETIT 15CM(1支) | D14: 20 | E14: PCS | F14: =SUMIF(站前4樓!B:B,B14,站前4樓!F:F) -> 0 | G14: =SUMIF(站前11樓!B:B,B14,站前11樓!F:F) -> 0 | H14: =SUMIF(忠孝7樓!B:B,B14,忠孝7樓!G:G) -> 16 | I14: =SUMIF(忠孝國際醫學3樓!B:B,B14,忠孝國際醫學3樓!G:G) -> 0 | J14: =SUMIF(忠孝健康7樓!B:B,B14,忠孝健康7樓!G:G) -> 8 | K14: 0 | L14: 0 | M14: 0 | N14: 0 | O14: 0 | P14: 0 | Q14: 0 | R14: 0 | S14: 0 | T14: 0 | U14: 0 | V14: 0 | W14: 0 | X14: 0 | Y14: 0 | Z14: 0 | AA14: 0 | AB14: 0 | AC14: 0 | AD14: 0 | AE14: 0 | AF14: 0 | AG14: 0 | AH14: 0 | AI14: 0 | AJ14: 0 | AK14: 0 | AL14: 1 | AM14: 1.8 | AN14: 1.2 | AO14: 1.6 | AP14: 0.6 | AQ14: 2.2 | AR14: 0.8 | AS14: 1.2 | AT14: 0.6 | AU14: 24 | AV14: =SUM(AJ14:AU14) -> 35 | AW14: =AV14/12 -> 2.9166667 | AX14: 56 | AY14: 16 | AZ14: 0 | BA14: 0 | BB14: 4 | BC14: =SUMIFS(領用表!$L:$L,領用表!$A:$A,BC$2,領用表!$E:$E,B14) -> 16 | BD14: =SUMIFS(領用表!$L:$L,領用表!$E:$E,$B14,領用表!$B:$B,BC$2&BD$2) -> 16 | BE14: =SUMIFS(領用表!$L:$L,領用表!$E:$E,$B14,領用表!$B:$B,$BC$2&BE$2) -> 0 | BF14: =SUMIFS(領用表!$L:$L,領用表!$E:$E,$B14,領用表!$B:$B,$BC$2&BF$2) -> 0 | BG14: =SUMIFS(領用表!$L:$L,領用表!$E:$E,$B14,領用表!$B:$B,$BC$2&BG$2) -> 0 | BH14: =SUMIFS(領用表!$L:$L,領用表!$A:$A,BH$2,領用表!$E:$E,B14) -> 4 | BI14: =SUMIFS(領用表!$L:$L,領用表!$E:$E,$B14,領用表!$B:$B,BH$2&BI$2) -> 4 | BJ14: =SUMIFS(領用表!$L:$L,領用表!$E:$E,$B14,領用表!$B:$B,$BH$2&BJ$2) -> 0 | BK14: =SUMIFS(領用表!$L:$L,領用表!$E:$E,$B14,領用表!$B:$B,$BH$2&BK$2) -> 0 | BL14: =SUMIFS(領用表!$L:$L,領用表!$E:$E,$B14,領用表!$B:$B,$BH$2&BL$2) -> 0 | BM14: =SUMIFS(領用表!$L:$L,領用表!$A:$A,BM$2,領用表!$E:$E,B14) -> 4 | BN14: =SUMIFS(領用表!$L:$L,領用表!$E:$E,$B14,領用表!$B:$B,BM$2&BN$2) -> 0 | BO14: =SUMIFS(領用表!$L:$L,領用表!$E:$E,$B14,領用表!$B:$B,$BM$2&BO$2) -> 0 | BP14: =SUMIFS(領用表!$L:$L,領用表!$E:$E,$B14,領用表!$B:$B,$BM$2&BP$2) -> 4 | BQ14: =SUMIFS(領用表!$L:$L,領用表!$E:$E,$B14,領用表!$B:$B,$BM$2&BQ$2) -> 0 | BR14: =SUMIFS(領用表!$L:$L,領用表!$A:$A,BR$2,領用表!$E:$E,B14) -> 0 | BS14: =SUMIFS(領用表!$L:$L,領用表!$E:$E,$B14,領用表!$B:$B,BR$2&BS$2) -> 0 | BT14: =SUMIFS(領用表!$L:$L,領用表!$E:$E,$B14,領用表!$B:$B,$BR$2&BT$2) -> 0 | BU14: =SUMIFS(領用表!$L:$L,領用表!$E:$E,$B14,領用表!$B:$B,$BR$2&BU$2) -> 0 | BV14: =SUMIFS(領用表!$L:$L,領用表!$E:$E,$B14,領用表!$B:$B,$BR$2&BV$2) -> 0 | BW14: =SUMIFS(領用表!$L:$L,領用表!$A:$A,BW$2,領用表!$E:$E,B14) -> 4 | BX14: =SUMIFS(領用表!$L:$L,領用表!$E:$E,$B14,領用表!$B:$B,BW$2&BX$2) -> 0 | BY14: =SUMIFS(領用表!$L:$L,領用表!$E:$E,$B14,領用表!$B:$B,$BW$2&BY$2) -> 0 | BZ14: =SUMIFS(領用表!$L:$L,領用表!$E:$E,$B14,領用表!$B:$B,$BW$2&BZ$2) -> 4 | CA14: =SUMIFS(領用表!$L:$L,領用表!$E:$E,$B14,領用表!$B:$B,$BW$2&CA$2) -> 0 | CB14: =SUMIFS(領用表!$L:$L,領用表!$A:$A,CB$2,領用表!$E:$E,B14) -> 24 | CC14: =SUMIFS(領用表!$L:$L,領用表!$E:$E,$B14,領用表!$B:$B,CB$2&CC$2) -> 0 | CD14: =SUMIFS(領用表!$L:$L,領用表!$E:$E,$B14,領用表!$B:$B,$CB$2&CD$2) -> 0 | CE14: =SUMIFS(領用表!$L:$L,領用表!$E:$E,$B14,領用表!$B:$B,$CB$2&CE$2) -> 24 | CF14: =SUMIFS(領用表!$L:$L,領用表!$E:$E,$B14,領用表!$B:$B,$CB$2&CF$2) -> 0 | CG14: =SUMIFS(領用表!$L:$L,領用表!$A:$A,CG$2,領用表!$E:$E,B14) -> 44 | CH14: =SUMIFS(領用表!$L:$L,領用表!$E:$E,$B14,領用表!$B:$B,CG$2&CH$2) -> 4 | CI14: =SUMIFS(領用表!$L:$L,領用表!$E:$E,$B14,領用表!$B:$B,CG$2&CI$2) -> 0 | CJ14: =SUMIFS(領用表!$L:$L,領用表!$E:$E,$B14,領用表!$B:$B,CG$2&CJ$2) -> 40 | CK14: =SUMIFS(領用表!$L:$L,領用表!$E:$E,$B14,領用表!$B:$B,$CG$2&CK$2) -> 0 | CL14: =SUM(AX14,AY14,AZ14,BA14,BB14,BC14,BH14,BM14,BR14,BW14,CB14,CG14) -> 172 | CM14: =AVERAGE(AX14,AY14,AZ14,BA14,BB14,BC14,BH14,BM14,BR14,BW14,CB14,CG14) -> 14.333333 | CN14: =SUMIFS(領用表!$L:$L,領用表!$A:$A,CN$2,領用表!$E:$E,B14) -> 8 | CO14: =SUMIFS(領用表!$L:$L,領用表!$E:$E,$B14,領用表!$B:$B,CN$2&CO$2) -> 0 | CP14: =SUMIFS(領用表!$L:$L,領用表!$E:$E,$B14,領用表!$B:$B,$CN$2&CP$2) -> 0 | CQ14: =SUMIFS(領用表!$L:$L,領用表!$E:$E,$B14,領用表!$B:$B,$CN$2&CQ$2) -> 8 | CR14: =SUMIFS(領用表!$L:$L,領用表!$E:$E,$B14,領用表!$B:$B,$CN$2&CR$2) -> 0 | CS14: =SUMIFS(領用表!$L:$L,領用表!$A:$A,CS$2,領用表!$E:$E,B14) -> 16 | CT14: =SUMIFS(領用表!$L:$L,領用表!$E:$E,$B14,領用表!$B:$B,CS$2&CT$2) -> 0 | CU14: =SUMIFS(領用表!$L:$L,領用表!$E:$E,$B14,領用表!$B:$B,$CS$2&CU$2) -> 0 | CV14: =SUMIFS(領用表!$L:$L,領用表!$E:$E,$B14,領用表!$B:$B,$CS$2&CV$2) -> 16 | CW14: =SUMIFS(領用表!$L:$L,領用表!$E:$E,$B14,領用表!$B:$B,$CS$2&CW$2) -> 0 | CX14: =SUMIFS(領用表!$L:$L,領用表!$E:$E,$B14,領用表!$B:$B,$CS$2&CX$2) -> 0 | CY14: =SUMIFS(領用表!$L:$L,領用表!$A:$A,CY$2,領用表!$E:$E,B14) -> 16 | CZ14: =SUMIFS(領用表!$L:$L,領用表!$E:$E,$B14,領用表!$B:$B,CY$2&CZ$2) -> 0 | DA14: =SUMIFS(領用表!$L:$L,領用表!$E:$E,$B14,領用表!$B:$B,$CY$2&DA$2) -> 0 | DB14: =SUMIFS(領用表!$L:$L,領用表!$E:$E,$B14,領用表!$B:$B,$CY$2&DB$2) -> 8 | DC14: =SUMIFS(領用表!$L:$L,領用表!$E:$E,$B14,領用表!$B:$B,$CY$2&DC$2) -> 0 | DD14: =SUMIFS(領用表!$L:$L,領用表!$E:$E,$B14,領用表!$B:$B,$CY$2&DD$2) -> 8 | DE14: =SUMIFS(領用表!$L:$L,領用表!$A:$A,DE$2,領用表!$E:$E,B14) -> 0 | DF14: =SUMIFS(領用表!$L:$L,領用表!$E:$E,$B14,領用表!$B:$B,DE$2&DF$2) -> 0 | DG14: =SUMIFS(領用表!$L:$L,領用表!$E:$E,$B14,領用表!$B:$B,$DE$2&DG$2) -> 0 | DH14: =SUMIFS(領用表!$L:$L,領用表!$E:$E,$B14,領用表!$B:$B,$DE$2&DH$2) -> 0 | DI14: =SUMIFS(領用表!$L:$L,領用表!$E:$E,$B14,領用表!$B:$B,$DE$2&DI$2) -> 0 | DJ14: =SUMIFS(領用表!$L:$L,領用表!$E:$E,$B14,領用表!$B:$B,$DE$2&DJ$2) -> 0 | DK14: =SUMIFS(領用表!$L:$L,領用表!$A:$A,DK$2,領用表!$E:$E,$B14) -> 12 | DL14: =SUMIFS(領用表!$L:$L,領用表!$E:$E,$B14,領用表!$B:$B,DK$2&DL$2) -> 8 | DM14: =SUMIFS(領用表!$L:$L,領用表!$E:$E,$B14,領用表!$B:$B,$DK$2&DM$2) -> 0 | DN14: =SUMIFS(領用表!$L:$L,領用表!$E:$E,$B14,領用表!$B:$B,$DK$2&DN$2) -> 4 | DO14: =SUMIFS(領用表!$L:$L,領用表!$E:$E,$B14,領用表!$B:$B,$DK$2&DO$2) -> 0 | DP14: =SUMIFS(領用表!$L:$L,領用表!$E:$E,$B14,領用表!$B:$B,$DK$2&DP$2) -> 0 | DQ14: =SUM(CN14,CS14,CY14,DE14,DK14) -> 52 | DR14: =AVERAGEA(CN14,CS14,CY14,DE14,DK14) -> 10.4 | DS14: =SUM(DT14:DW14) -> 16 | DT14: 4 | DU14: 0 | DV14: 12 | DW14: 0 | DX14: 20 | ED14: =IFERROR(VLOOKUP(A14,站前4樓!A:BF,57,0),0) -> 0 | EE14: =IFERROR(VLOOKUP(A14,站前11樓!A:BE,57,0),0) -> 0 | EF14: =IFERROR(VLOOKUP(A14,忠孝7樓!A:N,57,0),0) -> 0 | EG14: =IFERROR(VLOOKUP(A14,忠孝國際醫學3樓!A:L,57,0),0) -> 0 | EH14: =SUM(ED14:EG14) -> 0 | EJ14: 8 | EK14: 32
