Workbook

Sheet Summary
A1: *自2025/1起調整為最小單位(發/點/支) | BA1: Actual:填入買賣大表"耗療數量"
A2: 料件編號 新 | B2: 凱惠料號 | C2: 品名 | D2: 盒入數 | E2: 庫存 單位 | F2: 46181 | K2: 44531 | L2: 44562 | M2: 44593 | N2: 44621 | O2: 44652 | P2: 44682 | Q2: 44713 | R2: 44743 | S2: 44774 | T2: 44805 | U2: 44835 | V2: 44866 | W2: 44896 | X2: 44927 | Y2: 44958 | Z2: 44986 | AA2: 45017 | AB2: 45047 | AC2: 45078 | AD2: 45108 | AE2: 45139 | AF2: 45170 | AG2: 45200 | AH2: 45231 | AI2: 45261 | AJ2: 45292 | AK2: 45323 | AL2: 45352 | AM2: 45383 | AN2: 45413 | AO2: 45444 | AP2: 45474 | AQ2: 45505 | AR2: 45536 | AS2: 45566 | AT2: 45597 | AU2: 45627 | AV2: 2024 總銷量 (盒裝) | AW2: 2024 月均銷 (盒裝) | AX2: 45658 | AY2: 45689 | AZ2: 45717 | BA2: 45748 | BB2: 45778 | BC2: 2025/06 | BD2: 站前4樓 | BE2: 站前11樓 | BF2: 忠孝7樓 | BG2: 忠孝國際醫學3樓 | BH2: 2025/07 | BI2: 站前4樓 | BJ2: 站前11樓 | BK2: 忠孝7樓 | BL2: 忠孝國際醫學3樓 | BM2: 2025/08 | BN2: 站前4樓 | BO2: 站前11樓 | BP2: 忠孝7樓 | BQ2: 忠孝國際醫學3樓 | BR2: 2025/09 | BS2: 站前4樓 | BT2: 站前11樓 | BU2: 忠孝7樓 | BV2: 忠孝國際醫學3樓 | BW2: 2025/10 | BX2: 站前4樓 | BY2: 站前11樓 | BZ2: 忠孝7樓 | CA2: 忠孝國際醫學3樓 | CB2: 2025/11 | CC2: 站前4樓 | CD2: 站前11樓 | CE2: 忠孝7樓 | CF2: 忠孝國際醫學3樓 | CG2: 2025/12 | CH2: 站前4樓 | CI2: 站前11樓 | CJ2: 忠孝7樓 | CK2: 忠孝國際醫學3樓 | CL2: 2025 總銷量 (單支/條/點) | CM2: 2025 月均銷 (單支/條/點) | CN2: 2026/01 | CO2: 站前4樓 | CP2: 站前11樓 | CQ2: 忠孝7樓 | CR2: 忠孝國際醫學3樓 | CS2: 2026/02 | CT2: 站前4樓 | CU2: 站前11樓 | CV2: 忠孝7樓 | CW2: 忠孝國際醫學3樓 | CX2: 忠孝健康7樓 | CY2: 2026/03 | CZ2: 站前4樓 | DA2: 站前11樓 | DB2: 忠孝7樓 | DC2: 忠孝國際醫學3樓 | DD2: 忠孝健康7樓 | DE2: 2026/04 | DF2: 站前4樓 | DG2: 站前11樓 | DH2: 忠孝7樓 | DI2: 忠孝國際醫學3樓 | DJ2: 忠孝健康7樓 | DK2: 2026/05 | DL2: 站前4樓 | DM2: 站前11樓 | DN2: 忠孝7樓 | DO2: 忠孝國際醫學3樓 | DP2: 忠孝健康7樓 | DQ2: 2026/06 | DR2: 站前4樓 | DS2: 站前11樓 | DT2: 忠孝7樓 | DU2: 忠孝國際醫學3樓 | DV2: 忠孝健康7樓 | DW2: 2026 總銷量 (單支/條/點) | DX2: 2026 月均銷 (單支/條/點) | DY2: 2026/06 | DZ2: 站前4樓 | EA2: 站前11樓 | EB2: 忠孝7樓 | EC2: 忠孝國際醫學3樓 | ED2: 安庫 | EE2: 已簽約 寄庫數量 | EF2: 10/17在途 | EH2: 備註 | EJ2: 站前4樓 | EK2: 站前11樓 | EL2: 忠孝7樓 | EM2: 忠孝國際醫學3樓
F3: 站前4樓 庫存 | G3: 站前11樓 庫存 | H3: 忠孝7樓 庫存 | I3: 忠孝國際 醫學3樓 庫存 | J3: 忠孝健康7樓 庫存 | K3: Actual | L3: Actual | M3: Actual | N3: Actual | O3: Actual | P3: Actual | Q3: Actual | R3: Actual | S3: Actual | T3: Actual | U3: Actual | V3: Actual | W3: Actual | X3: Actual | Y3: Actual | Z3: Actual | AA3: Actual | AB3: Actual | AC3: Actual | AD3: Actual | AE3: Actual | AF3: Actual | AG3: Actual | AH3: Actual | AI3: Actual | AJ3: Actual | AK3: Actual | AL3: Actual | AM3: Actual | AN3: Actual | AO3: Actual | AP3: Actual | AQ3: Actual | AR3: Actual | AS3: Actual | AT3: Actual | AU3: Actual | AX3: Actual | AY3: Actual | AZ3: Actual | BA3: Actual | BB3: Actual | BC3: Actual | BD3: Actual | BE3: Actual | BF3: Actual | BG3: Actual | BH3: Actual | BI3: Actual | BJ3: Actual | BK3: Actual | BL3: Actual | BM3: Actual | BN3: Actual | BO3: Actual | BP3: Actual | BQ3: Actual | BR3: Actual | BS3: Actual | BT3: Actual | BU3: Actual | BV3: Actual | BW3: Actual | BX3: Actual | BY3: Actual | BZ3: Actual | CA3: Actual | CB3: Actual | CC3: Actual | CD3: Actual | CE3: Actual | CF3: Actual | CG3: Actual | CH3: Actual | CI3: Actual | CJ3: Actual | CK3: Actual | CN3: Actual | CO3: Actual | CP3: Actual | CQ3: Actual | CR3: Actual | CS3: Actual | CT3: Actual | CU3: Actual | CV3: Actual | CW3: Actual | CX3: Actual | CY3: Actual | CZ3: Actual | DA3: Actual | DB3: Actual | DC3: Actual | DD3: Actual | DE3: Actual | DF3: Actual | DG3: Actual | DH3: Actual | DI3: Actual | DJ3: Actual | DK3: Actual | DL3: Actual | DM3: Actual | DN3: Actual | DO3: Actual | DP3: Actual | DQ3: Actual | DR3: Actual | DS3: Actual | DT3: Actual | DU3: Actual | DV3: Actual | DY3: Forecast | DZ3: Forecast | EA3: Forecast | EB3: Forecast | EC3: Forecast | EF3: 站前診所 | EG3: 忠孝診所 | EJ3: Forecast | EK3: Forecast | EL3: Forecast | EM3: Forecast
A4: MP1MA020019A | B4: 6150001 | C4: 喬雅登豐麗緹玻尿酸植入物Voluma 1ml/ syringe(1支) | D4: 2 | E4: PCS | F4: =SUMIF(站前4樓!B:B,B4,站前4樓!F:F) | G4: =SUMIF(站前11樓!B:B,B4,站前11樓!F:F) | H4: =SUMIF(忠孝7樓!B:B,B4,忠孝7樓!G:G) | I4: =SUMIF(忠孝國際醫學3樓!B:B,B4,忠孝國際醫學3樓!G:G) | J4: =SUMIF(忠孝健康7樓!B:B,B4,忠孝健康7樓!G:G) | K4: 3 | L4: 3 | M4: 2 | N4: 5 | O4: 4 | P4: 6 | Q4: 0 | R4: 0 | S4: 14 | T4: 0 | U4: 6 | V4: 6 | W4: 20 | X4: 4 | Y4: 3 | Z4: 0 | AA4: 2 | AB4: 1 | AC4: 9 | AD4: 16 | AE4: 2 | AF4: 3 | AG4: 3 | AH4: 2 | AI4: 6 | AJ4: 7.5 | AK4: 6.5 | AL4: 11 | AM4: 11.5 | AN4: 11.5 | AO4: 21 | AP4: 9.5 | AQ4: 11 | AR4: 17 | AS4: 8.5 | AT4: 19.5 | AU4: 18 | AV4: =SUM(AJ4:AU4) | AW4: =AV4/12 | AX4: 64 | AY4: 29 | AZ4: 54 | BA4: 60 | BB4: 75 | BC4: =SUMIFS(領用表!$L:$L,領用表!$A:$A,BC$2,領用表!$E:$E,B4) | BD4: =SUMIFS(領用表!$L:$L,領用表!$E:$E,$B4,領用表!$B:$B,BC$2&BD$2) | BE4: =SUMIFS(領用表!$L:$L,領用表!$E:$E,$B4,領用表!$B:$B,$BC$2&BE$2) | BF4: =SUMIFS(領用表!$L:$L,領用表!$E:$E,$B4,領用表!$B:$B,$BC$2&BF$2) | BG4: =SUMIFS(領用表!$L:$L,領用表!$E:$E,$B4,領用表!$B:$B,$BC$2&BG$2) | BH4: =SUMIFS(領用表!$L:$L,領用表!$A:$A,BH$2,領用表!$E:$E,B4) | BI4: =SUMIFS(領用表!$L:$L,領用表!$E:$E,$B4,領用表!$B:$B,BH$2&BI$2) | BJ4: =SUMIFS(領用表!$L:$L,領用表!$E:$E,$B4,領用表!$B:$B,$BH$2&BJ$2) | BK4: =SUMIFS(領用表!$L:$L,領用表!$E:$E,$B4,領用表!$B:$B,$BH$2&BK$2) | BL4: =SUMIFS(領用表!$L:$L,領用表!$E:$E,$B4,領用表!$B:$B,$BH$2&BL$2) | BM4: =SUMIFS(領用表!$L:$L,領用表!$A:$A,BM$2,領用表!$E:$E,B4) | BN4: =SUMIFS(領用表!$L:$L,領用表!$E:$E,$B4,領用表!$B:$B,BM$2&BN$2) | BO4: =SUMIFS(領用表!$L:$L,領用表!$E:$E,$B4,領用表!$B:$B,$BM$2&BO$2) | BP4: =SUMIFS(領用表!$L:$L,領用表!$E:$E,$B4,領用表!$B:$B,$BM$2&BP$2) | BQ4: =SUMIFS(領用表!$L:$L,領用表!$E:$E,$B4,領用表!$B:$B,$BM$2&BQ$2) | BR4: =SUMIFS(領用表!$L:$L,領用表!$A:$A,BR$2,領用表!$E:$E,B4) | BS4: =SUMIFS(領用表!$L:$L,領用表!$E:$E,$B4,領用表!$B:$B,BR$2&BS$2) | BT4: =SUMIFS(領用表!$L:$L,領用表!$E:$E,$B4,領用表!$B:$B,$BR$2&BT$2) | BU4: =SUMIFS(領用表!$L:$L,領用表!$E:$E,$B4,領用表!$B:$B,$BR$2&BU$2) | BV4: =SUMIFS(領用表!$L:$L,領用表!$E:$E,$B4,領用表!$B:$B,$BR$2&BV$2) | BW4: =SUMIFS(領用表!$L:$L,領用表!$A:$A,BW$2,領用表!$E:$E,B4) | BX4: =SUMIFS(領用表!$L:$L,領用表!$E:$E,$B4,領用表!$B:$B,BW$2&BX$2) | BY4: =SUMIFS(領用表!$L:$L,領用表!$E:$E,$B4,領用表!$B:$B,$BW$2&BY$2) | BZ4: =SUMIFS(領用表!$L:$L,領用表!$E:$E,$B4,領用表!$B:$B,$BW$2&BZ$2) | CA4: =SUMIFS(領用表!$L:$L,領用表!$E:$E,$B4,領用表!$B:$B,$BW$2&CA$2) | CB4: =SUMIFS(領用表!$L:$L,領用表!$A:$A,CB$2,領用表!$E:$E,B4) | CC4: =SUMIFS(領用表!$L:$L,領用表!$E:$E,$B4,領用表!$B:$B,CB$2&CC$2) | CD4: =SUMIFS(領用表!$L:$L,領用表!$E:$E,$B4,領用表!$B:$B,$CB$2&CD$2) | CE4: =SUMIFS(領用表!$L:$L,領用表!$E:$E,$B4,領用表!$B:$B,$CB$2&CE$2) | CF4: =SUMIFS(領用表!$L:$L,領用表!$E:$E,$B4,領用表!$B:$B,$CB$2&CF$2) | CG4: =SUMIFS(領用表!$L:$L,領用表!$A:$A,CG$2,領用表!$E:$E,B4) | CH4: =SUMIFS(領用表!$L:$L,領用表!$E:$E,$B4,領用表!$B:$B,CG$2&CH$2) | CI4: =SUMIFS(領用表!$L:$L,領用表!$E:$E,$B4,領用表!$B:$B,CG$2&CI$2) | CJ4: =SUMIFS(領用表!$L:$L,領用表!$E:$E,$B4,領用表!$B:$B,CG$2&CJ$2) | CK4: =SUMIFS(領用表!$L:$L,領用表!$E:$E,$B4,領用表!$B:$B,$CG$2&CK$2) | CL4: =SUM(AX4,AY4,AZ4,BA4,BB4,BC4,BH4,BM4,BR4,BW4,CB4,CG4) | CM4: =AVERAGE(AX4,AY4,AZ4,BA4,BB4,BC4,BH4,BM4,BR4,BW4,CB4,CG4) | CN4: =SUMIFS(領用表!$L:$L,領用表!$A:$A,CN$2,領用表!$E:$E,B4) | CO4: =SUMIFS(領用表!$L:$L,領用表!$E:$E,$B4,領用表!$B:$B,CN$2&CO$2) | CP4: =SUMIFS(領用表!$L:$L,領用表!$E:$E,$B4,領用表!$B:$B,$CN$2&CP$2) | CQ4: =SUMIFS(領用表!$L:$L,領用表!$E:$E,$B4,領用表!$B:$B,$CN$2&CQ$2) | CR4: =SUMIFS(領用表!$L:$L,領用表!$E:$E,$B4,領用表!$B:$B,$CN$2&CR$2) | CS4: =SUMIFS(領用表!$L:$L,領用表!$A:$A,CS$2,領用表!$E:$E,B4) | CT4: =SUMIFS(領用表!$L:$L,領用表!$E:$E,$B4,領用表!$B:$B,CS$2&CT$2) | CU4: =SUMIFS(領用表!$L:$L,領用表!$E:$E,$B4,領用表!$B:$B,$CS$2&CU$2) | CV4: =SUMIFS(領用表!$L:$L,領用表!$E:$E,$B4,領用表!$B:$B,$CS$2&CV$2) | CW4: =SUMIFS(領用表!$L:$L,領用表!$E:$E,$B4,領用表!$B:$B,$CS$2&CW$2) | CX4: =SUMIFS(領用表!$L:$L,領用表!$E:$E,$B4,領用表!$B:$B,$CS$2&CX$2) | CY4: =SUMIFS(領用表!$L:$L,領用表!$A:$A,CY$2,領用表!$E:$E,B4) | CZ4: =SUMIFS(領用表!$L:$L,領用表!$E:$E,$B4,領用表!$B:$B,CY$2&CZ$2) | DA4: =SUMIFS(領用表!$L:$L,領用表!$E:$E,$B4,領用表!$B:$B,$CY$2&DA$2) | DB4: =SUMIFS(領用表!$L:$L,領用表!$E:$E,$B4,領用表!$B:$B,$CY$2&DB$2) | DC4: =SUMIFS(領用表!$L:$L,領用表!$E:$E,$B4,領用表!$B:$B,$CY$2&DC$2) | DD4: =SUMIFS(領用表!$L:$L,領用表!$E:$E,$B4,領用表!$B:$B,$CY$2&DD$2) | DE4: =SUMIFS(領用表!$L:$L,領用表!$A:$A,DE$2,領用表!$E:$E,B4) | DF4: =SUMIFS(領用表!$L:$L,領用表!$E:$E,$B4,領用表!$B:$B,DE$2&DF$2) | DG4: =SUMIFS(領用表!$L:$L,領用表!$E:$E,$B4,領用表!$B:$B,$DE$2&DG$2) | DH4: =SUMIFS(領用表!$L:$L,領用表!$E:$E,$B4,領用表!$B:$B,$DE$2&DH$2) | DI4: =SUMIFS(領用表!$L:$L,領用表!$E:$E,$B4,領用表!$B:$B,$DE$2&DI$2) | DJ4: =SUMIFS(領用表!$L:$L,領用表!$E:$E,$B4,領用表!$B:$B,$DE$2&DJ$2) | DK4: =SUMIFS(領用表!$L:$L,領用表!$A:$A,DK$2,領用表!$E:$E,$B4) | DL4: =SUMIFS(領用表!$L:$L,領用表!$E:$E,$B4,領用表!$B:$B,DK$2&DL$2) | DM4: =SUMIFS(領用表!$L:$L,領用表!$E:$E,$B4,領用表!$B:$B,$DK$2&DM$2) | DN4: =SUMIFS(領用表!$L:$L,領用表!$E:$E,$B4,領用表!$B:$B,$DK$2&DN$2) | DO4: =SUMIFS(領用表!$L:$L,領用表!$E:$E,$B4,領用表!$B:$B,$DK$2&DO$2) | DP4: =SUMIFS(領用表!$L:$L,領用表!$E:$E,$B4,領用表!$B:$B,$DK$2&DP$2) | DQ4: 91 | DR4: 42 | DT4: 34 | DV4: 15 | DW4: =SUM(CN4,CS4,CY4,DE4,DK4,DQ4) | DX4: =AVERAGEA(CN4,CS4,CY4,DE4,DK4,DQ4) | DY4: =SUM(DZ4:EC4) | DZ4: 120 | EA4: 0 | EB4: 120 | EC4: 0 | ED4: 50 | EE4: 0 | EF4: 40盒(10/21) | EG4: 10盒(10/21) | EJ4: =IFERROR(VLOOKUP(A4,站前4樓!A:BF,57,0),0) | EK4: =IFERROR(VLOOKUP(A4,站前11樓!A:BE,57,0),0) | EL4: =IFERROR(VLOOKUP(A4,忠孝7樓!A:N,57,0),0) | EM4: =IFERROR(VLOOKUP(A4,忠孝國際醫學3樓!A:L,57,0),0) | EN4: =SUM(ED4:EG4) | EP4: 61 | EQ4: 85
A5: MP1MA020020A | B5: 6150002 | C5: 喬雅登夢蓓菈玻尿酸植入物Volbella 1ml/ syringe(1支) | D5: 2 | E5: PCS | F5: =SUMIF(站前4樓!B:B,B5,站前4樓!F:F) | G5: =SUMIF(站前11樓!B:B,B5,站前11樓!F:F) | H5: =SUMIF(忠孝7樓!B:B,B5,忠孝7樓!G:G) | I5: =SUMIF(忠孝國際醫學3樓!B:B,B5,忠孝國際醫學3樓!G:G) | J5: =SUMIF(忠孝健康7樓!B:B,B5,忠孝健康7樓!G:G) | K5: 0 | L5: 3 | M5: 0 | N5: 3 | O5: 0 | P5: 0 | Q5: 0 | R5: 0 | S5: 3 | T5: 0 | U5: 2 | V5: 0 | W5: 2 | X5: 5 | Y5: 0 | Z5: 0 | AA5: 0 | AB5: 1 | AC5: 0 | AD5: 4 | AE5: 0 | AF5: 1 | AG5: 1 | AH5: 3 | AI5: 19 | AJ5: 4.5 | AK5: 0.5 | AL5: 3.5 | AM5: 0.5 | AN5: 3 | AO5: 5.5 | AP5: 4.5 | AQ5: 3.5 | AR5: 1 | AS5: 1 | AT5: 3 | AU5: 6 | AV5: =SUM(AJ5:AU5) | AW5: =AV5/12 | AX5: 11 | AY5: 2 | AZ5: 1 | BA5: 9 | BB5: 3 | BC5: =SUMIFS(領用表!$L:$L,領用表!$A:$A,BC$2,領用表!$E:$E,B5) | BD5: =SUMIFS(領用表!$L:$L,領用表!$E:$E,$B5,領用表!$B:$B,BC$2&BD$2) | BE5: =SUMIFS(領用表!$L:$L,領用表!$E:$E,$B5,領用表!$B:$B,$BC$2&BE$2) | BF5: =SUMIFS(領用表!$L:$L,領用表!$E:$E,$B5,領用表!$B:$B,$BC$2&BF$2) | BG5: =SUMIFS(領用表!$L:$L,領用表!$E:$E,$B5,領用表!$B:$B,$BC$2&BG$2) | BH5: =SUMIFS(領用表!$L:$L,領用表!$A:$A,BH$2,領用表!$E:$E,B5) | BI5: =SUMIFS(領用表!$L:$L,領用表!$E:$E,$B5,領用表!$B:$B,BH$2&BI$2) | BJ5: =SUMIFS(領用表!$L:$L,領用表!$E:$E,$B5,領用表!$B:$B,$BH$2&BJ$2) | BK5: =SUMIFS(領用表!$L:$L,領用表!$E:$E,$B5,領用表!$B:$B,$BH$2&BK$2) | BL5: =SUMIFS(領用表!$L:$L,領用表!$E:$E,$B5,領用表!$B:$B,$BH$2&BL$2) | BM5: =SUMIFS(領用表!$L:$L,領用表!$A:$A,BM$2,領用表!$E:$E,B5) | BN5: =SUMIFS(領用表!$L:$L,領用表!$E:$E,$B5,領用表!$B:$B,BM$2&BN$2) | BO5: =SUMIFS(領用表!$L:$L,領用表!$E:$E,$B5,領用表!$B:$B,$BM$2&BO$2) | BP5: =SUMIFS(領用表!$L:$L,領用表!$E:$E,$B5,領用表!$B:$B,$BM$2&BP$2) | BQ5: =SUMIFS(領用表!$L:$L,領用表!$E:$E,$B5,領用表!$B:$B,$BM$2&BQ$2) | BR5: =SUMIFS(領用表!$L:$L,領用表!$A:$A,BR$2,領用表!$E:$E,B5) | BS5: =SUMIFS(領用表!$L:$L,領用表!$E:$E,$B5,領用表!$B:$B,BR$2&BS$2) | BT5: =SUMIFS(領用表!$L:$L,領用表!$E:$E,$B5,領用表!$B:$B,$BR$2&BT$2) | BU5: =SUMIFS(領用表!$L:$L,領用表!$E:$E,$B5,領用表!$B:$B,$BR$2&BU$2) | BV5: =SUMIFS(領用表!$L:$L,領用表!$E:$E,$B5,領用表!$B:$B,$BR$2&BV$2) | BW5: =SUMIFS(領用表!$L:$L,領用表!$A:$A,BW$2,領用表!$E:$E,B5) | BX5: =SUMIFS(領用表!$L:$L,領用表!$E:$E,$B5,領用表!$B:$B,BW$2&BX$2) | BY5: =SUMIFS(領用表!$L:$L,領用表!$E:$E,$B5,領用表!$B:$B,$BW$2&BY$2) | BZ5: =SUMIFS(領用表!$L:$L,領用表!$E:$E,$B5,領用表!$B:$B,$BW$2&BZ$2) | CA5: =SUMIFS(領用表!$L:$L,領用表!$E:$E,$B5,領用表!$B:$B,$BW$2&CA$2) | CB5: =SUMIFS(領用表!$L:$L,領用表!$A:$A,CB$2,領用表!$E:$E,B5) | CC5: =SUMIFS(領用表!$L:$L,領用表!$E:$E,$B5,領用表!$B:$B,CB$2&CC$2) | CD5: =SUMIFS(領用表!$L:$L,領用表!$E:$E,$B5,領用表!$B:$B,$CB$2&CD$2) | CE5: =SUMIFS(領用表!$L:$L,領用表!$E:$E,$B5,領用表!$B:$B,$CB$2&CE$2) | CF5: =SUMIFS(領用表!$L:$L,領用表!$E:$E,$B5,領用表!$B:$B,$CB$2&CF$2) | CG5: =SUMIFS(領用表!$L:$L,領用表!$A:$A,CG$2,領用表!$E:$E,B5) | CH5: =SUMIFS(領用表!$L:$L,領用表!$E:$E,$B5,領用表!$B:$B,CG$2&CH$2) | CI5: =SUMIFS(領用表!$L:$L,領用表!$E:$E,$B5,領用表!$B:$B,CG$2&CI$2) | CJ5: =SUMIFS(領用表!$L:$L,領用表!$E:$E,$B5,領用表!$B:$B,CG$2&CJ$2) | CK5: =SUMIFS(領用表!$L:$L,領用表!$E:$E,$B5,領用表!$B:$B,$CG$2&CK$2) | CL5: =SUM(AX5,AY5,AZ5,BA5,BB5,BC5,BH5,BM5,BR5,BW5,CB5,CG5) | CM5: =AVERAGE(AX5,AY5,AZ5,BA5,BB5,BC5,BH5,BM5,BR5,BW5,CB5,CG5) | CN5: =SUMIFS(領用表!$L:$L,領用表!$A:$A,CN$2,領用表!$E:$E,B5) | CO5: =SUMIFS(領用表!$L:$L,領用表!$E:$E,$B5,領用表!$B:$B,CN$2&CO$2) | CP5: =SUMIFS(領用表!$L:$L,領用表!$E:$E,$B5,領用表!$B:$B,$CN$2&CP$2) | CQ5: =SUMIFS(領用表!$L:$L,領用表!$E:$E,$B5,領用表!$B:$B,$CN$2&CQ$2) | CR5: =SUMIFS(領用表!$L:$L,領用表!$E:$E,$B5,領用表!$B:$B,$CN$2&CR$2) | CS5: =SUMIFS(領用表!$L:$L,領用表!$A:$A,CS$2,領用表!$E:$E,B5) | CT5: =SUMIFS(領用表!$L:$L,領用表!$E:$E,$B5,領用表!$B:$B,CS$2&CT$2) | CU5: =SUMIFS(領用表!$L:$L,領用表!$E:$E,$B5,領用表!$B:$B,$CS$2&CU$2) | CV5: =SUMIFS(領用表!$L:$L,領用表!$E:$E,$B5,領用表!$B:$B,$CS$2&CV$2) | CW5: =SUMIFS(領用表!$L:$L,領用表!$E:$E,$B5,領用表!$B:$B,$CS$2&CW$2) | CX5: =SUMIFS(領用表!$L:$L,領用表!$E:$E,$B5,領用表!$B:$B,$CS$2&CX$2) | CY5: =SUMIFS(領用表!$L:$L,領用表!$A:$A,CY$2,領用表!$E:$E,B5) | CZ5: =SUMIFS(領用表!$L:$L,領用表!$E:$E,$B5,領用表!$B:$B,CY$2&CZ$2) | DA5: =SUMIFS(領用表!$L:$L,領用表!$E:$E,$B5,領用表!$B:$B,$CY$2&DA$2) | DB5: =SUMIFS(領用表!$L:$L,領用表!$E:$E,$B5,領用表!$B:$B,$CY$2&DB$2) | DC5: =SUMIFS(領用表!$L:$L,領用表!$E:$E,$B5,領用表!$B:$B,$CY$2&DC$2) | DD5: =SUMIFS(領用表!$L:$L,領用表!$E:$E,$B5,領用表!$B:$B,$CY$2&DD$2) | DE5: =SUMIFS(領用表!$L:$L,領用表!$A:$A,DE$2,領用表!$E:$E,B5) | DF5: =SUMIFS(領用表!$L:$L,領用表!$E:$E,$B5,領用表!$B:$B,DE$2&DF$2) | DG5: =SUMIFS(領用表!$L:$L,領用表!$E:$E,$B5,領用表!$B:$B,$DE$2&DG$2) | DH5: =SUMIFS(領用表!$L:$L,領用表!$E:$E,$B5,領用表!$B:$B,$DE$2&DH$2) | DI5: =SUMIFS(領用表!$L:$L,領用表!$E:$E,$B5,領用表!$B:$B,$DE$2&DI$2) | DJ5: =SUMIFS(領用表!$L:$L,領用表!$E:$E,$B5,領用表!$B:$B,$DE$2&DJ$2) | DK5: =SUMIFS(領用表!$L:$L,領用表!$A:$A,DK$2,領用表!$E:$E,$B5) | DL5: =SUMIFS(領用表!$L:$L,領用表!$E:$E,$B5,領用表!$B:$B,DK$2&DL$2) | DM5: =SUMIFS(領用表!$L:$L,領用表!$E:$E,$B5,領用表!$B:$B,$DK$2&DM$2) | DN5: =SUMIFS(領用表!$L:$L,領用表!$E:$E,$B5,領用表!$B:$B,$DK$2&DN$2) | DO5: =SUMIFS(領用表!$L:$L,領用表!$E:$E,$B5,領用表!$B:$B,$DK$2&DO$2) | DP5: =SUMIFS(領用表!$L:$L,領用表!$E:$E,$B5,領用表!$B:$B,$DK$2&DP$2) | DQ5: 8 | DR5: 3 | DT5: 1 | DV5: 4 | DW5: =SUM(CN5,CS5,CY5,DE5,DK5,DQ5) | DX5: =AVERAGEA(CN5,CS5,CY5,DE5,DK5,DQ5) | DY5: =SUM(DZ5:EC5) | DZ5: 8 | EA5: 0 | EB5: 25 | EC5: 0 | ED5: 10 | EE5: 0 | EG5: 10盒(10/21) | EJ5: =IFERROR(VLOOKUP(A5,站前4樓!A:BF,57,0),0) | EK5: =IFERROR(VLOOKUP(A5,站前11樓!A:BE,57,0),0) | EL5: =IFERROR(VLOOKUP(A5,忠孝7樓!A:N,57,0),0) | EM5: =IFERROR(VLOOKUP(A5,忠孝國際醫學3樓!A:L,57,0),0) | EN5: =SUM(ED5:EG5) | EP5: 19 | EQ5: 8
A6: MP1MA020021A | B6: 6150003 | C6: 喬雅登豐麗緹玻尿酸植入物Volift 1ml/ syringe(1支) | D6: 2 | E6: PCS | F6: =SUMIF(站前4樓!B:B,B6,站前4樓!F:F) | G6: =SUMIF(站前11樓!B:B,B6,站前11樓!F:F) | H6: =SUMIF(忠孝7樓!B:B,B6,忠孝7樓!G:G) | I6: =SUMIF(忠孝國際醫學3樓!B:B,B6,忠孝國際醫學3樓!G:G) | J6: =SUMIF(忠孝健康7樓!B:B,B6,忠孝健康7樓!G:G) | K6: 1 | L6: 1 | M6: 0 | N6: 0 | O6: 2 | P6: 1 | Q6: 0 | R6: 0 | S6: 2 | T6: 0 | U6: 0 | V6: 1 | W6: 6 | X6: 3 | Y6: 0 | Z6: 0 | AA6: 0 | AB6: 2 | AC6: 1 | AD6: 3 | AE6: 0 | AF6: 0 | AG6: 0 | AH6: 2 | AI6: 10 | AJ6: 1 | AK6: 0 | AL6: 0.5 | AM6: 0.5 | AN6: 0 | AO6: 2.5 | AP6: 0.5 | AQ6: 0.5 | AR6: 7 | AS6: 10 | AT6: 0.5 | AU6: 0 | AV6: =SUM(AJ6:AU6) | AW6: =AV6/12 | AX6: 1 | AY6: 0 | AZ6: 0 | BA6: 1 | BB6: 6 | BC6: =SUMIFS(領用表!$L:$L,領用表!$A:$A,BC$2,領用表!$E:$E,B6) | BD6: =SUMIFS(領用表!$L:$L,領用表!$E:$E,$B6,領用表!$B:$B,BC$2&BD$2) | BE6: =SUMIFS(領用表!$L:$L,領用表!$E:$E,$B6,領用表!$B:$B,$BC$2&BE$2) | BF6: =SUMIFS(領用表!$L:$L,領用表!$E:$E,$B6,領用表!$B:$B,$BC$2&BF$2) | BG6: =SUMIFS(領用表!$L:$L,領用表!$E:$E,$B6,領用表!$B:$B,$BC$2&BG$2) | BH6: =SUMIFS(領用表!$L:$L,領用表!$A:$A,BH$2,領用表!$E:$E,B6) | BI6: =SUMIFS(領用表!$L:$L,領用表!$E:$E,$B6,領用表!$B:$B,BH$2&BI$2) | BJ6: =SUMIFS(領用表!$L:$L,領用表!$E:$E,$B6,領用表!$B:$B,$BH$2&BJ$2) | BK6: =SUMIFS(領用表!$L:$L,領用表!$E:$E,$B6,領用表!$B:$B,$BH$2&BK$2) | BL6: =SUMIFS(領用表!$L:$L,領用表!$E:$E,$B6,領用表!$B:$B,$BH$2&BL$2) | BM6: =SUMIFS(領用表!$L:$L,領用表!$A:$A,BM$2,領用表!$E:$E,B6) | BN6: =SUMIFS(領用表!$L:$L,領用表!$E:$E,$B6,領用表!$B:$B,BM$2&BN$2) | BO6: =SUMIFS(領用表!$L:$L,領用表!$E:$E,$B6,領用表!$B:$B,$BM$2&BO$2) | BP6: =SUMIFS(領用表!$L:$L,領用表!$E:$E,$B6,領用表!$B:$B,$BM$2&BP$2) | BQ6: =SUMIFS(領用表!$L:$L,領用表!$E:$E,$B6,領用表!$B:$B,$BM$2&BQ$2) | BR6: =SUMIFS(領用表!$L:$L,領用表!$A:$A,BR$2,領用表!$E:$E,B6) | BS6: =SUMIFS(領用表!$L:$L,領用表!$E:$E,$B6,領用表!$B:$B,BR$2&BS$2) | BT6: =SUMIFS(領用表!$L:$L,領用表!$E:$E,$B6,領用表!$B:$B,$BR$2&BT$2) | BU6: =SUMIFS(領用表!$L:$L,領用表!$E:$E,$B6,領用表!$B:$B,$BR$2&BU$2) | BV6: =SUMIFS(領用表!$L:$L,領用表!$E:$E,$B6,領用表!$B:$B,$BR$2&BV$2) | BW6: =SUMIFS(領用表!$L:$L,領用表!$A:$A,BW$2,領用表!$E:$E,B6) | BX6: =SUMIFS(領用表!$L:$L,領用表!$E:$E,$B6,領用表!$B:$B,BW$2&BX$2) | BY6: =SUMIFS(領用表!$L:$L,領用表!$E:$E,$B6,領用表!$B:$B,$BW$2&BY$2) | BZ6: =SUMIFS(領用表!$L:$L,領用表!$E:$E,$B6,領用表!$B:$B,$BW$2&BZ$2) | CA6: =SUMIFS(領用表!$L:$L,領用表!$E:$E,$B6,領用表!$B:$B,$BW$2&CA$2) | CB6: =SUMIFS(領用表!$L:$L,領用表!$A:$A,CB$2,領用表!$E:$E,B6) | CC6: =SUMIFS(領用表!$L:$L,領用表!$E:$E,$B6,領用表!$B:$B,CB$2&CC$2) | CD6: =SUMIFS(領用表!$L:$L,領用表!$E:$E,$B6,領用表!$B:$B,$CB$2&CD$2) | CE6: =SUMIFS(領用表!$L:$L,領用表!$E:$E,$B6,領用表!$B:$B,$CB$2&CE$2) | CF6: =SUMIFS(領用表!$L:$L,領用表!$E:$E,$B6,領用表!$B:$B,$CB$2&CF$2) | CG6: =SUMIFS(領用表!$L:$L,領用表!$A:$A,CG$2,領用表!$E:$E,B6) | CH6: =SUMIFS(領用表!$L:$L,領用表!$E:$E,$B6,領用表!$B:$B,CG$2&CH$2) | CI6: =SUMIFS(領用表!$L:$L,領用表!$E:$E,$B6,領用表!$B:$B,CG$2&CI$2) | CJ6: =SUMIFS(領用表!$L:$L,領用表!$E:$E,$B6,領用表!$B:$B,CG$2&CJ$2) | CK6: =SUMIFS(領用表!$L:$L,領用表!$E:$E,$B6,領用表!$B:$B,$CG$2&CK$2) | CL6: =SUM(AX6,AY6,AZ6,BA6,BB6,BC6,BH6,BM6,BR6,BW6,CB6,CG6) | CM6: =AVERAGE(AX6,AY6,AZ6,BA6,BB6,BC6,BH6,BM6,BR6,BW6,CB6,CG6) | CN6: =SUMIFS(領用表!$L:$L,領用表!$A:$A,CN$2,領用表!$E:$E,B6) | CO6: =SUMIFS(領用表!$L:$L,領用表!$E:$E,$B6,領用表!$B:$B,CN$2&CO$2) | CP6: =SUMIFS(領用表!$L:$L,領用表!$E:$E,$B6,領用表!$B:$B,$CN$2&CP$2) | CQ6: =SUMIFS(領用表!$L:$L,領用表!$E:$E,$B6,領用表!$B:$B,$CN$2&CQ$2) | CR6: =SUMIFS(領用表!$L:$L,領用表!$E:$E,$B6,領用表!$B:$B,$CN$2&CR$2) | CS6: =SUMIFS(領用表!$L:$L,領用表!$A:$A,CS$2,領用表!$E:$E,B6) | CT6: =SUMIFS(領用表!$L:$L,領用表!$E:$E,$B6,領用表!$B:$B,CS$2&CT$2) | CU6: =SUMIFS(領用表!$L:$L,領用表!$E:$E,$B6,領用表!$B:$B,$CS$2&CU$2) | CV6: =SUMIFS(領用表!$L:$L,領用表!$E:$E,$B6,領用表!$B:$B,$CS$2&CV$2) | CW6: =SUMIFS(領用表!$L:$L,領用表!$E:$E,$B6,領用表!$B:$B,$CS$2&CW$2) | CX6: =SUMIFS(領用表!$L:$L,領用表!$E:$E,$B6,領用表!$B:$B,$CS$2&CX$2) | CY6: =SUMIFS(領用表!$L:$L,領用表!$A:$A,CY$2,領用表!$E:$E,B6) | CZ6: =SUMIFS(領用表!$L:$L,領用表!$E:$E,$B6,領用表!$B:$B,CY$2&CZ$2) | DA6: =SUMIFS(領用表!$L:$L,領用表!$E:$E,$B6,領用表!$B:$B,$CY$2&DA$2) | DB6: =SUMIFS(領用表!$L:$L,領用表!$E:$E,$B6,領用表!$B:$B,$CY$2&DB$2) | DC6: =SUMIFS(領用表!$L:$L,領用表!$E:$E,$B6,領用表!$B:$B,$CY$2&DC$2) | DD6: =SUMIFS(領用表!$L:$L,領用表!$E:$E,$B6,領用表!$B:$B,$CY$2&DD$2) | DE6: =SUMIFS(領用表!$L:$L,領用表!$A:$A,DE$2,領用表!$E:$E,B6) | DF6: =SUMIFS(領用表!$L:$L,領用表!$E:$E,$B6,領用表!$B:$B,DE$2&DF$2) | DG6: =SUMIFS(領用表!$L:$L,領用表!$E:$E,$B6,領用表!$B:$B,$DE$2&DG$2) | DH6: =SUMIFS(領用表!$L:$L,領用表!$E:$E,$B6,領用表!$B:$B,$DE$2&DH$2) | DI6: =SUMIFS(領用表!$L:$L,領用表!$E:$E,$B6,領用表!$B:$B,$DE$2&DI$2) | DJ6: =SUMIFS(領用表!$L:$L,領用表!$E:$E,$B6,領用表!$B:$B,$DE$2&DJ$2) | DK6: =SUMIFS(領用表!$L:$L,領用表!$A:$A,DK$2,領用表!$E:$E,$B6) | DL6: =SUMIFS(領用表!$L:$L,領用表!$E:$E,$B6,領用表!$B:$B,DK$2&DL$2) | DM6: =SUMIFS(領用表!$L:$L,領用表!$E:$E,$B6,領用表!$B:$B,$DK$2&DM$2) | DN6: =SUMIFS(領用表!$L:$L,領用表!$E:$E,$B6,領用表!$B:$B,$DK$2&DN$2) | DO6: =SUMIFS(領用表!$L:$L,領用表!$E:$E,$B6,領用表!$B:$B,$DK$2&DO$2) | DP6: =SUMIFS(領用表!$L:$L,領用表!$E:$E,$B6,領用表!$B:$B,$DK$2&DP$2) | DQ6: 10 | DR6: 1 | DT6: 7 | DV6: 2 | DW6: =SUM(CN6,CS6,CY6,DE6,DK6,DQ6) | DX6: =AVERAGEA(CN6,CS6,CY6,DE6,DK6,DQ6) | DY6: =SUM(DZ6:EC6) | DZ6: 10 | EA6: 0 | EB6: 10 | EC6: 0 | ED6: 10 | EE6: 0 | EJ6: =IFERROR(VLOOKUP(A6,站前4樓!A:BF,57,0),0) | EK6: =IFERROR(VLOOKUP(A6,站前11樓!A:BE,57,0),0) | EL6: =IFERROR(VLOOKUP(A6,忠孝7樓!A:N,57,0),0) | EM6: =IFERROR(VLOOKUP(A6,忠孝國際醫學3樓!A:L,57,0),0) | EN6: =SUM(ED6:EG6) | EP6: 23 | EQ6: 31
A7: MP1MA020022A | B7: 6150004 | C7: 喬雅登豐塑玻尿酸植入物Volux 1ml/ syringe(1支) | D7: 2 | E7: PCS | F7: =SUMIF(站前4樓!B:B,B7,站前4樓!F:F) | G7: =SUMIF(站前11樓!B:B,B7,站前11樓!F:F) | H7: =SUMIF(忠孝7樓!B:B,B7,忠孝7樓!G:G) | I7: =SUMIF(忠孝國際醫學3樓!B:B,B7,忠孝國際醫學3樓!G:G) | J7: =SUMIF(忠孝健康7樓!B:B,B7,忠孝健康7樓!G:G) | K7: 2 | L7: 2 | M7: 0 | N7: 2 | O7: 2 | P7: 2 | Q7: 0 | R7: 0 | S7: 2 | T7: 3 | U7: 0 | V7: 3 | W7: 1 | X7: 3 | Y7: 4 | Z7: 4 | AA7: 5 | AB7: 1 | AC7: 4 | AD7: 8 | AE7: 1 | AF7: 2 | AG7: 5 | AH7: 1 | AI7: 3 | AJ7: 2 | AK7: 0.5 | AL7: 1.5 | AM7: 0.5 | AN7: 2.5 | AO7: 1.5 | AP7: 2.5 | AQ7: 5.5 | AR7: 6 | AS7: 4 | AT7: 2.5 | AU7: 1 | AV7: =SUM(AJ7:AU7) | AW7: =AV7/12 | AX7: 6 | AY7: 5 | AZ7: 16 | BA7: 26 | BB7: 19 | BC7: =SUMIFS(領用表!$L:$L,領用表!$A:$A,BC$2,領用表!$E:$E,B7) | BD7: =SUMIFS(領用表!$L:$L,領用表!$E:$E,$B7,領用表!$B:$B,BC$2&BD$2) | BE7: =SUMIFS(領用表!$L:$L,領用表!$E:$E,$B7,領用表!$B:$B,$BC$2&BE$2) | BF7: =SUMIFS(領用表!$L:$L,領用表!$E:$E,$B7,領用表!$B:$B,$BC$2&BF$2) | BG7: =SUMIFS(領用表!$L:$L,領用表!$E:$E,$B7,領用表!$B:$B,$BC$2&BG$2) | BH7: =SUMIFS(領用表!$L:$L,領用表!$A:$A,BH$2,領用表!$E:$E,B7) | BI7: =SUMIFS(領用表!$L:$L,領用表!$E:$E,$B7,領用表!$B:$B,BH$2&BI$2) | BJ7: =SUMIFS(領用表!$L:$L,領用表!$E:$E,$B7,領用表!$B:$B,$BH$2&BJ$2) | BK7: =SUMIFS(領用表!$L:$L,領用表!$E:$E,$B7,領用表!$B:$B,$BH$2&BK$2) | BL7: =SUMIFS(領用表!$L:$L,領用表!$E:$E,$B7,領用表!$B:$B,$BH$2&BL$2) | BM7: =SUMIFS(領用表!$L:$L,領用表!$A:$A,BM$2,領用表!$E:$E,B7) | BN7: =SUMIFS(領用表!$L:$L,領用表!$E:$E,$B7,領用表!$B:$B,BM$2&BN$2) | BO7: =SUMIFS(領用表!$L:$L,領用表!$E:$E,$B7,領用表!$B:$B,$BM$2&BO$2) | BP7: =SUMIFS(領用表!$L:$L,領用表!$E:$E,$B7,領用表!$B:$B,$BM$2&BP$2) | BQ7: =SUMIFS(領用表!$L:$L,領用表!$E:$E,$B7,領用表!$B:$B,$BM$2&BQ$2) | BR7: =SUMIFS(領用表!$L:$L,領用表!$A:$A,BR$2,領用表!$E:$E,B7) | BS7: =SUMIFS(領用表!$L:$L,領用表!$E:$E,$B7,領用表!$B:$B,BR$2&BS$2) | BT7: =SUMIFS(領用表!$L:$L,領用表!$E:$E,$B7,領用表!$B:$B,$BR$2&BT$2) | BU7: =SUMIFS(領用表!$L:$L,領用表!$E:$E,$B7,領用表!$B:$B,$BR$2&BU$2) | BV7: =SUMIFS(領用表!$L:$L,領用表!$E:$E,$B7,領用表!$B:$B,$BR$2&BV$2) | BW7: =SUMIFS(領用表!$L:$L,領用表!$A:$A,BW$2,領用表!$E:$E,B7) | BX7: =SUMIFS(領用表!$L:$L,領用表!$E:$E,$B7,領用表!$B:$B,BW$2&BX$2) | BY7: =SUMIFS(領用表!$L:$L,領用表!$E:$E,$B7,領用表!$B:$B,$BW$2&BY$2) | BZ7: =SUMIFS(領用表!$L:$L,領用表!$E:$E,$B7,領用表!$B:$B,$BW$2&BZ$2) | CA7: =SUMIFS(領用表!$L:$L,領用表!$E:$E,$B7,領用表!$B:$B,$BW$2&CA$2) | CB7: =SUMIFS(領用表!$L:$L,領用表!$A:$A,CB$2,領用表!$E:$E,B7) | CC7: =SUMIFS(領用表!$L:$L,領用表!$E:$E,$B7,領用表!$B:$B,CB$2&CC$2) | CD7: =SUMIFS(領用表!$L:$L,領用表!$E:$E,$B7,領用表!$B:$B,$CB$2&CD$2) | CE7: =SUMIFS(領用表!$L:$L,領用表!$E:$E,$B7,領用表!$B:$B,$CB$2&CE$2) | CF7: =SUMIFS(領用表!$L:$L,領用表!$E:$E,$B7,領用表!$B:$B,$CB$2&CF$2) | CG7: =SUMIFS(領用表!$L:$L,領用表!$A:$A,CG$2,領用表!$E:$E,B7) | CH7: =SUMIFS(領用表!$L:$L,領用表!$E:$E,$B7,領用表!$B:$B,CG$2&CH$2) | CI7: =SUMIFS(領用表!$L:$L,領用表!$E:$E,$B7,領用表!$B:$B,CG$2&CI$2) | CJ7: =SUMIFS(領用表!$L:$L,領用表!$E:$E,$B7,領用表!$B:$B,CG$2&CJ$2) | CK7: =SUMIFS(領用表!$L:$L,領用表!$E:$E,$B7,領用表!$B:$B,$CG$2&CK$2) | CL7: =SUM(AX7,AY7,AZ7,BA7,BB7,BC7,BH7,BM7,BR7,BW7,CB7,CG7) | CM7: =AVERAGE(AX7,AY7,AZ7,BA7,BB7,BC7,BH7,BM7,BR7,BW7,CB7,CG7) | CN7: =SUMIFS(領用表!$L:$L,領用表!$A:$A,CN$2,領用表!$E:$E,B7) | CO7: =SUMIFS(領用表!$L:$L,領用表!$E:$E,$B7,領用表!$B:$B,CN$2&CO$2) | CP7: =SUMIFS(領用表!$L:$L,領用表!$E:$E,$B7,領用表!$B:$B,$CN$2&CP$2) | CQ7: =SUMIFS(領用表!$L:$L,領用表!$E:$E,$B7,領用表!$B:$B,$CN$2&CQ$2) | CR7: =SUMIFS(領用表!$L:$L,領用表!$E:$E,$B7,領用表!$B:$B,$CN$2&CR$2) | CS7: =SUMIFS(領用表!$L:$L,領用表!$A:$A,CS$2,領用表!$E:$E,B7) | CT7: =SUMIFS(領用表!$L:$L,領用表!$E:$E,$B7,領用表!$B:$B,CS$2&CT$2) | CU7: =SUMIFS(領用表!$L:$L,領用表!$E:$E,$B7,領用表!$B:$B,$CS$2&CU$2) | CV7: =SUMIFS(領用表!$L:$L,領用表!$E:$E,$B7,領用表!$B:$B,$CS$2&CV$2) | CW7: =SUMIFS(領用表!$L:$L,領用表!$E:$E,$B7,領用表!$B:$B,$CS$2&CW$2) | CX7: =SUMIFS(領用表!$L:$L,領用表!$E:$E,$B7,領用表!$B:$B,$CS$2&CX$2) | CY7: =SUMIFS(領用表!$L:$L,領用表!$A:$A,CY$2,領用表!$E:$E,B7) | CZ7: =SUMIFS(領用表!$L:$L,領用表!$E:$E,$B7,領用表!$B:$B,CY$2&CZ$2) | DA7: =SUMIFS(領用表!$L:$L,領用表!$E:$E,$B7,領用表!$B:$B,$CY$2&DA$2) | DB7: =SUMIFS(領用表!$L:$L,領用表!$E:$E,$B7,領用表!$B:$B,$CY$2&DB$2) | DC7: =SUMIFS(領用表!$L:$L,領用表!$E:$E,$B7,領用表!$B:$B,$CY$2&DC$2) | DD7: =SUMIFS(領用表!$L:$L,領用表!$E:$E,$B7,領用表!$B:$B,$CY$2&DD$2) | DE7: =SUMIFS(領用表!$L:$L,領用表!$A:$A,DE$2,領用表!$E:$E,B7) | DF7: =SUMIFS(領用表!$L:$L,領用表!$E:$E,$B7,領用表!$B:$B,DE$2&DF$2) | DG7: =SUMIFS(領用表!$L:$L,領用表!$E:$E,$B7,領用表!$B:$B,$DE$2&DG$2) | DH7: =SUMIFS(領用表!$L:$L,領用表!$E:$E,$B7,領用表!$B:$B,$DE$2&DH$2) | DI7: =SUMIFS(領用表!$L:$L,領用表!$E:$E,$B7,領用表!$B:$B,$DE$2&DI$2) | DJ7: =SUMIFS(領用表!$L:$L,領用表!$E:$E,$B7,領用表!$B:$B,$DE$2&DJ$2) | DK7: =SUMIFS(領用表!$L:$L,領用表!$A:$A,DK$2,領用表!$E:$E,$B7) | DL7: =SUMIFS(領用表!$L:$L,領用表!$E:$E,$B7,領用表!$B:$B,DK$2&DL$2) | DM7: =SUMIFS(領用表!$L:$L,領用表!$E:$E,$B7,領用表!$B:$B,$DK$2&DM$2) | DN7: =SUMIFS(領用表!$L:$L,領用表!$E:$E,$B7,領用表!$B:$B,$DK$2&DN$2) | DO7: =SUMIFS(領用表!$L:$L,領用表!$E:$E,$B7,領用表!$B:$B,$DK$2&DO$2) | DP7: =SUMIFS(領用表!$L:$L,領用表!$E:$E,$B7,領用表!$B:$B,$DK$2&DP$2) | DQ7: 6 | DR7: 3 | DT7: 3 | DW7: =SUM(CN7,CS7,CY7,DE7,DK7,DQ7) | DX7: =AVERAGEA(CN7,CS7,CY7,DE7,DK7,DQ7) | DY7: =SUM(DZ7:EC7) | DZ7: 15 | EA7: 0 | EB7: 15 | EC7: 0 | ED7: 20 | EE7: 0 | EG7: 15盒(10/21) | EJ7: =IFERROR(VLOOKUP(A7,站前4樓!A:BF,57,0),0) | EK7: =IFERROR(VLOOKUP(A7,站前11樓!A:BE,57,0),0) | EL7: =IFERROR(VLOOKUP(A7,忠孝7樓!A:N,57,0),0) | EM7: =IFERROR(VLOOKUP(A7,忠孝國際醫學3樓!A:L,57,0),0) | EN7: =SUM(ED7:EG7) | EP7: 38 | EQ7: 32
A8: MP1MA020023A | B8: 6150005 | C8: 喬雅登芙潤玻尿酸植入物Volite 1ml/ Syringe(1支) | D8: 2 | E8: PCS | F8: =SUMIF(站前4樓!B:B,B8,站前4樓!F:F) | G8: =SUMIF(站前11樓!B:B,B8,站前11樓!F:F) | H8: =SUMIF(忠孝7樓!B:B,B8,忠孝7樓!G:G) | I8: =SUMIF(忠孝國際醫學3樓!B:B,B8,忠孝國際醫學3樓!G:G) | J8: =SUMIF(忠孝健康7樓!B:B,B8,忠孝健康7樓!G:G) | K8: 0 | L8: 0 | M8: 0 | N8: 0 | O8: 0 | P8: 0 | Q8: 3 | R8: 0 | S8: 0 | T8: 0 | U8: 3 | V8: 2 | W8: 2 | X8: 1 | Y8: 1 | Z8: 0 | AA8: 0 | AB8: 0 | AC8: 0 | AD8: 0 | AE8: 0 | AF8: 0 | AG8: 5 | AH8: 0 | AI8: 0 | AJ8: 0.5 | AK8: 1.5 | AL8: 2 | AM8: 2.5 | AN8: 2 | AO8: 5.5 | AP8: 2.5 | AQ8: 7 | AR8: 2 | AS8: 1 | AT8: 0.5 | AU8: 4 | AV8: =SUM(AJ8:AU8) | AW8: =AV8/12 | AX8: 2 | AY8: 3 | AZ8: 6 | BA8: 2 | BB8: 3 | BC8: =SUMIFS(領用表!$L:$L,領用表!$A:$A,BC$2,領用表!$E:$E,B8) | BD8: =SUMIFS(領用表!$L:$L,領用表!$E:$E,$B8,領用表!$B:$B,BC$2&BD$2) | BE8: =SUMIFS(領用表!$L:$L,領用表!$E:$E,$B8,領用表!$B:$B,$BC$2&BE$2) | BF8: =SUMIFS(領用表!$L:$L,領用表!$E:$E,$B8,領用表!$B:$B,$BC$2&BF$2) | BG8: =SUMIFS(領用表!$L:$L,領用表!$E:$E,$B8,領用表!$B:$B,$BC$2&BG$2) | BH8: =SUMIFS(領用表!$L:$L,領用表!$A:$A,BH$2,領用表!$E:$E,B8) | BI8: =SUMIFS(領用表!$L:$L,領用表!$E:$E,$B8,領用表!$B:$B,BH$2&BI$2) | BJ8: =SUMIFS(領用表!$L:$L,領用表!$E:$E,$B8,領用表!$B:$B,$BH$2&BJ$2) | BK8: =SUMIFS(領用表!$L:$L,領用表!$E:$E,$B8,領用表!$B:$B,$BH$2&BK$2) | BL8: =SUMIFS(領用表!$L:$L,領用表!$E:$E,$B8,領用表!$B:$B,$BH$2&BL$2) | BM8: =SUMIFS(領用表!$L:$L,領用表!$A:$A,BM$2,領用表!$E:$E,B8) | BN8: =SUMIFS(領用表!$L:$L,領用表!$E:$E,$B8,領用表!$B:$B,BM$2&BN$2) | BO8: =SUMIFS(領用表!$L:$L,領用表!$E:$E,$B8,領用表!$B:$B,$BM$2&BO$2) | BP8: =SUMIFS(領用表!$L:$L,領用表!$E:$E,$B8,領用表!$B:$B,$BM$2&BP$2) | BQ8: =SUMIFS(領用表!$L:$L,領用表!$E:$E,$B8,領用表!$B:$B,$BM$2&BQ$2) | BR8: =SUMIFS(領用表!$L:$L,領用表!$A:$A,BR$2,領用表!$E:$E,B8) | BS8: =SUMIFS(領用表!$L:$L,領用表!$E:$E,$B8,領用表!$B:$B,BR$2&BS$2) | BT8: =SUMIFS(領用表!$L:$L,領用表!$E:$E,$B8,領用表!$B:$B,$BR$2&BT$2) | BU8: =SUMIFS(領用表!$L:$L,領用表!$E:$E,$B8,領用表!$B:$B,$BR$2&BU$2) | BV8: =SUMIFS(領用表!$L:$L,領用表!$E:$E,$B8,領用表!$B:$B,$BR$2&BV$2) | BW8: =SUMIFS(領用表!$L:$L,領用表!$A:$A,BW$2,領用表!$E:$E,B8) | BX8: =SUMIFS(領用表!$L:$L,領用表!$E:$E,$B8,領用表!$B:$B,BW$2&BX$2) | BY8: =SUMIFS(領用表!$L:$L,領用表!$E:$E,$B8,領用表!$B:$B,$BW$2&BY$2) | BZ8: =SUMIFS(領用表!$L:$L,領用表!$E:$E,$B8,領用表!$B:$B,$BW$2&BZ$2) | CA8: =SUMIFS(領用表!$L:$L,領用表!$E:$E,$B8,領用表!$B:$B,$BW$2&CA$2) | CB8: =SUMIFS(領用表!$L:$L,領用表!$A:$A,CB$2,領用表!$E:$E,B8) | CC8: =SUMIFS(領用表!$L:$L,領用表!$E:$E,$B8,領用表!$B:$B,CB$2&CC$2) | CD8: =SUMIFS(領用表!$L:$L,領用表!$E:$E,$B8,領用表!$B:$B,$CB$2&CD$2) | CE8: =SUMIFS(領用表!$L:$L,領用表!$E:$E,$B8,領用表!$B:$B,$CB$2&CE$2) | CF8: =SUMIFS(領用表!$L:$L,領用表!$E:$E,$B8,領用表!$B:$B,$CB$2&CF$2) | CG8: =SUMIFS(領用表!$L:$L,領用表!$A:$A,CG$2,領用表!$E:$E,B8) | CH8: =SUMIFS(領用表!$L:$L,領用表!$E:$E,$B8,領用表!$B:$B,CG$2&CH$2) | CI8: =SUMIFS(領用表!$L:$L,領用表!$E:$E,$B8,領用表!$B:$B,CG$2&CI$2) | CJ8: =SUMIFS(領用表!$L:$L,領用表!$E:$E,$B8,領用表!$B:$B,CG$2&CJ$2) | CK8: =SUMIFS(領用表!$L:$L,領用表!$E:$E,$B8,領用表!$B:$B,$CG$2&CK$2) | CL8: =SUM(AX8,AY8,AZ8,BA8,BB8,BC8,BH8,BM8,BR8,BW8,CB8,CG8) | CM8: =AVERAGE(AX8,AY8,AZ8,BA8,BB8,BC8,BH8,BM8,BR8,BW8,CB8,CG8) | CN8: =SUMIFS(領用表!$L:$L,領用表!$A:$A,CN$2,領用表!$E:$E,B8) | CO8: =SUMIFS(領用表!$L:$L,領用表!$E:$E,$B8,領用表!$B:$B,CN$2&CO$2) | CP8: =SUMIFS(領用表!$L:$L,領用表!$E:$E,$B8,領用表!$B:$B,$CN$2&CP$2) | CQ8: =SUMIFS(領用表!$L:$L,領用表!$E:$E,$B8,領用表!$B:$B,$CN$2&CQ$2) | CR8: =SUMIFS(領用表!$L:$L,領用表!$E:$E,$B8,領用表!$B:$B,$CN$2&CR$2) | CS8: =SUMIFS(領用表!$L:$L,領用表!$A:$A,CS$2,領用表!$E:$E,B8) | CT8: =SUMIFS(領用表!$L:$L,領用表!$E:$E,$B8,領用表!$B:$B,CS$2&CT$2) | CU8: =SUMIFS(領用表!$L:$L,領用表!$E:$E,$B8,領用表!$B:$B,$CS$2&CU$2) | CV8: =SUMIFS(領用表!$L:$L,領用表!$E:$E,$B8,領用表!$B:$B,$CS$2&CV$2) | CW8: =SUMIFS(領用表!$L:$L,領用表!$E:$E,$B8,領用表!$B:$B,$CS$2&CW$2) | CX8: =SUMIFS(領用表!$L:$L,領用表!$E:$E,$B8,領用表!$B:$B,$CS$2&CX$2) | CY8: =SUMIFS(領用表!$L:$L,領用表!$A:$A,CY$2,領用表!$E:$E,B8) | CZ8: =SUMIFS(領用表!$L:$L,領用表!$E:$E,$B8,領用表!$B:$B,CY$2&CZ$2) | DA8: =SUMIFS(領用表!$L:$L,領用表!$E:$E,$B8,領用表!$B:$B,$CY$2&DA$2) | DB8: =SUMIFS(領用表!$L:$L,領用表!$E:$E,$B8,領用表!$B:$B,$CY$2&DB$2) | DC8: =SUMIFS(領用表!$L:$L,領用表!$E:$E,$B8,領用表!$B:$B,$CY$2&DC$2) | DD8: =SUMIFS(領用表!$L:$L,領用表!$E:$E,$B8,領用表!$B:$B,$CY$2&DD$2) | DE8: =SUMIFS(領用表!$L:$L,領用表!$A:$A,DE$2,領用表!$E:$E,B8) | DF8: =SUMIFS(領用表!$L:$L,領用表!$E:$E,$B8,領用表!$B:$B,DE$2&DF$2) | DG8: =SUMIFS(領用表!$L:$L,領用表!$E:$E,$B8,領用表!$B:$B,$DE$2&DG$2) | DH8: =SUMIFS(領用表!$L:$L,領用表!$E:$E,$B8,領用表!$B:$B,$DE$2&DH$2) | DI8: =SUMIFS(領用表!$L:$L,領用表!$E:$E,$B8,領用表!$B:$B,$DE$2&DI$2) | DJ8: =SUMIFS(領用表!$L:$L,領用表!$E:$E,$B8,領用表!$B:$B,$DE$2&DJ$2) | DK8: =SUMIFS(領用表!$L:$L,領用表!$A:$A,DK$2,領用表!$E:$E,$B8) | DL8: =SUMIFS(領用表!$L:$L,領用表!$E:$E,$B8,領用表!$B:$B,DK$2&DL$2) | DM8: =SUMIFS(領用表!$L:$L,領用表!$E:$E,$B8,領用表!$B:$B,$DK$2&DM$2) | DN8: =SUMIFS(領用表!$L:$L,領用表!$E:$E,$B8,領用表!$B:$B,$DK$2&DN$2) | DO8: =SUMIFS(領用表!$L:$L,領用表!$E:$E,$B8,領用表!$B:$B,$DK$2&DO$2) | DP8: =SUMIFS(領用表!$L:$L,領用表!$E:$E,$B8,領用表!$B:$B,$DK$2&DP$2) | DW8: =SUM(CN8,CS8,CY8,DE8,DK8,DQ8) | DX8: =AVERAGEA(CN8,CS8,CY8,DE8,DK8,DQ8) | DY8: =SUM(DZ8:EC8) | DZ8: 5 | EA8: 0 | EB8: 5 | EC8: 0 | ED8: 6 | EE8: 0 | EJ8: =IFERROR(VLOOKUP(A8,站前4樓!A:BF,57,0),0) | EK8: =IFERROR(VLOOKUP(A8,站前11樓!A:BE,57,0),0) | EL8: =IFERROR(VLOOKUP(A8,忠孝7樓!A:N,57,0),0) | EM8: =IFERROR(VLOOKUP(A8,忠孝國際醫學3樓!A:L,57,0),0) | EN8: =SUM(ED8:EG8) | EP8: 26 | EQ8: 7
B9: 6150015 | C9: 喬雅登絲漾膚玻尿酸植入物Skinvive 1ml/支 | D9: 2 | E9: PCS | F9: =SUMIF(站前4樓!B:B,B9,站前4樓!F:F) | G9: =SUMIF(站前11樓!B:B,B9,站前11樓!F:F) | H9: =SUMIF(忠孝7樓!B:B,B9,忠孝7樓!G:G) | I9: =SUMIF(忠孝國際醫學3樓!B:B,B9,忠孝國際醫學3樓!G:G) | J9: =SUMIF(忠孝健康7樓!B:B,B9,忠孝健康7樓!G:G) | CL9: =SUM(AX9,AY9,AZ9,BA9,BB9,BC9,BH9,BM9,BR9,BW9,CB9,CG9) | CM9: =IFERROR(AVERAGE(AX9,AY9,AZ9,BA9,BB9,BC9,BH9,BM9,BR9,BW9,CB9,CG9),0) | CN9: =SUMIFS(領用表!$L:$L,領用表!$A:$A,CN$2,領用表!$E:$E,B9) | CO9: =SUMIFS(領用表!$L:$L,領用表!$E:$E,$B9,領用表!$B:$B,CN$2&CO$2) | CP9: =SUMIFS(領用表!$L:$L,領用表!$E:$E,$B9,領用表!$B:$B,$CN$2&CP$2) | CQ9: =SUMIFS(領用表!$L:$L,領用表!$E:$E,$B9,領用表!$B:$B,$CN$2&CQ$2) | CR9: =SUMIFS(領用表!$L:$L,領用表!$E:$E,$B9,領用表!$B:$B,$CN$2&CR$2) | CS9: =SUMIFS(領用表!$L:$L,領用表!$A:$A,CS$2,領用表!$E:$E,B9) | CT9: =SUMIFS(領用表!$L:$L,領用表!$E:$E,$B9,領用表!$B:$B,CS$2&CT$2) | CU9: =SUMIFS(領用表!$L:$L,領用表!$E:$E,$B9,領用表!$B:$B,$CS$2&CU$2) | CV9: =SUMIFS(領用表!$L:$L,領用表!$E:$E,$B9,領用表!$B:$B,$CS$2&CV$2) | CW9: =SUMIFS(領用表!$L:$L,領用表!$E:$E,$B9,領用表!$B:$B,$CS$2&CW$2) | CX9: =SUMIFS(領用表!$L:$L,領用表!$E:$E,$B9,領用表!$B:$B,$CS$2&CX$2) | CY9: =SUMIFS(領用表!$L:$L,領用表!$A:$A,CY$2,領用表!$E:$E,B9) | CZ9: =SUMIFS(領用表!$L:$L,領用表!$E:$E,$B9,領用表!$B:$B,CY$2&CZ$2) | DA9: =SUMIFS(領用表!$L:$L,領用表!$E:$E,$B9,領用表!$B:$B,$CY$2&DA$2) | DB9: =SUMIFS(領用表!$L:$L,領用表!$E:$E,$B9,領用表!$B:$B,$CY$2&DB$2) | DC9: =SUMIFS(領用表!$L:$L,領用表!$E:$E,$B9,領用表!$B:$B,$CY$2&DC$2) | DD9: =SUMIFS(領用表!$L:$L,領用表!$E:$E,$B9,領用表!$B:$B,$CY$2&DD$2) | DE9: =SUMIFS(領用表!$L:$L,領用表!$A:$A,DE$2,領用表!$E:$E,B9) | DF9: =SUMIFS(領用表!$L:$L,領用表!$E:$E,$B9,領用表!$B:$B,DE$2&DF$2) | DG9: =SUMIFS(領用表!$L:$L,領用表!$E:$E,$B9,領用表!$B:$B,$DE$2&DG$2) | DH9: =SUMIFS(領用表!$L:$L,領用表!$E:$E,$B9,領用表!$B:$B,$DE$2&DH$2) | DI9: =SUMIFS(領用表!$L:$L,領用表!$E:$E,$B9,領用表!$B:$B,$DE$2&DI$2) | DJ9: =SUMIFS(領用表!$L:$L,領用表!$E:$E,$B9,領用表!$B:$B,$DE$2&DJ$2) | DK9: =SUMIFS(領用表!$L:$L,領用表!$A:$A,DK$2,領用表!$E:$E,$B9) | DL9: =SUMIFS(領用表!$L:$L,領用表!$E:$E,$B9,領用表!$B:$B,DK$2&DL$2) | DM9: =SUMIFS(領用表!$L:$L,領用表!$E:$E,$B9,領用表!$B:$B,$DK$2&DM$2) | DN9: =SUMIFS(領用表!$L:$L,領用表!$E:$E,$B9,領用表!$B:$B,$DK$2&DN$2) | DO9: =SUMIFS(領用表!$L:$L,領用表!$E:$E,$B9,領用表!$B:$B,$DK$2&DO$2) | DP9: =SUMIFS(領用表!$L:$L,領用表!$E:$E,$B9,領用表!$B:$B,$DK$2&DP$2) | DQ9: 3 | DT9: 1 | DV9: 2 | DW9: =SUM(CN9,CS9,CY9,DE9,DK9,DQ9) | DX9: =AVERAGEA(CN9,CS9,CY9,DE9,DK9,DQ9) | DY9: =SUM(DZ9:EC9)
B10: 6150016 | C10: 彈力針(1支/盒) | D10: 1 | E10: PCS | F10: =SUMIF(站前4樓!B:B,B10,站前4樓!F:F) | G10: =SUMIF(站前11樓!B:B,B10,站前11樓!F:F) | H10: =SUMIF(忠孝7樓!B:B,B10,忠孝7樓!G:G) | I10: =SUMIF(忠孝國際醫學3樓!B:B,B10,忠孝國際醫學3樓!G:G) | J10: =SUMIF(忠孝健康7樓!B:B,B10,忠孝健康7樓!G:G) | DK10: =SUMIFS(領用表!$L:$L,領用表!$A:$A,DK$2,領用表!$E:$E,$B10) | DL10: =SUMIFS(領用表!$L:$L,領用表!$E:$E,$B10,領用表!$B:$B,DK$2&DL$2) | DM10: =SUMIFS(領用表!$L:$L,領用表!$E:$E,$B10,領用表!$B:$B,$DK$2&DM$2) | DN10: =SUMIFS(領用表!$L:$L,領用表!$E:$E,$B10,領用表!$B:$B,$DK$2&DN$2) | DO10: =SUMIFS(領用表!$L:$L,領用表!$E:$E,$B10,領用表!$B:$B,$DK$2&DO$2) | DP10: =SUMIFS(領用表!$L:$L,領用表!$E:$E,$B10,領用表!$B:$B,$DK$2&DP$2) | DW10: =SUM(CN10,CS10,CY10,DE10,DK10,DQ10) | DX10: =AVERAGEA(CN10,CS10,CY10,DE10,DK10,DQ10) | DY10: =SUM(DZ10:EC10)
A11: MP1MA010011A | B11: 6180015 | C11: MINT秘特拉提線EASY 42.4CM(1支) | D11: 2 | E11: PCS | F11: =SUMIF(站前4樓!B:B,B11,站前4樓!F:F) | G11: =SUMIF(站前11樓!B:B,B11,站前11樓!F:F) | H11: =SUMIF(忠孝7樓!B:B,B11,忠孝7樓!G:G) | I11: =SUMIF(忠孝國際醫學3樓!B:B,B11,忠孝國際醫學3樓!G:G) | J11: =SUMIF(忠孝健康7樓!B:B,B11,忠孝健康7樓!G:G) | K11: 0 | L11: 0 | M11: 0 | N11: 0 | O11: 0 | P11: 0 | Q11: 0 | R11: 0 | S11: 0 | T11: 0 | U11: 0 | V11: 0 | W11: 0 | X11: 0 | Y11: 0 | Z11: 0 | AA11: 0 | AB11: 0 | AC11: 0 | AD11: 0 | AE11: 0 | AF11: 0 | AG11: 0 | AH11: 0 | AI11: 0 | AJ11: 0 | AK11: 0 | AL11: 0 | AM11: 2 | AN11: 0 | AO11: 0 | AP11: 0 | AQ11: 0 | AR11: 1 | AS11: 0 | AT11: 0 | AU11: 0 | AV11: =SUM(AJ11:AU11) | AW11: =AV11/12 | AX11: 0 | AY11: 0 | AZ11: 2 | BA11: 0 | BB11: 2 | BC11: =SUMIFS(領用表!$L:$L,領用表!$A:$A,BC$2,領用表!$E:$E,B11) | BD11: =SUMIFS(領用表!$L:$L,領用表!$E:$E,$B11,領用表!$B:$B,BC$2&BD$2) | BE11: =SUMIFS(領用表!$L:$L,領用表!$E:$E,$B11,領用表!$B:$B,$BC$2&BE$2) | BF11: =SUMIFS(領用表!$L:$L,領用表!$E:$E,$B11,領用表!$B:$B,$BC$2&BF$2) | BG11: =SUMIFS(領用表!$L:$L,領用表!$E:$E,$B11,領用表!$B:$B,$BC$2&BG$2) | BH11: =SUMIFS(領用表!$L:$L,領用表!$A:$A,BH$2,領用表!$E:$E,B11) | BI11: =SUMIFS(領用表!$L:$L,領用表!$E:$E,$B11,領用表!$B:$B,BH$2&BI$2) | BJ11: =SUMIFS(領用表!$L:$L,領用表!$E:$E,$B11,領用表!$B:$B,$BH$2&BJ$2) | BK11: =SUMIFS(領用表!$L:$L,領用表!$E:$E,$B11,領用表!$B:$B,$BH$2&BK$2) | BL11: =SUMIFS(領用表!$L:$L,領用表!$E:$E,$B11,領用表!$B:$B,$BH$2&BL$2) | BM11: =SUMIFS(領用表!$L:$L,領用表!$A:$A,BM$2,領用表!$E:$E,B11) | BN11: =SUMIFS(領用表!$L:$L,領用表!$E:$E,$B11,領用表!$B:$B,BM$2&BN$2) | BO11: =SUMIFS(領用表!$L:$L,領用表!$E:$E,$B11,領用表!$B:$B,$BM$2&BO$2) | BP11: =SUMIFS(領用表!$L:$L,領用表!$E:$E,$B11,領用表!$B:$B,$BM$2&BP$2) | BQ11: =SUMIFS(領用表!$L:$L,領用表!$E:$E,$B11,領用表!$B:$B,$BM$2&BQ$2) | BR11: =SUMIFS(領用表!$L:$L,領用表!$A:$A,BR$2,領用表!$E:$E,B11) | BS11: =SUMIFS(領用表!$L:$L,領用表!$E:$E,$B11,領用表!$B:$B,BR$2&BS$2) | BT11: =SUMIFS(領用表!$L:$L,領用表!$E:$E,$B11,領用表!$B:$B,$BR$2&BT$2) | BU11: =SUMIFS(領用表!$L:$L,領用表!$E:$E,$B11,領用表!$B:$B,$BR$2&BU$2) | BV11: =SUMIFS(領用表!$L:$L,領用表!$E:$E,$B11,領用表!$B:$B,$BR$2&BV$2) | BW11: =SUMIFS(領用表!$L:$L,領用表!$A:$A,BW$2,領用表!$E:$E,B11) | BX11: =SUMIFS(領用表!$L:$L,領用表!$E:$E,$B11,領用表!$B:$B,BW$2&BX$2) | BY11: =SUMIFS(領用表!$L:$L,領用表!$E:$E,$B11,領用表!$B:$B,$BW$2&BY$2) | BZ11: =SUMIFS(領用表!$L:$L,領用表!$E:$E,$B11,領用表!$B:$B,$BW$2&BZ$2) | CA11: =SUMIFS(領用表!$L:$L,領用表!$E:$E,$B11,領用表!$B:$B,$BW$2&CA$2) | CB11: =SUMIFS(領用表!$L:$L,領用表!$A:$A,CB$2,領用表!$E:$E,B11) | CC11: =SUMIFS(領用表!$L:$L,領用表!$E:$E,$B11,領用表!$B:$B,CB$2&CC$2) | CD11: =SUMIFS(領用表!$L:$L,領用表!$E:$E,$B11,領用表!$B:$B,$CB$2&CD$2) | CE11: =SUMIFS(領用表!$L:$L,領用表!$E:$E,$B11,領用表!$B:$B,$CB$2&CE$2) | CF11: =SUMIFS(領用表!$L:$L,領用表!$E:$E,$B11,領用表!$B:$B,$CB$2&CF$2) | CG11: =SUMIFS(領用表!$L:$L,領用表!$A:$A,CG$2,領用表!$E:$E,B11) | CH11: =SUMIFS(領用表!$L:$L,領用表!$E:$E,$B11,領用表!$B:$B,CG$2&CH$2) | CI11: =SUMIFS(領用表!$L:$L,領用表!$E:$E,$B11,領用表!$B:$B,CG$2&CI$2) | CJ11: =SUMIFS(領用表!$L:$L,領用表!$E:$E,$B11,領用表!$B:$B,CG$2&CJ$2) | CK11: =SUMIFS(領用表!$L:$L,領用表!$E:$E,$B11,領用表!$B:$B,$CG$2&CK$2) | CL11: =SUM(AX11,AY11,AZ11,BA11,BB11,BC11,BH11,BM11,BR11,BW11,CB11,CG11) | CM11: =AVERAGE(AX11,AY11,AZ11,BA11,BB11,BC11,BH11,BM11,BR11,BW11,CB11,CG11) | CN11: =SUMIFS(領用表!$L:$L,領用表!$A:$A,CN$2,領用表!$E:$E,B11) | CO11: =SUMIFS(領用表!$L:$L,領用表!$E:$E,$B11,領用表!$B:$B,CN$2&CO$2) | CP11: =SUMIFS(領用表!$L:$L,領用表!$E:$E,$B11,領用表!$B:$B,$CN$2&CP$2) | CQ11: =SUMIFS(領用表!$L:$L,領用表!$E:$E,$B11,領用表!$B:$B,$CN$2&CQ$2) | CR11: =SUMIFS(領用表!$L:$L,領用表!$E:$E,$B11,領用表!$B:$B,$CN$2&CR$2) | CS11: =SUMIFS(領用表!$L:$L,領用表!$A:$A,CS$2,領用表!$E:$E,B11) | CT11: =SUMIFS(領用表!$L:$L,領用表!$E:$E,$B11,領用表!$B:$B,CS$2&CT$2) | CU11: =SUMIFS(領用表!$L:$L,領用表!$E:$E,$B11,領用表!$B:$B,$CS$2&CU$2) | CV11: =SUMIFS(領用表!$L:$L,領用表!$E:$E,$B11,領用表!$B:$B,$CS$2&CV$2) | CW11: =SUMIFS(領用表!$L:$L,領用表!$E:$E,$B11,領用表!$B:$B,$CS$2&CW$2) | CX11: =SUMIFS(領用表!$L:$L,領用表!$E:$E,$B11,領用表!$B:$B,$CS$2&CX$2) | CY11: =SUMIFS(領用表!$L:$L,領用表!$A:$A,CY$2,領用表!$E:$E,B11) | CZ11: =SUMIFS(領用表!$L:$L,領用表!$E:$E,$B11,領用表!$B:$B,CY$2&CZ$2) | DA11: =SUMIFS(領用表!$L:$L,領用表!$E:$E,$B11,領用表!$B:$B,$CY$2&DA$2) | DB11: =SUMIFS(領用表!$L:$L,領用表!$E:$E,$B11,領用表!$B:$B,$CY$2&DB$2) | DC11: =SUMIFS(領用表!$L:$L,領用表!$E:$E,$B11,領用表!$B:$B,$CY$2&DC$2) | DD11: =SUMIFS(領用表!$L:$L,領用表!$E:$E,$B11,領用表!$B:$B,$CY$2&DD$2) | DE11: =SUMIFS(領用表!$L:$L,領用表!$A:$A,DE$2,領用表!$E:$E,B11) | DF11: =SUMIFS(領用表!$L:$L,領用表!$E:$E,$B11,領用表!$B:$B,DE$2&DF$2) | DG11: =SUMIFS(領用表!$L:$L,領用表!$E:$E,$B11,領用表!$B:$B,$DE$2&DG$2) | DH11: =SUMIFS(領用表!$L:$L,領用表!$E:$E,$B11,領用表!$B:$B,$DE$2&DH$2) | DI11: =SUMIFS(領用表!$L:$L,領用表!$E:$E,$B11,領用表!$B:$B,$DE$2&DI$2) | DJ11: =SUMIFS(領用表!$L:$L,領用表!$E:$E,$B11,領用表!$B:$B,$DE$2&DJ$2) | DK11: =SUMIFS(領用表!$L:$L,領用表!$A:$A,DK$2,領用表!$E:$E,$B11) | DL11: =SUMIFS(領用表!$L:$L,領用表!$E:$E,$B11,領用表!$B:$B,DK$2&DL$2) | DM11: =SUMIFS(領用表!$L:$L,領用表!$E:$E,$B11,領用表!$B:$B,$DK$2&DM$2) | DN11: =SUMIFS(領用表!$L:$L,領用表!$E:$E,$B11,領用表!$B:$B,$DK$2&DN$2) | DO11: =SUMIFS(領用表!$L:$L,領用表!$E:$E,$B11,領用表!$B:$B,$DK$2&DO$2) | DP11: =SUMIFS(領用表!$L:$L,領用表!$E:$E,$B11,領用表!$B:$B,$DK$2&DP$2) | DW11: =SUM(CN11,CS11,CY11,DE11,DK11,DQ11) | DX11: =AVERAGEA(CN11,CS11,CY11,DE11,DK11,DQ11) | DY11: =SUM(DZ11:EC11) | DZ11: 1 | EA11: 0 | EB11: 1 | EC11: 0 | ED11: 1 | EJ11: =IFERROR(VLOOKUP(A11,站前4樓!A:BF,57,0),0) | EK11: =IFERROR(VLOOKUP(A11,站前11樓!A:BE,57,0),0) | EL11: =IFERROR(VLOOKUP(A11,忠孝7樓!A:N,57,0),0) | EM11: =IFERROR(VLOOKUP(A11,忠孝國際醫學3樓!A:L,57,0),0) | EN11: =SUM(ED11:EG11) | EP11: 6 | EQ11: 4
A12: MP1MA010012A | B12: 6180005 | C12: MINT秘特拉提線FINE 18CM(1支) | D12: 20 | E12: PCS | F12: =SUMIF(站前4樓!B:B,B12,站前4樓!F:F) | G12: =SUMIF(站前11樓!B:B,B12,站前11樓!F:F) | H12: =SUMIF(忠孝7樓!B:B,B12,忠孝7樓!G:G) | I12: =SUMIF(忠孝國際醫學3樓!B:B,B12,忠孝國際醫學3樓!G:G) | J12: =SUMIF(忠孝健康7樓!B:B,B12,忠孝健康7樓!G:G) | K12: 0 | L12: 0 | M12: 0 | N12: 0 | O12: 0 | P12: 0 | Q12: 0 | R12: 0 | S12: 0 | T12: 0 | U12: 0 | V12: 0 | W12: 0 | X12: 0 | Y12: 0 | Z12: 0 | AA12: 0 | AB12: 0 | AC12: 0 | AD12: 0 | AE12: 0 | AF12: 0 | AG12: 0 | AH12: 0 | AI12: 32 | AJ12: 1.2 | AK12: 2.2 | AL12: 2.2 | AM12: 1.6 | AN12: 3.4 | AO12: 2.2 | AP12: 0.4 | AQ12: 0.6 | AR12: 0.4 | AS12: 0.2 | AT12: 0.4 | AU12: 28 | AV12: =SUM(AJ12:AU12) | AW12: =AV12/12 | AX12: 0 | AY12: 8 | AZ12: 0 | BA12: 0 | BB12: 0 | BC12: =SUMIFS(領用表!$L:$L,領用表!$A:$A,BC$2,領用表!$E:$E,B12) | BD12: =SUMIFS(領用表!$L:$L,領用表!$E:$E,$B12,領用表!$B:$B,BC$2&BD$2) | BE12: =SUMIFS(領用表!$L:$L,領用表!$E:$E,$B12,領用表!$B:$B,$BC$2&BE$2) | BF12: =SUMIFS(領用表!$L:$L,領用表!$E:$E,$B12,領用表!$B:$B,$BC$2&BF$2) | BG12: =SUMIFS(領用表!$L:$L,領用表!$E:$E,$B12,領用表!$B:$B,$BC$2&BG$2) | BH12: =SUMIFS(領用表!$L:$L,領用表!$A:$A,BH$2,領用表!$E:$E,B12) | BI12: =SUMIFS(領用表!$L:$L,領用表!$E:$E,$B12,領用表!$B:$B,BH$2&BI$2) | BJ12: =SUMIFS(領用表!$L:$L,領用表!$E:$E,$B12,領用表!$B:$B,$BH$2&BJ$2) | BK12: =SUMIFS(領用表!$L:$L,領用表!$E:$E,$B12,領用表!$B:$B,$BH$2&BK$2) | BL12: =SUMIFS(領用表!$L:$L,領用表!$E:$E,$B12,領用表!$B:$B,$BH$2&BL$2) | BM12: =SUMIFS(領用表!$L:$L,領用表!$A:$A,BM$2,領用表!$E:$E,B12) | BN12: =SUMIFS(領用表!$L:$L,領用表!$E:$E,$B12,領用表!$B:$B,BM$2&BN$2) | BO12: =SUMIFS(領用表!$L:$L,領用表!$E:$E,$B12,領用表!$B:$B,$BM$2&BO$2) | BP12: =SUMIFS(領用表!$L:$L,領用表!$E:$E,$B12,領用表!$B:$B,$BM$2&BP$2) | BQ12: =SUMIFS(領用表!$L:$L,領用表!$E:$E,$B12,領用表!$B:$B,$BM$2&BQ$2) | BR12: =SUMIFS(領用表!$L:$L,領用表!$A:$A,BR$2,領用表!$E:$E,B12) | BS12: =SUMIFS(領用表!$L:$L,領用表!$E:$E,$B12,領用表!$B:$B,BR$2&BS$2) | BT12: =SUMIFS(領用表!$L:$L,領用表!$E:$E,$B12,領用表!$B:$B,$BR$2&BT$2) | BU12: =SUMIFS(領用表!$L:$L,領用表!$E:$E,$B12,領用表!$B:$B,$BR$2&BU$2) | BV12: =SUMIFS(領用表!$L:$L,領用表!$E:$E,$B12,領用表!$B:$B,$BR$2&BV$2) | BW12: =SUMIFS(領用表!$L:$L,領用表!$A:$A,BW$2,領用表!$E:$E,B12) | BX12: =SUMIFS(領用表!$L:$L,領用表!$E:$E,$B12,領用表!$B:$B,BW$2&BX$2) | BY12: =SUMIFS(領用表!$L:$L,領用表!$E:$E,$B12,領用表!$B:$B,$BW$2&BY$2) | BZ12: =SUMIFS(領用表!$L:$L,領用表!$E:$E,$B12,領用表!$B:$B,$BW$2&BZ$2) | CA12: =SUMIFS(領用表!$L:$L,領用表!$E:$E,$B12,領用表!$B:$B,$BW$2&CA$2) | CB12: =SUMIFS(領用表!$L:$L,領用表!$A:$A,CB$2,領用表!$E:$E,B12) | CC12: =SUMIFS(領用表!$L:$L,領用表!$E:$E,$B12,領用表!$B:$B,CB$2&CC$2) | CD12: =SUMIFS(領用表!$L:$L,領用表!$E:$E,$B12,領用表!$B:$B,$CB$2&CD$2) | CE12: =SUMIFS(領用表!$L:$L,領用表!$E:$E,$B12,領用表!$B:$B,$CB$2&CE$2) | CF12: =SUMIFS(領用表!$L:$L,領用表!$E:$E,$B12,領用表!$B:$B,$CB$2&CF$2) | CG12: =SUMIFS(領用表!$L:$L,領用表!$A:$A,CG$2,領用表!$E:$E,B12) | CH12: =SUMIFS(領用表!$L:$L,領用表!$E:$E,$B12,領用表!$B:$B,CG$2&CH$2) | CI12: =SUMIFS(領用表!$L:$L,領用表!$E:$E,$B12,領用表!$B:$B,CG$2&CI$2) | CJ12: =SUMIFS(領用表!$L:$L,領用表!$E:$E,$B12,領用表!$B:$B,CG$2&CJ$2) | CK12: =SUMIFS(領用表!$L:$L,領用表!$E:$E,$B12,領用表!$B:$B,$CG$2&CK$2) | CL12: =SUM(AX12,AY12,AZ12,BA12,BB12,BC12,BH12,BM12,BR12,BW12,CB12,CG12) | CM12: =AVERAGE(AX12,AY12,AZ12,BA12,BB12,BC12,BH12,BM12,BR12,BW12,CB12,CG12) | CN12: =SUMIFS(領用表!$L:$L,領用表!$A:$A,CN$2,領用表!$E:$E,B12) | CO12: =SUMIFS(領用表!$L:$L,領用表!$E:$E,$B12,領用表!$B:$B,CN$2&CO$2) | CP12: =SUMIFS(領用表!$L:$L,領用表!$E:$E,$B12,領用表!$B:$B,$CN$2&CP$2) | CQ12: =SUMIFS(領用表!$L:$L,領用表!$E:$E,$B12,領用表!$B:$B,$CN$2&CQ$2) | CR12: =SUMIFS(領用表!$L:$L,領用表!$E:$E,$B12,領用表!$B:$B,$CN$2&CR$2) | CS12: =SUMIFS(領用表!$L:$L,領用表!$A:$A,CS$2,領用表!$E:$E,B12) | CT12: =SUMIFS(領用表!$L:$L,領用表!$E:$E,$B12,領用表!$B:$B,CS$2&CT$2) | CU12: =SUMIFS(領用表!$L:$L,領用表!$E:$E,$B12,領用表!$B:$B,$CS$2&CU$2) | CV12: =SUMIFS(領用表!$L:$L,領用表!$E:$E,$B12,領用表!$B:$B,$CS$2&CV$2) | CW12: =SUMIFS(領用表!$L:$L,領用表!$E:$E,$B12,領用表!$B:$B,$CS$2&CW$2) | CX12: =SUMIFS(領用表!$L:$L,領用表!$E:$E,$B12,領用表!$B:$B,$CS$2&CX$2) | CY12: =SUMIFS(領用表!$L:$L,領用表!$A:$A,CY$2,領用表!$E:$E,B12) | CZ12: =SUMIFS(領用表!$L:$L,領用表!$E:$E,$B12,領用表!$B:$B,CY$2&CZ$2) | DA12: =SUMIFS(領用表!$L:$L,領用表!$E:$E,$B12,領用表!$B:$B,$CY$2&DA$2) | DB12: =SUMIFS(領用表!$L:$L,領用表!$E:$E,$B12,領用表!$B:$B,$CY$2&DB$2) | DC12: =SUMIFS(領用表!$L:$L,領用表!$E:$E,$B12,領用表!$B:$B,$CY$2&DC$2) | DD12: =SUMIFS(領用表!$L:$L,領用表!$E:$E,$B12,領用表!$B:$B,$CY$2&DD$2) | DE12: =SUMIFS(領用表!$L:$L,領用表!$A:$A,DE$2,領用表!$E:$E,B12) | DF12: =SUMIFS(領用表!$L:$L,領用表!$E:$E,$B12,領用表!$B:$B,DE$2&DF$2) | DG12: =SUMIFS(領用表!$L:$L,領用表!$E:$E,$B12,領用表!$B:$B,$DE$2&DG$2) | DH12: =SUMIFS(領用表!$L:$L,領用表!$E:$E,$B12,領用表!$B:$B,$DE$2&DH$2) | DI12: =SUMIFS(領用表!$L:$L,領用表!$E:$E,$B12,領用表!$B:$B,$DE$2&DI$2) | DJ12: =SUMIFS(領用表!$L:$L,領用表!$E:$E,$B12,領用表!$B:$B,$DE$2&DJ$2) | DK12: =SUMIFS(領用表!$L:$L,領用表!$A:$A,DK$2,領用表!$E:$E,$B12) | DL12: =SUMIFS(領用表!$L:$L,領用表!$E:$E,$B12,領用表!$B:$B,DK$2&DL$2) | DM12: =SUMIFS(領用表!$L:$L,領用表!$E:$E,$B12,領用表!$B:$B,$DK$2&DM$2) | DN12: =SUMIFS(領用表!$L:$L,領用表!$E:$E,$B12,領用表!$B:$B,$DK$2&DN$2) | DO12: =SUMIFS(領用表!$L:$L,領用表!$E:$E,$B12,領用表!$B:$B,$DK$2&DO$2) | DP12: =SUMIFS(領用表!$L:$L,領用表!$E:$E,$B12,領用表!$B:$B,$DK$2&DP$2) | DW12: =SUM(CN12,CS12,CY12,DE12,DK12,DQ12) | DX12: =AVERAGEA(CN12,CS12,CY12,DE12,DK12,DQ12) | DY12: =SUM(DZ12:EC12) | DZ12: 4 | EA12: 0 | EB12: 10 | EC12: 0 | ED12: 20 | EJ12: =IFERROR(VLOOKUP(A12,站前4樓!A:BF,57,0),0) | EK12: =IFERROR(VLOOKUP(A12,站前11樓!A:BE,57,0),0) | EL12: =IFERROR(VLOOKUP(A12,忠孝7樓!A:N,57,0),0) | EM12: =IFERROR(VLOOKUP(A12,忠孝國際醫學3樓!A:L,57,0),0) | EN12: =SUM(ED12:EG12) | EP12: 48 | EQ12: 8
A13: MP1MA010013A | B13: 6180013 | C13: MINT秘特拉提線FIX 18CM(1支) | D13: 20 | E13: PCS | F13: =SUMIF(站前4樓!B:B,B13,站前4樓!F:F) | G13: =SUMIF(站前11樓!B:B,B13,站前11樓!F:F) | H13: =SUMIF(忠孝7樓!B:B,B13,忠孝7樓!G:G) | I13: =SUMIF(忠孝國際醫學3樓!B:B,B13,忠孝國際醫學3樓!G:G) | J13: =SUMIF(忠孝健康7樓!B:B,B13,忠孝健康7樓!G:G) | K13: 0 | L13: 0 | M13: 0 | N13: 0 | O13: 0 | P13: 0 | Q13: 0 | R13: 0 | S13: 0 | T13: 0 | U13: 0 | V13: 0 | W13: 0 | X13: 0 | Y13: 0 | Z13: 0 | AA13: 0 | AB13: 0 | AC13: 0 | AD13: 0 | AE13: 0 | AF13: 0 | AG13: 0 | AH13: 0 | AI13: 0 | AJ13: 0 | AK13: 0 | AL13: 0 | AM13: 0.4 | AN13: 0 | AO13: 0.4 | AP13: 0.2 | AQ13: 0.8 | AR13: 0.2 | AS13: 0.6 | AT13: 0 | AU13: 0 | AV13: =SUM(AJ13:AU13) | AW13: =AV13/12 | AX13: 23 | AY13: 0 | AZ13: 0 | BA13: 0 | BB13: 8 | BC13: =SUMIFS(領用表!$L:$L,領用表!$A:$A,BC$2,領用表!$E:$E,B13) | BD13: =SUMIFS(領用表!$L:$L,領用表!$E:$E,$B13,領用表!$B:$B,BC$2&BD$2) | BE13: =SUMIFS(領用表!$L:$L,領用表!$E:$E,$B13,領用表!$B:$B,$BC$2&BE$2) | BF13: =SUMIFS(領用表!$L:$L,領用表!$E:$E,$B13,領用表!$B:$B,$BC$2&BF$2) | BG13: =SUMIFS(領用表!$L:$L,領用表!$E:$E,$B13,領用表!$B:$B,$BC$2&BG$2) | BH13: =SUMIFS(領用表!$L:$L,領用表!$A:$A,BH$2,領用表!$E:$E,B13) | BI13: =SUMIFS(領用表!$L:$L,領用表!$E:$E,$B13,領用表!$B:$B,BH$2&BI$2) | BJ13: =SUMIFS(領用表!$L:$L,領用表!$E:$E,$B13,領用表!$B:$B,$BH$2&BJ$2) | BK13: =SUMIFS(領用表!$L:$L,領用表!$E:$E,$B13,領用表!$B:$B,$BH$2&BK$2) | BL13: =SUMIFS(領用表!$L:$L,領用表!$E:$E,$B13,領用表!$B:$B,$BH$2&BL$2) | BM13: =SUMIFS(領用表!$L:$L,領用表!$A:$A,BM$2,領用表!$E:$E,B13) | BN13: =SUMIFS(領用表!$L:$L,領用表!$E:$E,$B13,領用表!$B:$B,BM$2&BN$2) | BO13: =SUMIFS(領用表!$L:$L,領用表!$E:$E,$B13,領用表!$B:$B,$BM$2&BO$2) | BP13: =SUMIFS(領用表!$L:$L,領用表!$E:$E,$B13,領用表!$B:$B,$BM$2&BP$2) | BQ13: =SUMIFS(領用表!$L:$L,領用表!$E:$E,$B13,領用表!$B:$B,$BM$2&BQ$2) | BR13: =SUMIFS(領用表!$L:$L,領用表!$A:$A,BR$2,領用表!$E:$E,B13) | BS13: =SUMIFS(領用表!$L:$L,領用表!$E:$E,$B13,領用表!$B:$B,BR$2&BS$2) | BT13: =SUMIFS(領用表!$L:$L,領用表!$E:$E,$B13,領用表!$B:$B,$BR$2&BT$2) | BU13: =SUMIFS(領用表!$L:$L,領用表!$E:$E,$B13,領用表!$B:$B,$BR$2&BU$2) | BV13: =SUMIFS(領用表!$L:$L,領用表!$E:$E,$B13,領用表!$B:$B,$BR$2&BV$2) | BW13: =SUMIFS(領用表!$L:$L,領用表!$A:$A,BW$2,領用表!$E:$E,B13) | BX13: =SUMIFS(領用表!$L:$L,領用表!$E:$E,$B13,領用表!$B:$B,BW$2&BX$2) | BY13: =SUMIFS(領用表!$L:$L,領用表!$E:$E,$B13,領用表!$B:$B,$BW$2&BY$2) | BZ13: =SUMIFS(領用表!$L:$L,領用表!$E:$E,$B13,領用表!$B:$B,$BW$2&BZ$2) | CA13: =SUMIFS(領用表!$L:$L,領用表!$E:$E,$B13,領用表!$B:$B,$BW$2&CA$2) | CB13: =SUMIFS(領用表!$L:$L,領用表!$A:$A,CB$2,領用表!$E:$E,B13) | CC13: =SUMIFS(領用表!$L:$L,領用表!$E:$E,$B13,領用表!$B:$B,CB$2&CC$2) | CD13: =SUMIFS(領用表!$L:$L,領用表!$E:$E,$B13,領用表!$B:$B,$CB$2&CD$2) | CE13: =SUMIFS(領用表!$L:$L,領用表!$E:$E,$B13,領用表!$B:$B,$CB$2&CE$2) | CF13: =SUMIFS(領用表!$L:$L,領用表!$E:$E,$B13,領用表!$B:$B,$CB$2&CF$2) | CG13: =SUMIFS(領用表!$L:$L,領用表!$A:$A,CG$2,領用表!$E:$E,B13) | CH13: =SUMIFS(領用表!$L:$L,領用表!$E:$E,$B13,領用表!$B:$B,CG$2&CH$2) | CI13: =SUMIFS(領用表!$L:$L,領用表!$E:$E,$B13,領用表!$B:$B,CG$2&CI$2) | CJ13: =SUMIFS(領用表!$L:$L,領用表!$E:$E,$B13,領用表!$B:$B,CG$2&CJ$2) | CK13: =SUMIFS(領用表!$L:$L,領用表!$E:$E,$B13,領用表!$B:$B,$CG$2&CK$2) | CL13: =SUM(AX13,AY13,AZ13,BA13,BB13,BC13,BH13,BM13,BR13,BW13,CB13,CG13) | CM13: =AVERAGE(AX13,AY13,AZ13,BA13,BB13,BC13,BH13,BM13,BR13,BW13,CB13,CG13) | CN13: =SUMIFS(領用表!$L:$L,領用表!$A:$A,CN$2,領用表!$E:$E,B13) | CO13: =SUMIFS(領用表!$L:$L,領用表!$E:$E,$B13,領用表!$B:$B,CN$2&CO$2) | CP13: =SUMIFS(領用表!$L:$L,領用表!$E:$E,$B13,領用表!$B:$B,$CN$2&CP$2) | CQ13: =SUMIFS(領用表!$L:$L,領用表!$E:$E,$B13,領用表!$B:$B,$CN$2&CQ$2) | CR13: =SUMIFS(領用表!$L:$L,領用表!$E:$E,$B13,領用表!$B:$B,$CN$2&CR$2) | CS13: =SUMIFS(領用表!$L:$L,領用表!$A:$A,CS$2,領用表!$E:$E,B13) | CT13: =SUMIFS(領用表!$L:$L,領用表!$E:$E,$B13,領用表!$B:$B,CS$2&CT$2) | CU13: =SUMIFS(領用表!$L:$L,領用表!$E:$E,$B13,領用表!$B:$B,$CS$2&CU$2) | CV13: =SUMIFS(領用表!$L:$L,領用表!$E:$E,$B13,領用表!$B:$B,$CS$2&CV$2) | CW13: =SUMIFS(領用表!$L:$L,領用表!$E:$E,$B13,領用表!$B:$B,$CS$2&CW$2) | CX13: =SUMIFS(領用表!$L:$L,領用表!$E:$E,$B13,領用表!$B:$B,$CS$2&CX$2) | CY13: =SUMIFS(領用表!$L:$L,領用表!$A:$A,CY$2,領用表!$E:$E,B13) | CZ13: =SUMIFS(領用表!$L:$L,領用表!$E:$E,$B13,領用表!$B:$B,CY$2&CZ$2) | DA13: =SUMIFS(領用表!$L:$L,領用表!$E:$E,$B13,領用表!$B:$B,$CY$2&DA$2) | DB13: =SUMIFS(領用表!$L:$L,領用表!$E:$E,$B13,領用表!$B:$B,$CY$2&DB$2) | DC13: =SUMIFS(領用表!$L:$L,領用表!$E:$E,$B13,領用表!$B:$B,$CY$2&DC$2) | DD13: =SUMIFS(領用表!$L:$L,領用表!$E:$E,$B13,領用表!$B:$B,$CY$2&DD$2) | DE13: =SUMIFS(領用表!$L:$L,領用表!$A:$A,DE$2,領用表!$E:$E,B13) | DF13: =SUMIFS(領用表!$L:$L,領用表!$E:$E,$B13,領用表!$B:$B,DE$2&DF$2) | DG13: =SUMIFS(領用表!$L:$L,領用表!$E:$E,$B13,領用表!$B:$B,$DE$2&DG$2) | DH13: =SUMIFS(領用表!$L:$L,領用表!$E:$E,$B13,領用表!$B:$B,$DE$2&DH$2) | DI13: =SUMIFS(領用表!$L:$L,領用表!$E:$E,$B13,領用表!$B:$B,$DE$2&DI$2) | DJ13: =SUMIFS(領用表!$L:$L,領用表!$E:$E,$B13,領用表!$B:$B,$DE$2&DJ$2) | DK13: =SUMIFS(領用表!$L:$L,領用表!$A:$A,DK$2,領用表!$E:$E,$B13) | DL13: =SUMIFS(領用表!$L:$L,領用表!$E:$E,$B13,領用表!$B:$B,DK$2&DL$2) | DM13: =SUMIFS(領用表!$L:$L,領用表!$E:$E,$B13,領用表!$B:$B,$DK$2&DM$2) | DN13: =SUMIFS(領用表!$L:$L,領用表!$E:$E,$B13,領用表!$B:$B,$DK$2&DN$2) | DO13: =SUMIFS(領用表!$L:$L,領用表!$E:$E,$B13,領用表!$B:$B,$DK$2&DO$2) | DP13: =SUMIFS(領用表!$L:$L,領用表!$E:$E,$B13,領用表!$B:$B,$DK$2&DP$2) | DW13: =SUM(CN13,CS13,CY13,DE13,DK13,DQ13) | DX13: =AVERAGEA(CN13,CS13,CY13,DE13,DK13,DQ13) | DY13: =SUM(DZ13:EC13) | DZ13: 1 | EA13: 0 | EB13: 5 | EC13: 0 | ED13: 20 | EJ13: =IFERROR(VLOOKUP(A13,站前4樓!A:BF,57,0),0) | EK13: =IFERROR(VLOOKUP(A13,站前11樓!A:BE,57,0),0) | EL13: =IFERROR(VLOOKUP(A13,忠孝7樓!A:N,57,0),0) | EM13: =IFERROR(VLOOKUP(A13,忠孝國際醫學3樓!A:L,57,0),0) | EN13: =SUM(ED13:EG13) | EP13: 40 | EQ13: 24
A14: MP1MA010014A | B14: 6180007 | C14: MINT秘特拉提線PETIT 15CM(1支) | D14: 20 | E14: PCS | F14: =SUMIF(站前4樓!B:B,B14,站前4樓!F:F) | G14: =SUMIF(站前11樓!B:B,B14,站前11樓!F:F) | H14: =SUMIF(忠孝7樓!B:B,B14,忠孝7樓!G:G) | I14: =SUMIF(忠孝國際醫學3樓!B:B,B14,忠孝國際醫學3樓!G:G) | J14: =SUMIF(忠孝健康7樓!B:B,B14,忠孝健康7樓!G:G) | K14: 0 | L14: 0 | M14: 0 | N14: 0 | O14: 0 | P14: 0 | Q14: 0 | R14: 0 | S14: 0 | T14: 0 | U14: 0 | V14: 0 | W14: 0 | X14: 0 | Y14: 0 | Z14: 0 | AA14: 0 | AB14: 0 | AC14: 0 | AD14: 0 | AE14: 0 | AF14: 0 | AG14: 0 | AH14: 0 | AI14: 0 | AJ14: 0 | AK14: 0 | AL14: 1 | AM14: 1.8 | AN14: 1.2 | AO14: 1.6 | AP14: 0.6 | AQ14: 2.2 | AR14: 0.8 | AS14: 1.2 | AT14: 0.6 | AU14: 24 | AV14: =SUM(AJ14:AU14) | AW14: =AV14/12 | AX14: 56 | AY14: 16 | AZ14: 0 | BA14: 0 | BB14: 4 | BC14: =SUMIFS(領用表!$L:$L,領用表!$A:$A,BC$2,領用表!$E:$E,B14) | BD14: =SUMIFS(領用表!$L:$L,領用表!$E:$E,$B14,領用表!$B:$B,BC$2&BD$2) | BE14: =SUMIFS(領用表!$L:$L,領用表!$E:$E,$B14,領用表!$B:$B,$BC$2&BE$2) | BF14: =SUMIFS(領用表!$L:$L,領用表!$E:$E,$B14,領用表!$B:$B,$BC$2&BF$2) | BG14: =SUMIFS(領用表!$L:$L,領用表!$E:$E,$B14,領用表!$B:$B,$BC$2&BG$2) | BH14: =SUMIFS(領用表!$L:$L,領用表!$A:$A,BH$2,領用表!$E:$E,B14) | BI14: =SUMIFS(領用表!$L:$L,領用表!$E:$E,$B14,領用表!$B:$B,BH$2&BI$2) | BJ14: =SUMIFS(領用表!$L:$L,領用表!$E:$E,$B14,領用表!$B:$B,$BH$2&BJ$2) | BK14: =SUMIFS(領用表!$L:$L,領用表!$E:$E,$B14,領用表!$B:$B,$BH$2&BK$2) | BL14: =SUMIFS(領用表!$L:$L,領用表!$E:$E,$B14,領用表!$B:$B,$BH$2&BL$2) | BM14: =SUMIFS(領用表!$L:$L,領用表!$A:$A,BM$2,領用表!$E:$E,B14) | BN14: =SUMIFS(領用表!$L:$L,領用表!$E:$E,$B14,領用表!$B:$B,BM$2&BN$2) | BO14: =SUMIFS(領用表!$L:$L,領用表!$E:$E,$B14,領用表!$B:$B,$BM$2&BO$2) | BP14: =SUMIFS(領用表!$L:$L,領用表!$E:$E,$B14,領用表!$B:$B,$BM$2&BP$2) | BQ14: =SUMIFS(領用表!$L:$L,領用表!$E:$E,$B14,領用表!$B:$B,$BM$2&BQ$2) | BR14: =SUMIFS(領用表!$L:$L,領用表!$A:$A,BR$2,領用表!$E:$E,B14) | BS14: =SUMIFS(領用表!$L:$L,領用表!$E:$E,$B14,領用表!$B:$B,BR$2&BS$2) | BT14: =SUMIFS(領用表!$L:$L,領用表!$E:$E,$B14,領用表!$B:$B,$BR$2&BT$2) | BU14: =SUMIFS(領用表!$L:$L,領用表!$E:$E,$B14,領用表!$B:$B,$BR$2&BU$2) | BV14: =SUMIFS(領用表!$L:$L,領用表!$E:$E,$B14,領用表!$B:$B,$BR$2&BV$2) | BW14: =SUMIFS(領用表!$L:$L,領用表!$A:$A,BW$2,領用表!$E:$E,B14) | BX14: =SUMIFS(領用表!$L:$L,領用表!$E:$E,$B14,領用表!$B:$B,BW$2&BX$2) | BY14: =SUMIFS(領用表!$L:$L,領用表!$E:$E,$B14,領用表!$B:$B,$BW$2&BY$2) | BZ14: =SUMIFS(領用表!$L:$L,領用表!$E:$E,$B14,領用表!$B:$B,$BW$2&BZ$2) | CA14: =SUMIFS(領用表!$L:$L,領用表!$E:$E,$B14,領用表!$B:$B,$BW$2&CA$2) | CB14: =SUMIFS(領用表!$L:$L,領用表!$A:$A,CB$2,領用表!$E:$E,B14) | CC14: =SUMIFS(領用表!$L:$L,領用表!$E:$E,$B14,領用表!$B:$B,CB$2&CC$2) | CD14: =SUMIFS(領用表!$L:$L,領用表!$E:$E,$B14,領用表!$B:$B,$CB$2&CD$2) | CE14: =SUMIFS(領用表!$L:$L,領用表!$E:$E,$B14,領用表!$B:$B,$CB$2&CE$2) | CF14: =SUMIFS(領用表!$L:$L,領用表!$E:$E,$B14,領用表!$B:$B,$CB$2&CF$2) | CG14: =SUMIFS(領用表!$L:$L,領用表!$A:$A,CG$2,領用表!$E:$E,B14) | CH14: =SUMIFS(領用表!$L:$L,領用表!$E:$E,$B14,領用表!$B:$B,CG$2&CH$2) | CI14: =SUMIFS(領用表!$L:$L,領用表!$E:$E,$B14,領用表!$B:$B,CG$2&CI$2) | CJ14: =SUMIFS(領用表!$L:$L,領用表!$E:$E,$B14,領用表!$B:$B,CG$2&CJ$2) | CK14: =SUMIFS(領用表!$L:$L,領用表!$E:$E,$B14,領用表!$B:$B,$CG$2&CK$2) | CL14: =SUM(AX14,AY14,AZ14,BA14,BB14,BC14,BH14,BM14,BR14,BW14,CB14,CG14) | CM14: =AVERAGE(AX14,AY14,AZ14,BA14,BB14,BC14,BH14,BM14,BR14,BW14,CB14,CG14) | CN14: =SUMIFS(領用表!$L:$L,領用表!$A:$A,CN$2,領用表!$E:$E,B14) | CO14: =SUMIFS(領用表!$L:$L,領用表!$E:$E,$B14,領用表!$B:$B,CN$2&CO$2) | CP14: =SUMIFS(領用表!$L:$L,領用表!$E:$E,$B14,領用表!$B:$B,$CN$2&CP$2) | CQ14: =SUMIFS(領用表!$L:$L,領用表!$E:$E,$B14,領用表!$B:$B,$CN$2&CQ$2) | CR14: =SUMIFS(領用表!$L:$L,領用表!$E:$E,$B14,領用表!$B:$B,$CN$2&CR$2) | CS14: =SUMIFS(領用表!$L:$L,領用表!$A:$A,CS$2,領用表!$E:$E,B14) | CT14: =SUMIFS(領用表!$L:$L,領用表!$E:$E,$B14,領用表!$B:$B,CS$2&CT$2) | CU14: =SUMIFS(領用表!$L:$L,領用表!$E:$E,$B14,領用表!$B:$B,$CS$2&CU$2) | CV14: =SUMIFS(領用表!$L:$L,領用表!$E:$E,$B14,領用表!$B:$B,$CS$2&CV$2) | CW14: =SUMIFS(領用表!$L:$L,領用表!$E:$E,$B14,領用表!$B:$B,$CS$2&CW$2) | CX14: =SUMIFS(領用表!$L:$L,領用表!$E:$E,$B14,領用表!$B:$B,$CS$2&CX$2) | CY14: =SUMIFS(領用表!$L:$L,領用表!$A:$A,CY$2,領用表!$E:$E,B14) | CZ14: =SUMIFS(領用表!$L:$L,領用表!$E:$E,$B14,領用表!$B:$B,CY$2&CZ$2) | DA14: =SUMIFS(領用表!$L:$L,領用表!$E:$E,$B14,領用表!$B:$B,$CY$2&DA$2) | DB14: =SUMIFS(領用表!$L:$L,領用表!$E:$E,$B14,領用表!$B:$B,$CY$2&DB$2) | DC14: =SUMIFS(領用表!$L:$L,領用表!$E:$E,$B14,領用表!$B:$B,$CY$2&DC$2) | DD14: =SUMIFS(領用表!$L:$L,領用表!$E:$E,$B14,領用表!$B:$B,$CY$2&DD$2) | DE14: =SUMIFS(領用表!$L:$L,領用表!$A:$A,DE$2,領用表!$E:$E,B14) | DF14: =SUMIFS(領用表!$L:$L,領用表!$E:$E,$B14,領用表!$B:$B,DE$2&DF$2) | DG14: =SUMIFS(領用表!$L:$L,領用表!$E:$E,$B14,領用表!$B:$B,$DE$2&DG$2) | DH14: =SUMIFS(領用表!$L:$L,領用表!$E:$E,$B14,領用表!$B:$B,$DE$2&DH$2) | DI14: =SUMIFS(領用表!$L:$L,領用表!$E:$E,$B14,領用表!$B:$B,$DE$2&DI$2) | DJ14: =SUMIFS(領用表!$L:$L,領用表!$E:$E,$B14,領用表!$B:$B,$DE$2&DJ$2) | DK14: =SUMIFS(領用表!$L:$L,領用表!$A:$A,DK$2,領用表!$E:$E,$B14) | DL14: =SUMIFS(領用表!$L:$L,領用表!$E:$E,$B14,領用表!$B:$B,DK$2&DL$2) | DM14: =SUMIFS(領用表!$L:$L,領用表!$E:$E,$B14,領用表!$B:$B,$DK$2&DM$2) | DN14: =SUMIFS(領用表!$L:$L,領用表!$E:$E,$B14,領用表!$B:$B,$DK$2&DN$2) | DO14: =SUMIFS(領用表!$L:$L,領用表!$E:$E,$B14,領用表!$B:$B,$DK$2&DO$2) | DP14: =SUMIFS(領用表!$L:$L,領用表!$E:$E,$B14,領用表!$B:$B,$DK$2&DP$2) | DW14: =SUM(CN14,CS14,CY14,DE14,DK14,DQ14) | DX14: =AVERAGEA(CN14,CS14,CY14,DE14,DK14,DQ14) | DY14: =SUM(DZ14:EC14) | DZ14: 4 | EA14: 0 | EB14: 12 | EC14: 0 | ED14: 20 | EJ14: =IFERROR(VLOOKUP(A14,站前4樓!A:BF,57,0),0) | EK14: =IFERROR(VLOOKUP(A14,站前11樓!A:BE,57,0),0) | EL14: =IFERROR(VLOOKUP(A14,忠孝7樓!A:N,57,0),0) | EM14: =IFERROR(VLOOKUP(A14,忠孝國際醫學3樓!A:L,57,0),0) | EN14: =SUM(ED14:EG14) | EP14: 8 | EQ14: 32
A15: MP1MA010015A | B15: 6180009 | C15: MINT秘特拉提線TIP 4CM(1支) | D15: 10 | E15: PCS | F15: =SUMIF(站前4樓!B:B,B15,站前4樓!F:F) | G15: =SUMIF(站前11樓!B:B,B15,站前11樓!F:F) | H15: =SUMIF(忠孝7樓!B:B,B15,忠孝7樓!G:G) | I15: =SUMIF(忠孝國際醫學3樓!B:B,B15,忠孝國際醫學3樓!G:G) | J15: =SUMIF(忠孝健康7樓!B:B,B15,忠孝健康7樓!G:G) | K15: 0 | L15: 0 | M15: 0 | N15: 0 | O15: 0 | P15: 0 | Q15: 0 | R15: 0 | S15: 0 | T15: 0 | U15: 0 | V15: 0 | W15: 0 | X15: 0 | Y15: 0 | Z15: 0 | AA15: 0 | AB15: 0 | AC15: 0 | AD15: 0 | AE15: 0 | AF15: 0 | AG15: 0 | AH15: 0 | AI15: 0 | AJ15: 0.4 | AK15: 0.2 | AL15: 0.8 | AM15: 0.2 | AN15: 1.4 | AO15: 0.8 | AP15: 0.6 | AQ15: 0.6 | AR15: 0.4 | AS15: 0.6 | AT15: 0.6 | AU15: 0 | AV15: =SUM(AJ15:AU15) | AW15: =AV15/12 | AX15: 4 | AY15: 4 | AZ15: 12 | BA15: 0 | BB15: 8 | BC15: =SUMIFS(領用表!$L:$L,領用表!$A:$A,BC$2,領用表!$E:$E,B15) | BD15: =SUMIFS(領用表!$L:$L,領用表!$E:$E,$B15,領用表!$B:$B,BC$2&BD$2) | BE15: =SUMIFS(領用表!$L:$L,領用表!$E:$E,$B15,領用表!$B:$B,$BC$2&BE$2) | BF15: =SUMIFS(領用表!$L:$L,領用表!$E:$E,$B15,領用表!$B:$B,$BC$2&BF$2) | BG15: =SUMIFS(領用表!$L:$L,領用表!$E:$E,$B15,領用表!$B:$B,$BC$2&BG$2) | BH15: =SUMIFS(領用表!$L:$L,領用表!$A:$A,BH$2,領用表!$E:$E,B15) | BI15: =SUMIFS(領用表!$L:$L,領用表!$E:$E,$B15,領用表!$B:$B,BH$2&BI$2) | BJ15: =SUMIFS(領用表!$L:$L,領用表!$E:$E,$B15,領用表!$B:$B,$BH$2&BJ$2) | BK15: =SUMIFS(領用表!$L:$L,領用表!$E:$E,$B15,領用表!$B:$B,$BH$2&BK$2) | BL15: =SUMIFS(領用表!$L:$L,領用表!$E:$E,$B15,領用表!$B:$B,$BH$2&BL$2) | BM15: =SUMIFS(領用表!$L:$L,領用表!$A:$A,BM$2,領用表!$E:$E,B15) | BN15: =SUMIFS(領用表!$L:$L,領用表!$E:$E,$B15,領用表!$B:$B,BM$2&BN$2) | BO15: =SUMIFS(領用表!$L:$L,領用表!$E:$E,$B15,領用表!$B:$B,$BM$2&BO$2) | BP15: =SUMIFS(領用表!$L:$L,領用表!$E:$E,$B15,領用表!$B:$B,$BM$2&BP$2) | BQ15: =SUMIFS(領用表!$L:$L,領用表!$E:$E,$B15,領用表!$B:$B,$BM$2&BQ$2) | BR15: =SUMIFS(領用表!$L:$L,領用表!$A:$A,BR$2,領用表!$E:$E,B15) | BS15: =SUMIFS(領用表!$L:$L,領用表!$E:$E,$B15,領用表!$B:$B,BR$2&BS$2) | BT15: =SUMIFS(領用表!$L:$L,領用表!$E:$E,$B15,領用表!$B:$B,$BR$2&BT$2) | BU15: =SUMIFS(領用表!$L:$L,領用表!$E:$E,$B15,領用表!$B:$B,$BR$2&BU$2) | BV15: =SUMIFS(領用表!$L:$L,領用表!$E:$E,$B15,領用表!$B:$B,$BR$2&BV$2) | BW15: =SUMIFS(領用表!$L:$L,領用表!$A:$A,BW$2,領用表!$E:$E,B15) | BX15: =SUMIFS(領用表!$L:$L,領用表!$E:$E,$B15,領用表!$B:$B,BW$2&BX$2) | BY15: =SUMIFS(領用表!$L:$L,領用表!$E:$E,$B15,領用表!$B:$B,$BW$2&BY$2) | BZ15: =SUMIFS(領用表!$L:$L,領用表!$E:$E,$B15,領用表!$B:$B,$BW$2&BZ$2) | CA15: =SUMIFS(領用表!$L:$L,領用表!$E:$E,$B15,領用表!$B:$B,$BW$2&CA$2) | CB15: =SUMIFS(領用表!$L:$L,領用表!$A:$A,CB$2,領用表!$E:$E,B15) | CC15: =SUMIFS(領用表!$L:$L,領用表!$E:$E,$B15,領用表!$B:$B,CB$2&CC$2) | CD15: =SUMIFS(領用表!$L:$L,領用表!$E:$E,$B15,領用表!$B:$B,$CB$2&CD$2) | CE15: =SUMIFS(領用表!$L:$L,領用表!$E:$E,$B15,領用表!$B:$B,$CB$2&CE$2) | CF15: =SUMIFS(領用表!$L:$L,領用表!$E:$E,$B15,領用表!$B:$B,$CB$2&CF$2) | CG15: =SUMIFS(領用表!$L:$L,領用表!$A:$A,CG$2,領用表!$E:$E,B15) | CH15: =SUMIFS(領用表!$L:$L,領用表!$E:$E,$B15,領用表!$B:$B,CG$2&CH$2) | CI15: =SUMIFS(領用表!$L:$L,領用表!$E:$E,$B15,領用表!$B:$B,CG$2&CI$2) | CJ15: =SUMIFS(領用表!$L:$L,領用表!$E:$E,$B15,領用表!$B:$B,CG$2&CJ$2) | CK15: =SUMIFS(領用表!$L:$L,領用表!$E:$E,$B15,領用表!$B:$B,$CG$2&CK$2) | CL15: =SUM(AX15,AY15,AZ15,BA15,BB15,BC15,BH15,BM15,BR15,BW15,CB15,CG15) | CM15: =AVERAGE(AX15,AY15,AZ15,BA15,BB15,BC15,BH15,BM15,BR15,BW15,CB15,CG15) | CN15: =SUMIFS(領用表!$L:$L,領用表!$A:$A,CN$2,領用表!$E:$E,B15) | CO15: =SUMIFS(領用表!$L:$L,領用表!$E:$E,$B15,領用表!$B:$B,CN$2&CO$2) | CP15: =SUMIFS(領用表!$L:$L,領用表!$E:$E,$B15,領用表!$B:$B,$CN$2&CP$2) | CQ15: =SUMIFS(領用表!$L:$L,領用表!$E:$E,$B15,領用表!$B:$B,$CN$2&CQ$2) | CR15: =SUMIFS(領用表!$L:$L,領用表!$E:$E,$B15,領用表!$B:$B,$CN$2&CR$2) | CS15: =SUMIFS(領用表!$L:$L,領用表!$A:$A,CS$2,領用表!$E:$E,B15) | CT15: =SUMIFS(領用表!$L:$L,領用表!$E:$E,$B15,領用表!$B:$B,CS$2&CT$2) | CU15: =SUMIFS(領用表!$L:$L,領用表!$E:$E,$B15,領用表!$B:$B,$CS$2&CU$2) | CV15: =SUMIFS(領用表!$L:$L,領用表!$E:$E,$B15,領用表!$B:$B,$CS$2&CV$2) | CW15: =SUMIFS(領用表!$L:$L,領用表!$E:$E,$B15,領用表!$B:$B,$CS$2&CW$2) | CX15: =SUMIFS(領用表!$L:$L,領用表!$E:$E,$B15,領用表!$B:$B,$CS$2&CX$2) | CY15: =SUMIFS(領用表!$L:$L,領用表!$A:$A,CY$2,領用表!$E:$E,B15) | CZ15: =SUMIFS(領用表!$L:$L,領用表!$E:$E,$B15,領用表!$B:$B,CY$2&CZ$2) | DA15: =SUMIFS(領用表!$L:$L,領用表!$E:$E,$B15,領用表!$B:$B,$CY$2&DA$2) | DB15: =SUMIFS(領用表!$L:$L,領用表!$E:$E,$B15,領用表!$B:$B,$CY$2&DB$2) | DC15: =SUMIFS(領用表!$L:$L,領用表!$E:$E,$B15,領用表!$B:$B,$CY$2&DC$2) | DD15: =SUMIFS(領用表!$L:$L,領用表!$E:$E,$B15,領用表!$B:$B,$CY$2&DD$2) | DE15: =SUMIFS(領用表!$L:$L,領用表!$A:$A,DE$2,領用表!$E:$E,B15) | DF15: =SUMIFS(領用表!$L:$L,領用表!$E:$E,$B15,領用表!$B:$B,DE$2&DF$2) | DG15: =SUMIFS(領用表!$L:$L,領用表!$E:$E,$B15,領用表!$B:$B,$DE$2&DG$2) | DH15: =SUMIFS(領用表!$L:$L,領用表!$E:$E,$B15,領用表!$B:$B,$DE$2&DH$2) | DI15: =SUMIFS(領用表!$L:$L,領用表!$E:$E,$B15,領用表!$B:$B,$DE$2&DI$2) | DJ15: =SUMIFS(領用表!$L:$L,領用表!$E:$E,$B15,領用表!$B:$B,$DE$2&DJ$2) | DK15: =SUMIFS(領用表!$L:$L,領用表!$A:$A,DK$2,領用表!$E:$E,$B15) | DL15: =SUMIFS(領用表!$L:$L,領用表!$E:$E,$B15,領用表!$B:$B,DK$2&DL$2) | DM15: =SUMIFS(領用表!$L:$L,領用表!$E:$E,$B15,領用表!$B:$B,$DK$2&DM$2) | DN15: =SUMIFS(領用表!$L:$L,領用表!$E:$E,$B15,領用表!$B:$B,$DK$2&DN$2) | DO15: =SUMIFS(領用表!$L:$L,領用表!$E:$E,$B15,領用表!$B:$B,$DK$2&DO$2) | DP15: =SUMIFS(領用表!$L:$L,領用表!$E:$E,$B15,領用表!$B:$B,$DK$2&DP$2) | DQ15: 4 | DT15: 4 | DW15: =SUM(CN15,CS15,CY15,DE15,DK15,DQ15) | DX15: =AVERAGEA(CN15,CS15,CY15,DE15,DK15,DQ15) | DY15: =SUM(DZ15:EC15) | DZ15: 8 | EA15: 0 | EB15: 12 | EC15: 0 | ED15: 20 | EJ15: =IFERROR(VLOOKUP(A15,站前4樓!A:BF,57,0),0) | EK15: =IFERROR(VLOOKUP(A15,站前11樓!A:BE,57,0),0) | EL15: =IFERROR(VLOOKUP(A15,忠孝7樓!A:N,57,0),0) | EM15: =IFERROR(VLOOKUP(A15,忠孝國際醫學3樓!A:L,57,0),0) | EN15: =SUM(ED15:EG15) | EP15: 36 | EQ15: 52
